Workbook

Sheet IMPORTAÇÃO GENOTIPER
A1: CASO: | C1: (IMPORTANTE: 1º SALVAR) | O1: =(IF((A2=1),"Helder - MS",(IF((A2=2),"Carlos - PR",(IF((A2=3),"Rui - PR",(IF((A2=4),"Helder - PR",(IF((A2=5),"Carlos - MS","Opção Incorreta")))))))))) -> Helder - MS
A2: 1 | B2: =IF(OR(($O$17="ERRO"),($W$17="ERRO"),($AU$17="ERRO"),($BC$17="ERRO")),"VERIFICAR ERRO NA AMELOGENINA","DADOS IMPORTADOS") -> DADOS IMPORTADOS | O2: DADOS AJUSTADOS
A3: STR | B3: M1 | C3: M2 | D3: C1 | E3: C2 | F3: SP1 | G3: SP2 | H3: M1 AJ-1 | I3: M1 AJ-2 | J3: M1 AJ-3 | K3: M1 AJ-4 | L3: M1 AJ-5 | M3: M1 AJ-6 | N3: M1 AJ-7 | O3: M1-FIN | P3: M2 AJ-1 | Q3: M2 AJ-2 | R3: M2 AJ-3 | S3: M2 AJ-4 | T3: M2 AJ-5 | U3: M2 AJ-6 | V3: M2 AJ-7 | W3: M2-FIN | X3: C1 AJ-1 | Y3: C1 AJ-2 | Z3: C1 AJ-3 | AA3: C1 AJ-4 | AB3: C1 AJ-5 | AC3: C1 AJ-6 | AD3: C1 AJ-7 | AE3: C1-FIN | AF3: C2 AJ-1 | AG3: C2 AJ-2 | AH3: C2 AJ-3 | AI3: C2 AJ-4 | AJ3: C2 AJ-5 | AK3: C2 AJ-6 | AL3: C2 AJ-7 | AM3: C2-FIN | AN3: SP1 AJ-1 | AO3: SP1 AJ-2 | AP3: SP1 AJ-3 | AQ3: SP1 AJ-4 | AR3: SP1 AJ-5 | AS3: SP1 AJ-6 | AT3: SP1 AJ-7 | AU3: SP1-FIN | AV3: SP2 AJ-1 | AW3: SP2 AJ-2 | AX3: SP2 AJ-3 | AY3: SP2 AJ-4 | AZ3: SP2 AJ-5 | BA3: SP2 AJ-6 | BB3: SP2 AJ-7 | BC3: SP2-FIN
A4: AMEL | B4: ND | C4: ND | D4: X | E4: X | F4: X | G4: Y | H4: =((IF(($B4=38785),9.3,((IF(($B4=38761),13.2,((IF(($B4="31.2"),31.2,((IF(($B4=38787),11.3,((IF(($B4=38759),11.2,((IF(($B4=38763),15.2,((IF(($B4=38765),17.2,((IF(($B4=38772),24.2,0)))))))))))))))))))))))) -> 0 | I4: =((IF(($B4=38800),24.3,((IF(($B4=38773),25.2,((IF(($B4=38046),29.2,((IF(($B4=38075),29.3,((IF(($B4="32.2"),32.2,((IF(($B4="33.2"),33.2,((IF(($B4="34.2"),34.2,((IF(($B4="35.2"),35.2,0)))))))))))))))))))))))) -> 0 | J4: =((IF(($B4=38767),19.2,((IF(($B4="21.2"),21.2,((IF(($B4="22.2"),22.2,((IF(($B4="22.3"),22.3,((IF(($B4="26.2"),26.2,((IF(($B4="42.2"),42.2,((IF(($B4="44.2"),44.2,((IF(($B4="46.2"),46.2,0)))))))))))))))))))))))) -> 0 | K4: =((IF(($B4="47.2"),47.2,((IF(($B4="50.2"),50.2,((IF(($B4="8.3"),8.3,((IF(($B4="23.2"),23.2,((IF(($B4="43.2"),43.2,((IF(($B4="45.2"),45.2,((IF(($B4="48.2"),48.2,((IF(($B4="51.2"),51.2,0)))))))))))))))))))))))) -> 0 | L4: =((IF(($B4="13.3"),13.3,((IF(($B4=38758),10.2,((IF(($B4=38762),14.2,((IF(($B4=38760),12.2,((IF(($B4=38764),16.2,((IF(($B4=38766),18.2,((IF(($B4=38776),28.2,((IF(($B4="30.2"),30.2,0)))))))))))))))))))))))) -> 0 | M4: =((IF(($B4="34.1"),34.1,((IF(($B4="35.1"),35.1,((IF(($B4=38733),16.1,((IF(($B4=38768),20.2,((IF(($B4=38774),26.2,0))))))))))))))) -> 0 | O4: =(IF((SUM(H4:N4)<>0),(SUM(H4:N4)),$B4)) -> ND | P4: =((IF(($C4=38785),9.3,((IF(($C4=38761),13.2,((IF(($C4="31.2"),31.2,((IF(($C4=38787),11.3,((IF(($C4=38759),11.2,((IF(($C4=38763),15.2,((IF(($C4=38765),4.2,((IF(($C4=38772),24.2,0)))))))))))))))))))))))) -> 0 | Q4: =((IF(($C4=38800),24.3,((IF(($C4=38773),25.2,((IF(($C4=38046),29.2,((IF(($C4=38075),29.3,((IF(($C4="32.2"),32.2,((IF(($C4="33.2"),33.2,((IF(($C4="34.2"),34.2,((IF(($C4="35.2"),35.2,0)))))))))))))))))))))))) -> 0 | R4: =((IF(($C4=38767),19.2,((IF(($C4="21.2"),21.2,((IF(($C4="22.2"),22.2,((IF(($C4="22.3"),22.3,((IF(($C4="26.2"),26.2,((IF(($C4="42.2"),42.2,((IF(($C4="44.2"),44.2,((IF(($C4="46.2"),46.2,0)))))))))))))))))))))))) -> 0 | S4: =((IF(($C4="47.2"),47.2,((IF(($C4="50.2"),50.2,((IF(($C4="8.3"),8.3,((IF(($C4="23.2"),23.2,((IF(($C4="43.2"),43.2,((IF(($C4="45.2"),45.2,((IF(($C4="48.2"),48.2,((IF(($C4="51.2"),51.2,0)))))))))))))))))))))))) -> 0 | T4: =((IF(($C4="13.3"),13.3,((IF(($C4=38758),10.2,((IF(($C4=38762),14.2,((IF(($C4=38760),12.2,((IF(($C4=38764),16.2,((IF(($C4=38766),18.2,((IF(($C4=38776),28.2,((IF(($C4="30.2"),30.2,0)))))))))))))))))))))))) -> 0 | U4: =((IF(($C4="34.1"),34.1,((IF(($C4="35.1"),35.1,((IF(($C4=38733),16.1,((IF(($C4=38768),20.2,((IF(($C4=38774),26.2,((IF(($C4=38771),23.2,0)))))))))))))))))) -> 0 | W4: =(IF((SUM(P4:V4)<>0),(SUM(P4:V4)),$C4)) -> ND | X4: =((IF(($D4=38785),9.3,((IF(($D4=38761),13.2,((IF(($D4="31.2"),31.2,((IF(($D4=38787),11.3,((IF(($D4=38759),11.2,((IF(($D4=38763),15.2,((IF(($D4=38765),4.2,((IF(($D4=38772),24.2,0)))))))))))))))))))))))) -> 0 | Y4: =((IF(($D4=38800),24.3,((IF(($D4=38773),25.2,((IF(($D4=38046),29.2,((IF(($D4=38075),29.3,((IF(($D4="32.2"),32.2,((IF(($D4="33.2"),33.2,((IF(($D4="34.2"),34.2,((IF(($D4="35.2"),35.2,0)))))))))))))))))))))))) -> 0 | Z4: =((IF(($D4=38767),19.2,((IF(($D4="21.2"),21.2,((IF(($D4="22.2"),22.2,((IF(($D4="22.3"),22.3,((IF(($D4="26.2"),26.2,((IF(($D4="42.2"),42.2,((IF(($D4="44.2"),44.2,((IF(($D4="46.2"),46.2,0)))))))))))))))))))))))) -> 0 | AA4: =((IF(($D4="47.2"),47.2,((IF(($D4="50.2"),50.2,((IF(($D4="8.3"),8.3,((IF(($D4="23.2"),23.2,((IF(($D4="43.2"),43.2,((IF(($D4="45.2"),45.2,((IF(($D4="48.2"),48.2,((IF(($D4="51.2"),51.2,0)))))))))))))))))))))))) -> 0 | AB4: =((IF(($D4="13.3"),13.3,((IF(($D4=38758),10.2,((IF(($D4=38762),14.2,((IF(($D4=38760),12.2,((IF(($D4=38764),16.2,((IF(($D4=38766),18.2,((IF(($D4=38776),28.2,((IF(($D4="30.2"),30.2,0)))))))))))))))))))))))) -> 0 | AC4: =((IF(($D4="34.1"),34.1,((IF(($D4="35.1"),35.1,((IF(($D4=38733),16.1,((IF(($D4=38768),20.2,((IF(($D4=38774),26.2,0))))))))))))))) -> 0 | AE4: =(IF((SUM(X4:AD4)<>0),(SUM(X4:AD4)),$D4)) -> X | AF4: =((IF(($E4=38785),9.3,((IF(($E4=38761),13.2,((IF(($E4="31.2"),31.2,((IF(($E4=38787),11.3,((IF(($E4=38759),11.2,((IF(($E4=38763),15.2,((IF(($E4=38765),4.2,((IF(($E4=38772),24.2,0)))))))))))))))))))))))) -> 0 | AG4: =((IF(($E4=38800),24.3,((IF(($E4=38773),25.2,((IF(($E4=38046),29.2,((IF(($E4=38075),29.3,((IF(($E4="32.2"),32.2,((IF(($E4="33.2"),33.2,((IF(($E4="34.2"),34.2,((IF(($E4="35.2"),35.2,0)))))))))))))))))))))))) -> 0 | AH4: =((IF(($E4=38767),19.2,((IF(($E4="21.2"),21.2,((IF(($E4="22.2"),22.2,((IF(($E4="22.3"),22.3,((IF(($E4="26.2"),26.2,((IF(($E4="42.2"),42.2,((IF(($E4="44.2"),44.2,((IF(($E4="46.2"),46.2,0)))))))))))))))))))))))) -> 0 | AI4: =((IF(($E4="47.2"),47.2,((IF(($E4="50.2"),50.2,((IF(($E4="8.3"),8.3,((IF(($E4="23.2"),23.2,((IF(($E4="43.2"),43.2,((IF(($E4="45.2"),45.2,((IF(($E4="48.2"),48.2,((IF(($E4="51.2"),51.2,0)))))))))))))))))))))))) -> 0 | AJ4: =((IF(($E4="13.3"),13.3,((IF(($E4=38758),10.2,((IF(($E4=38762),14.2,((IF(($E4=38760),12.2,((IF(($E4=38764),16.2,((IF(($E4=38766),18.2,((IF(($E4=38776),28.2,((IF(($E4="30.2"),30.2,0)))))))))))))))))))))))) -> 0 | AK4: =((IF(($E4="34.1"),34.1,((IF(($E4="35.1"),35.1,((IF(($E4=38733),16.1,((IF(($E4=38768),20.2,((IF(($E4=38774),26.2,((IF(($E4=38771),23.2,0)))))))))))))))))) -> 0 | AM4: =(IF((SUM(AF4:AL4)<>0),(SUM(AF4:AL4)),$E4)) -> X | AN4: =((IF(($F4=38785),9.3,((IF(($F4=38761),13.2,((IF(($F4="31.2"),31.2,((IF(($F4=38787),11.3,((IF(($F4=38759),11.2,((IF(($F4=38763),15.2,((IF(($F4=38765),4.2,((IF(($F4=38772),24.2,0)))))))))))))))))))))))) -> 0 | AO4: =((IF(($F4=38800),24.3,((IF(($F4=38773),25.2,((IF(($F4=38046),29.2,((IF(($F4=38075),29.3,((IF(($F4="32.2"),32.2,((IF(($F4="33.2"),33.2,((IF(($F4="34.2"),34.2,((IF(($F4="35.2"),35.2,0)))))))))))))))))))))))) -> 0 | AP4: =((IF(($F4=38767),19.2,((IF(($F4="21.2"),21.2,((IF(($F4="22.2"),22.2,((IF(($F4="22.3"),22.3,((IF(($F4="26.2"),26.2,((IF(($F4="42.2"),42.2,((IF(($F4="44.2"),44.2,((IF(($F4="46.2"),46.2,0)))))))))))))))))))))))) -> 0 | AQ4: =((IF(($F4="47.2"),47.2,((IF(($F4="50.2"),50.2,((IF(($F4="8.3"),8.3,((IF(($F4="23.2"),23.2,((IF(($F4="43.2"),43.2,((IF(($F4="45.2"),45.2,((IF(($F4="48.2"),48.2,((IF(($F4="51.2"),51.2,0)))))))))))))))))))))))) -> 0 | AR4: =((IF(($F4="13.3"),13.3,((IF(($F4=38758),10.2,((IF(($F4=38762),14.2,((IF(($F4=38760),12.2,((IF(($F4=38764),16.2,((IF(($F4=38766),18.2,((IF(($F4=38776),28.2,((IF(($F4="30.2"),30.2,0)))))))))))))))))))))))) -> 0 | AS4: =((IF(($F4="34.1"),34.1,((IF(($F4="35.1"),35.1,((IF(($F4=38733),16.1,((IF(($F4=38768),20.2,((IF(($F4=38774),26.2,0))))))))))))))) -> 0 | AU4: =(IF((SUM(AN4:AT4)<>0),(SUM(AN4:AT4)),$F4)) -> X | AV4: =(IF((SUM(AO4:AU4)<>0),(SUM(AO4:AU4)),$E4)) -> X | AW4: =(IF((SUM(AP4:AV4)<>0),(SUM(AP4:AV4)),$E4)) -> X | AX4: =(IF((SUM(AQ4:AW4)<>0),(SUM(AQ4:AW4)),$E4)) -> X | AY4: =(IF((SUM(AR4:AX4)<>0),(SUM(AR4:AX4)),$E4)) -> X | AZ4: =(IF((SUM(AS4:AY4)<>0),(SUM(AS4:AY4)),$E4)) -> X | BA4: =(IF((SUM(AT4:AZ4)<>0),(SUM(AT4:AZ4)),$E4)) -> X | BB4: =(IF((SUM(AU4:BA4)<>0),(SUM(AU4:BA4)),$E4)) -> X | BC4: =(IF((SUM(AV4:BB4)<>0),(SUM(AV4:BB4)),$G4)) -> Y
A5: =FREQUENCIAS!B$1 -> D3S1358 | B5: ND | C5: ND | D5: 15 | E5: 17 | F5: 15 | G5: 16 | H5: =((IF(($B5=38785),9.3,((IF(($B5=38761),13.2,((IF(($B5="31.2"),31.2,((IF(($B5=38787),11.3,((IF(($B5=38759),11.2,((IF(($B5=38763),15.2,((IF(($B5=38765),17.2,((IF(($B5=38772),24.2,0)))))))))))))))))))))))) -> 0 | I5: =((IF(($B5=38800),24.3,((IF(($B5=38773),25.2,((IF(($B5=38046),29.2,((IF(($B5=38075),29.3,((IF(($B5="32.2"),32.2,((IF(($B5="33.2"),33.2,((IF(($B5="34.2"),34.2,((IF(($B5="35.2"),35.2,0)))))))))))))))))))))))) -> 0 | J5: =((IF(($B5=38767),19.2,((IF(($B5="21.2"),21.2,((IF(($B5="22.2"),22.2,((IF(($B5="22.3"),22.3,((IF(($B5="26.2"),26.2,((IF(($B5="42.2"),42.2,((IF(($B5="44.2"),44.2,((IF(($B5="46.2"),46.2,0)))))))))))))))))))))))) -> 0 | K5: =((IF(($B5="47.2"),47.2,((IF(($B5="50.2"),50.2,((IF(($B5="8.3"),8.3,((IF(($B5="23.2"),23.2,((IF(($B5="43.2"),43.2,((IF(($B5="45.2"),45.2,((IF(($B5="48.2"),48.2,((IF(($B5="51.2"),51.2,0)))))))))))))))))))))))) -> 0 | L5: =((IF(($B5="13.3"),13.3,((IF(($B5=38758),10.2,((IF(($B5=38762),14.2,((IF(($B5=38760),12.2,((IF(($B5=38764),16.2,((IF(($B5=38766),18.2,((IF(($B5=38776),28.2,((IF(($B5="30.2"),30.2,0)))))))))))))))))))))))) -> 0 | M5: =((IF(($B5="34.1"),34.1,((IF(($B5="35.1"),35.1,((IF(($B5=38733),16.1,((IF(($B5=38768),20.2,((IF(($B5=38774),26.2,((IF(($B5=38771),23.2,((IF(($B5="29.2"),29.2,0))))))))))))))))))))) -> 0 | O5: =(IF((SUM(H5:N5)<>0),(SUM(H5:N5)),$B5)) -> ND | P5: =((IF(($C5=38785),9.3,((IF(($C5=38761),13.2,((IF(($C5="31.2"),31.2,((IF(($C5=38787),11.3,((IF(($C5=38759),11.2,((IF(($C5=38763),15.2,((IF(($C5=38765),17.2,((IF(($C5=38772),24.2,0)))))))))))))))))))))))) -> 0 | Q5: =((IF(($C5=38800),24.3,((IF(($C5=38773),25.2,((IF(($C5=38046),29.2,((IF(($C5=38075),29.3,((IF(($C5="32.2"),32.2,((IF(($C5="33.2"),33.2,((IF(($C5="34.2"),34.2,((IF(($C5="35.2"),35.2,0)))))))))))))))))))))))) -> 0 | R5: =((IF(($C5=38767),19.2,((IF(($C5="21.2"),21.2,((IF(($C5="22.2"),22.2,((IF(($C5="22.3"),22.3,((IF(($C5="26.2"),26.2,((IF(($C5="42.2"),42.2,((IF(($C5="44.2"),44.2,((IF(($C5="46.2"),46.2,0)))))))))))))))))))))))) -> 0 | S5: =((IF(($C5="47.2"),47.2,((IF(($C5="50.2"),50.2,((IF(($C5="8.3"),8.3,((IF(($C5="23.2"),23.2,((IF(($C5="43.2"),43.2,((IF(($C5="45.2"),45.2,((IF(($C5="48.2"),48.2,((IF(($C5="51.2"),51.2,0)))))))))))))))))))))))) -> 0 | T5: =((IF(($C5="13.3"),13.3,((IF(($C5=38758),10.2,((IF(($C5=38762),14.2,((IF(($C5=38760),12.2,((IF(($C5=38764),16.2,((IF(($C5=38766),18.2,((IF(($C5=38776),28.2,((IF(($C5="30.2"),30.2,0)))))))))))))))))))))))) -> 0 | U5: =((IF(($C5="34.1"),34.1,((IF(($C5="35.1"),35.1,((IF(($C5=38733),16.1,((IF(($C5=38768),20.2,((IF(($C5=38774),26.2,((IF(($C5=38771),23.2,((IF(($C5="29.2"),29.2,0))))))))))))))))))))) -> 0 | W5: =(IF((SUM(P5:V5)<>0),(SUM(P5:V5)),$C5)) -> ND | X5: =((IF(($D5=38785),9.3,((IF(($D5=38761),13.2,((IF(($D5="31.2"),31.2,((IF(($D5=38787),11.3,((IF(($D5=38759),11.2,((IF(($D5=38763),15.2,((IF(($D5=38765),17.2,((IF(($D5=38772),24.2,0)))))))))))))))))))))))) -> 0 | Y5: =((IF(($D5=38800),24.3,((IF(($D5=38773),25.2,((IF(($D5=38046),29.2,((IF(($D5=38075),29.3,((IF(($D5="32.2"),32.2,((IF(($D5="33.2"),33.2,((IF(($D5="34.2"),34.2,((IF(($D5="35.2"),35.2,0)))))))))))))))))))))))) -> 0 | Z5: =((IF(($D5=38767),19.2,((IF(($D5="21.2"),21.2,((IF(($D5="22.2"),22.2,((IF(($D5="22.3"),22.3,((IF(($D5="26.2"),26.2,((IF(($D5="42.2"),42.2,((IF(($D5="44.2"),44.2,((IF(($D5="46.2"),46.2,0)))))))))))))))))))))))) -> 0 | AA5: =((IF(($D5="47.2"),47.2,((IF(($D5="50.2"),50.2,((IF(($D5="8.3"),8.3,((IF(($D5="23.2"),23.2,((IF(($D5="43.2"),43.2,((IF(($D5="45.2"),45.2,((IF(($D5="48.2"),48.2,((IF(($D5="51.2"),51.2,0)))))))))))))))))))))))) -> 0 | AB5: =((IF(($D5="13.3"),13.3,((IF(($D5=38758),10.2,((IF(($D5=38762),14.2,((IF(($D5=38760),12.2,((IF(($D5=38764),16.2,((IF(($D5=38766),18.2,((IF(($D5=38776),28.2,((IF(($D5="30.2"),30.2,0)))))))))))))))))))))))) -> 0 | AC5: =((IF(($D5="34.1"),34.1,((IF(($D5="35.1"),35.1,((IF(($D5=38733),16.1,((IF(($D5=38768),20.2,((IF(($D5=38774),26.2,((IF(($D5=38771),23.2,((IF(($D5="29.2"),29.2,0))))))))))))))))))))) -> 0 | AE5: =(IF((SUM(X5:AD5)<>0),(SUM(X5:AD5)),$D5)) -> 15 | AF5: =((IF(($E5=38785),9.3,((IF(($E5=38761),13.2,((IF(($E5="31.2"),31.2,((IF(($E5=38787),11.3,((IF(($E5=38759),11.2,((IF(($E5=38763),15.2,((IF(($E5=38765),17.2,((IF(($E5=38772),24.2,0)))))))))))))))))))))))) -> 0 | AG5: =((IF(($E5=38800),24.3,((IF(($E5=38773),25.2,((IF(($E5=38046),29.2,((IF(($E5=38075),29.3,((IF(($E5="32.2"),32.2,((IF(($E5="33.2"),33.2,((IF(($E5="34.2"),34.2,((IF(($E5="35.2"),35.2,0)))))))))))))))))))))))) -> 0 | AH5: =((IF(($E5=38767),19.2,((IF(($E5="21.2"),21.2,((IF(($E5="22.2"),22.2,((IF(($E5="22.3"),22.3,((IF(($E5="26.2"),26.2,((IF(($E5="42.2"),42.2,((IF(($E5="44.2"),44.2,((IF(($E5="46.2"),46.2,0)))))))))))))))))))))))) -> 0 | AI5: =((IF(($E5="47.2"),47.2,((IF(($E5="50.2"),50.2,((IF(($E5="8.3"),8.3,((IF(($E5="23.2"),23.2,((IF(($E5="43.2"),43.2,((IF(($E5="45.2"),45.2,((IF(($E5="48.2"),48.2,((IF(($E5="51.2"),51.2,0)))))))))))))))))))))))) -> 0 | AJ5: =((IF(($E5="13.3"),13.3,((IF(($E5=38758),10.2,((IF(($E5=38762),14.2,((IF(($E5=38760),12.2,((IF(($E5=38764),16.2,((IF(($E5=38766),18.2,((IF(($E5=38776),28.2,((IF(($E5="30.2"),30.2,0)))))))))))))))))))))))) -> 0 | AK5: =((IF(($E5="34.1"),34.1,((IF(($E5="35.1"),35.1,((IF(($E5=38733),16.1,((IF(($E5=38768),20.2,((IF(($E5=38774),26.2,((IF(($E5=38771),23.2,((IF(($E5="29.2"),29.2,0))))))))))))))))))))) -> 0 | AM5: =(IF((SUM(AF5:AL5)<>0),(SUM(AF5:AL5)),$E5)) -> 17 | AN5: =((IF(($F5=38785),9.3,((IF(($F5=38761),13.2,((IF(($F5="31.2"),31.2,((IF(($F5=38787),11.3,((IF(($F5=38759),11.2,((IF(($F5=38763),15.2,((IF(($F5=38765),17.2,((IF(($F5=38772),24.2,0)))))))))))))))))))))))) -> 0 | AO5: =((IF(($F5=38800),24.3,((IF(($F5=38773),25.2,((IF(($F5=38046),29.2,((IF(($F5=38075),29.3,((IF(($F5="32.2"),32.2,((IF(($F5="33.2"),33.2,((IF(($F5="34.2"),34.2,((IF(($F5="35.2"),35.2,0)))))))))))))))))))))))) -> 0 | AP5: =((IF(($F5=38767),19.2,((IF(($F5="21.2"),21.2,((IF(($F5="22.2"),22.2,((IF(($F5="22.3"),22.3,((IF(($F5="26.2"),26.2,((IF(($F5="42.2"),42.2,((IF(($F5="44.2"),44.2,((IF(($F5="46.2"),46.2,0)))))))))))))))))))))))) -> 0 | AQ5: =((IF(($F5="47.2"),47.2,((IF(($F5="50.2"),50.2,((IF(($F5="8.3"),8.3,((IF(($F5="23.2"),23.2,((IF(($F5="43.2"),43.2,((IF(($F5="45.2"),45.2,((IF(($F5="48.2"),48.2,((IF(($F5="51.2"),51.2,0)))))))))))))))))))))))) -> 0 | AR5: =((IF(($F5="13.3"),13.3,((IF(($F5=38758),10.2,((IF(($F5=38762),14.2,((IF(($F5=38760),12.2,((IF(($F5=38764),16.2,((IF(($F5=38766),18.2,((IF(($F5=38776),28.2,((IF(($F5="30.2"),30.2,0)))))))))))))))))))))))) -> 0 | AS5: =((IF(($F5="34.1"),34.1,((IF(($F5="35.1"),35.1,((IF(($F5=38733),16.1,((IF(($F5=38768),20.2,((IF(($F5=38774),26.2,((IF(($F5=38771),23.2,((IF(($F5="29.2"),29.2,0))))))))))))))))))))) -> 0 | AU5: =(IF((SUM(AN5:AT5)<>0),(SUM(AN5:AT5)),$F5)) -> 15 | AV5: =((IF(($G5=38785),9.3,((IF(($G5=38761),13.2,((IF(($G5="31.2"),31.2,((IF(($G5=38787),11.3,((IF(($G5=38759),11.2,((IF(($G5=38763),15.2,((IF(($G5=38765),17.2,((IF(($G5=38772),24.2,0)))))))))))))))))))))))) -> 0 | AW5: =((IF(($G5=38800),24.3,((IF(($G5=38773),25.2,((IF(($G5=38046),29.2,((IF(($G5=38075),29.3,((IF(($G5="32.2"),32.2,((IF(($G5="33.2"),33.2,((IF(($G5="34.2"),34.2,((IF(($G5="35.2"),35.2,0)))))))))))))))))))))))) -> 0 | AX5: =((IF(($G5=38767),19.2,((IF(($G5="21.2"),21.2,((IF(($G5="22.2"),22.2,((IF(($G5="22.3"),22.3,((IF(($G5="26.2"),26.2,((IF(($G5="42.2"),42.2,((IF(($G5="44.2"),44.2,((IF(($G5="46.2"),46.2,0)))))))))))))))))))))))) -> 0 | AY5: =((IF(($G5="47.2"),47.2,((IF(($G5="50.2"),50.2,((IF(($G5="8.3"),8.3,((IF(($G5="23.2"),23.2,((IF(($G5="43.2"),43.2,((IF(($G5="45.2"),45.2,((IF(($G5="48.2"),48.2,((IF(($G5="51.2"),51.2,0)))))))))))))))))))))))) -> 0 | AZ5: =((IF(($G5="13.3"),13.3,((IF(($G5=38758),10.2,((IF(($G5=38762),14.2,((IF(($G5=38760),12.2,((IF(($G5=38764),16.2,((IF(($G5=38766),18.2,((IF(($G5=38776),28.2,((IF(($G5="30.2"),30.2,0)))))))))))))))))))))))) -> 0 | BA5: =((IF(($G5="34.1"),34.1,((IF(($G5="35.1"),35.1,((IF(($G5=38733),16.1,((IF(($G5=38768),20.2,((IF(($G5=38774),26.2,((IF(($G5=38771),23.2,((IF(($G5="29.2"),29.2,0))))))))))))))))))))) -> 0 | BC5: =(IF((SUM(AV5:BB5)<>0),(SUM(AV5:BB5)),$G5)) -> 16
A6: =FREQUENCIAS!C$1 -> D1S1656 | B6: ND | C6: ND | D6: 15.3 | E6: 17 | F6: 16 | G6: 17 | H6: =((IF(($B6=38785),9.3,((IF(($B6=38761),13.2,((IF(($B6="31.2"),31.2,((IF(($B6=38787),11.3,((IF(($B6=38759),11.2,((IF(($B6=38763),15.2,((IF(($B6=38765),17.2,((IF(($B6=38772),24.2,0)))))))))))))))))))))))) -> 0 | I6: =((IF(($B6=38800),24.3,((IF(($B6=38773),25.2,((IF(($B6=38046),29.2,((IF(($B6=38075),29.3,((IF(($B6="32.2"),32.2,((IF(($B6="33.2"),33.2,((IF(($B6="34.2"),34.2,((IF(($B6="35.2"),35.2,0)))))))))))))))))))))))) -> 0 | J6: =((IF(($B6=38767),19.2,((IF(($B6="21.2"),21.2,((IF(($B6="22.2"),22.2,((IF(($B6="22.3"),22.3,((IF(($B6="26.2"),26.2,((IF(($B6="42.2"),42.2,((IF(($B6="44.2"),44.2,((IF(($B6="46.2"),46.2,0)))))))))))))))))))))))) -> 0 | K6: =((IF(($B6="47.2"),47.2,((IF(($B6="50.2"),50.2,((IF(($B6="8.3"),8.3,((IF(($B6="23.2"),23.2,((IF(($B6="43.2"),43.2,((IF(($B6="45.2"),45.2,((IF(($B6="48.2"),48.2,((IF(($B6="51.2"),51.2,0)))))))))))))))))))))))) -> 0 | L6: =((IF(($B6="13.3"),13.3,((IF(($B6=38758),10.2,((IF(($B6=38762),14.2,((IF(($B6=38760),12.2,((IF(($B6=38764),16.2,((IF(($B6=38766),18.2,((IF(($B6=38776),28.2,((IF(($B6="30.2"),30.2,0)))))))))))))))))))))))) -> 0 | M6: =((IF(($B6="34.1"),34.1,((IF(($B6="35.1"),35.1,((IF(($B6=38733),16.1,((IF(($B6=38768),20.2,((IF(($B6=38774),26.2,0))))))))))))))) -> 0 | O6: =(IF((SUM(H6:N6)<>0),(SUM(H6:N6)),$B6)) -> ND | P6: =((IF(($C6=38785),9.3,((IF(($C6=38761),13.2,((IF(($C6="31.2"),31.2,((IF(($C6=38787),11.3,((IF(($C6=38759),11.2,((IF(($C6=38763),15.2,((IF(($C6=38765),17.2,((IF(($C6=38772),24.2,0)))))))))))))))))))))))) -> 0 | Q6: =((IF(($C6=38800),24.3,((IF(($C6=38773),25.2,((IF(($C6=38046),29.2,((IF(($C6=38075),29.3,((IF(($C6="32.2"),32.2,((IF(($C6="33.2"),33.2,((IF(($C6="34.2"),34.2,((IF(($C6="35.2"),35.2,0)))))))))))))))))))))))) -> 0 | R6: =((IF(($C6=38767),19.2,((IF(($C6="21.2"),21.2,((IF(($C6="22.2"),22.2,((IF(($C6="22.3"),22.3,((IF(($C6="26.2"),26.2,((IF(($C6="42.2"),42.2,((IF(($C6="44.2"),44.2,((IF(($C6="46.2"),46.2,0)))))))))))))))))))))))) -> 0 | S6: =((IF(($C6="47.2"),47.2,((IF(($C6="50.2"),50.2,((IF(($C6="8.3"),8.3,((IF(($C6="23.2"),23.2,((IF(($C6="43.2"),43.2,((IF(($C6="45.2"),45.2,((IF(($C6="48.2"),48.2,((IF(($C6="51.2"),51.2,0)))))))))))))))))))))))) -> 0 | T6: =((IF(($C6="13.3"),13.3,((IF(($C6=38758),10.2,((IF(($C6=38762),14.2,((IF(($C6=38760),12.2,((IF(($C6=38764),16.2,((IF(($C6=38766),18.2,((IF(($C6=38776),28.2,((IF(($C6="30.2"),30.2,0)))))))))))))))))))))))) -> 0 | U6: =((IF(($C6="34.1"),34.1,((IF(($C6="35.1"),35.1,((IF(($C6=38733),16.1,((IF(($C6=38768),20.2,((IF(($C6=38774),26.2,((IF(($C6=38771),23.2,0)))))))))))))))))) -> 0 | W6: =(IF((SUM(P6:V6)<>0),(SUM(P6:V6)),$C6)) -> ND | X6: =((IF(($D6=38785),9.3,((IF(($D6=38761),13.2,((IF(($D6="31.2"),31.2,((IF(($D6=38787),11.3,((IF(($D6=38759),11.2,((IF(($D6=38763),15.2,((IF(($D6=38765),17.2,((IF(($D6=38772),24.2,0)))))))))))))))))))))))) -> 0 | Y6: =((IF(($D6=38800),24.3,((IF(($D6=38773),25.2,((IF(($D6=38046),29.2,((IF(($D6=38075),29.3,((IF(($D6="32.2"),32.2,((IF(($D6="33.2"),33.2,((IF(($D6="34.2"),34.2,((IF(($D6="35.2"),35.2,0)))))))))))))))))))))))) -> 0 | Z6: =((IF(($D6=38767),19.2,((IF(($D6="21.2"),21.2,((IF(($D6="22.2"),22.2,((IF(($D6="22.3"),22.3,((IF(($D6="26.2"),26.2,((IF(($D6="42.2"),42.2,((IF(($D6="44.2"),44.2,((IF(($D6="46.2"),46.2,0)))))))))))))))))))))))) -> 0 | AA6: =((IF(($D6="47.2"),47.2,((IF(($D6="50.2"),50.2,((IF(($D6="8.3"),8.3,((IF(($D6="23.2"),23.2,((IF(($D6="43.2"),43.2,((IF(($D6="45.2"),45.2,((IF(($D6="48.2"),48.2,((IF(($D6="51.2"),51.2,0)))))))))))))))))))))))) -> 0 | AB6: =((IF(($D6="13.3"),13.3,((IF(($D6=38758),10.2,((IF(($D6=38762),14.2,((IF(($D6=38760),12.2,((IF(($D6=38764),16.2,((IF(($D6=38766),18.2,((IF(($D6=38776),28.2,((IF(($D6="30.2"),30.2,0)))))))))))))))))))))))) -> 0 | AC6: =((IF(($D6="34.1"),34.1,((IF(($D6="35.1"),35.1,((IF(($D6=38733),16.1,((IF(($D6=38768),20.2,((IF(($D6=38774),26.2,0))))))))))))))) -> 0 | AE6: =(IF((SUM(X6:AD6)<>0),(SUM(X6:AD6)),$D6)) -> 15.3 | AF6: =((IF(($E6=38785),9.3,((IF(($E6=38761),13.2,((IF(($E6="31.2"),31.2,((IF(($E6=38787),11.3,((IF(($E6=38759),11.2,((IF(($E6=38763),15.2,((IF(($E6=38765),17.2,((IF(($E6=38772),24.2,0)))))))))))))))))))))))) -> 0 | AG6: =((IF(($E6=38800),24.3,((IF(($E6=38773),25.2,((IF(($E6=38046),29.2,((IF(($E6=38075),29.3,((IF(($E6="32.2"),32.2,((IF(($E6="33.2"),33.2,((IF(($E6="34.2"),34.2,((IF(($E6="35.2"),35.2,0)))))))))))))))))))))))) -> 0 | AH6: =((IF(($E6=38767),19.2,((IF(($E6="21.2"),21.2,((IF(($E6="22.2"),22.2,((IF(($E6="22.3"),22.3,((IF(($E6="26.2"),26.2,((IF(($E6="42.2"),42.2,((IF(($E6="44.2"),44.2,((IF(($E6="46.2"),46.2,0)))))))))))))))))))))))) -> 0 | AI6: =((IF(($E6="47.2"),47.2,((IF(($E6="50.2"),50.2,((IF(($E6="8.3"),8.3,((IF(($E6="23.2"),23.2,((IF(($E6="43.2"),43.2,((IF(($E6="45.2"),45.2,((IF(($E6="48.2"),48.2,((IF(($E6="51.2"),51.2,0)))))))))))))))))))))))) -> 0 | AJ6: =((IF(($E6="13.3"),13.3,((IF(($E6=38758),10.2,((IF(($E6=38762),14.2,((IF(($E6=38760),12.2,((IF(($E6=38764),16.2,((IF(($E6=38766),18.2,((IF(($E6=38776),28.2,((IF(($E6="30.2"),30.2,0)))))))))))))))))))))))) -> 0 | AK6: =((IF(($E6="34.1"),34.1,((IF(($E6="35.1"),35.1,((IF(($E6=38733),16.1,((IF(($E6=38768),20.2,((IF(($E6=38774),26.2,((IF(($E6=38771),23.2,0)))))))))))))))))) -> 0 | AM6: =(IF((SUM(AF6:AL6)<>0),(SUM(AF6:AL6)),$E6)) -> 17 | AN6: =((IF(($F6=38785),9.3,((IF(($F6=38761),13.2,((IF(($F6="31.2"),31.2,((IF(($F6=38787),11.3,((IF(($F6=38759),11.2,((IF(($F6=38763),15.2,((IF(($F6=38765),17.2,((IF(($F6=38772),24.2,0)))))))))))))))))))))))) -> 0 | AO6: =((IF(($F6=38800),24.3,((IF(($F6=38773),25.2,((IF(($F6=38046),29.2,((IF(($F6=38075),29.3,((IF(($F6="32.2"),32.2,((IF(($F6="33.2"),33.2,((IF(($F6="34.2"),34.2,((IF(($F6="35.2"),35.2,0)))))))))))))))))))))))) -> 0 | AP6: =((IF(($F6=38767),19.2,((IF(($F6="21.2"),21.2,((IF(($F6="22.2"),22.2,((IF(($F6="22.3"),22.3,((IF(($F6="26.2"),26.2,((IF(($F6="42.2"),42.2,((IF(($F6="44.2"),44.2,((IF(($F6="46.2"),46.2,0)))))))))))))))))))))))) -> 0 | AQ6: =((IF(($F6="47.2"),47.2,((IF(($F6="50.2"),50.2,((IF(($F6="8.3"),8.3,((IF(($F6="23.2"),23.2,((IF(($F6="43.2"),43.2,((IF(($F6="45.2"),45.2,((IF(($F6="48.2"),48.2,((IF(($F6="51.2"),51.2,0)))))))))))))))))))))))) -> 0 | AR6: =((IF(($F6="13.3"),13.3,((IF(($F6=38758),10.2,((IF(($F6=38762),14.2,((IF(($F6=38760),12.2,((IF(($F6=38764),16.2,((IF(($F6=38766),18.2,((IF(($F6=38776),28.2,((IF(($F6="30.2"),30.2,0)))))))))))))))))))))))) -> 0 | AS6: =((IF(($F6="34.1"),34.1,((IF(($F6="35.1"),35.1,((IF(($F6=38733),16.1,((IF(($F6=38768),20.2,((IF(($F6=38774),26.2,0))))))))))))))) -> 0 | AU6: =(IF((SUM(AN6:AT6)<>0),(SUM(AN6:AT6)),$F6)) -> 16 | AV6: =((IF(($G6=38785),9.3,((IF(($G6=38761),13.2,((IF(($G6="31.2"),31.2,((IF(($G6=38787),11.3,((IF(($G6=38759),11.2,((IF(($G6=38763),15.2,((IF(($G6=38765),17.2,((IF(($G6=38772),24.2,0)))))))))))))))))))))))) -> 0 | AW6: =((IF(($G6=38800),24.3,((IF(($G6=38773),25.2,((IF(($G6=38046),29.2,((IF(($G6=38075),29.3,((IF(($G6="32.2"),32.2,((IF(($G6="33.2"),33.2,((IF(($G6="34.2"),34.2,((IF(($G6="35.2"),35.2,0)))))))))))))))))))))))) -> 0 | AX6: =((IF(($G6=38767),19.2,((IF(($G6="21.2"),21.2,((IF(($G6="22.2"),22.2,((IF(($G6="22.3"),22.3,((IF(($G6="26.2"),26.2,((IF(($G6="42.2"),42.2,((IF(($G6="44.2"),44.2,((IF(($G6="46.2"),46.2,0)))))))))))))))))))))))) -> 0 | AY6: =((IF(($G6="47.2"),47.2,((IF(($G6="50.2"),50.2,((IF(($G6="8.3"),8.3,((IF(($G6="23.2"),23.2,((IF(($G6="43.2"),43.2,((IF(($G6="45.2"),45.2,((IF(($G6="48.2"),48.2,((IF(($G6="51.2"),51.2,0)))))))))))))))))))))))) -> 0 | AZ6: =((IF(($G6="13.3"),13.3,((IF(($G6=38758),10.2,((IF(($G6=38762),14.2,((IF(($G6=38760),12.2,((IF(($G6=38764),16.2,((IF(($G6=38766),18.2,((IF(($G6=38776),28.2,((IF(($G6="30.2"),30.2,0)))))))))))))))))))))))) -> 0 | BA6: =((IF(($G6="34.1"),34.1,((IF(($G6="35.1"),35.1,((IF(($G6=38733),16.1,((IF(($G6=38768),20.2,((IF(($G6=38774),26.2,((IF(($G6=38771),23.2,0)))))))))))))))))) -> 0 | BC6: =(IF((SUM(AV6:BB6)<>0),(SUM(AV6:BB6)),$G6)) -> 17
A7: =FREQUENCIAS!D$1 -> D2S441 | B7: ND | C7: ND | D7: 10 | E7: 11 | F7: 10 | G7: 11 | H7: =((IF(($B7=38785),9.3,((IF(($B7=38761),13.2,((IF(($B7="31.2"),31.2,((IF(($B7=38787),11.3,((IF(($B7=38759),11.2,((IF(($B7=38763),15.2,((IF(($B7=38765),17.2,((IF(($B7=38772),24.2,0)))))))))))))))))))))))) -> 0 | I7: =((IF(($B7=38800),24.3,((IF(($B7=38773),25.2,((IF(($B7=38046),29.2,((IF(($B7=38075),29.3,((IF(($B7="32.2"),32.2,((IF(($B7="33.2"),33.2,((IF(($B7="34.2"),34.2,((IF(($B7="35.2"),35.2,0)))))))))))))))))))))))) -> 0 | J7: =((IF(($B7=38767),19.2,((IF(($B7="21.2"),21.2,((IF(($B7="22.2"),22.2,((IF(($B7="22.3"),22.3,((IF(($B7="26.2"),26.2,((IF(($B7="42.2"),42.2,((IF(($B7="44.2"),44.2,((IF(($B7="46.2"),46.2,0)))))))))))))))))))))))) -> 0 | K7: =((IF(($B7="47.2"),47.2,((IF(($B7="50.2"),50.2,((IF(($B7="8.3"),8.3,((IF(($B7="23.2"),23.2,((IF(($B7="43.2"),43.2,((IF(($B7="45.2"),45.2,((IF(($B7="48.2"),48.2,((IF(($B7="51.2"),51.2,0)))))))))))))))))))))))) -> 0 | L7: =((IF(($B7="13.3"),13.3,((IF(($B7=38758),10.2,((IF(($B7=38762),14.2,((IF(($B7=38760),12.2,((IF(($B7=38764),16.2,((IF(($B7=38766),18.2,((IF(($B7=38776),28.2,((IF(($B7="30.2"),30.2,0)))))))))))))))))))))))) -> 0 | M7: =((IF(($B7="34.1"),34.1,((IF(($B7="35.1"),35.1,((IF(($B7=38733),16.1,((IF(($B7=38768),20.2,((IF(($B7=38774),26.2,0))))))))))))))) -> 0 | O7: =(IF((SUM(H7:N7)<>0),(SUM(H7:N7)),$B7)) -> ND | P7: =((IF(($C7=38785),9.3,((IF(($C7=38761),13.2,((IF(($C7="31.2"),31.2,((IF(($C7=38787),11.3,((IF(($C7=38759),11.2,((IF(($C7=38763),15.2,((IF(($C7=38765),17.2,((IF(($C7=38772),24.2,0)))))))))))))))))))))))) -> 0 | Q7: =((IF(($C7=38800),24.3,((IF(($C7=38773),25.2,((IF(($C7=38046),29.2,((IF(($C7=38075),29.3,((IF(($C7="32.2"),32.2,((IF(($C7="33.2"),33.2,((IF(($C7="34.2"),34.2,((IF(($C7="35.2"),35.2,0)))))))))))))))))))))))) -> 0 | R7: =((IF(($C7=38767),19.2,((IF(($C7="21.2"),21.2,((IF(($C7="22.2"),22.2,((IF(($C7="22.3"),22.3,((IF(($C7="26.2"),26.2,((IF(($C7="42.2"),42.2,((IF(($C7="44.2"),44.2,((IF(($C7="46.2"),46.2,0)))))))))))))))))))))))) -> 0 | S7: =((IF(($C7="47.2"),47.2,((IF(($C7="50.2"),50.2,((IF(($C7="8.3"),8.3,((IF(($C7="23.2"),23.2,((IF(($C7="43.2"),43.2,((IF(($C7="45.2"),45.2,((IF(($C7="48.2"),48.2,((IF(($C7="51.2"),51.2,0)))))))))))))))))))))))) -> 0 | T7: =((IF(($C7="13.3"),13.3,((IF(($C7=38758),10.2,((IF(($C7=38762),14.2,((IF(($C7=38760),12.2,((IF(($C7=38764),16.2,((IF(($C7=38766),18.2,((IF(($C7=38776),28.2,((IF(($C7="30.2"),30.2,0)))))))))))))))))))))))) -> 0 | U7: =((IF(($C7="34.1"),34.1,((IF(($C7="35.1"),35.1,((IF(($C7=38733),16.1,((IF(($C7=38768),20.2,((IF(($C7=38774),26.2,((IF(($C7=38771),23.2,0)))))))))))))))))) -> 0 | W7: =(IF((SUM(P7:V7)<>0),(SUM(P7:V7)),$C7)) -> ND | X7: =((IF(($D7=38785),9.3,((IF(($D7=38761),13.2,((IF(($D7="31.2"),31.2,((IF(($D7=38787),11.3,((IF(($D7=38759),11.2,((IF(($D7=38763),15.2,((IF(($D7=38765),17.2,((IF(($D7=38772),24.2,0)))))))))))))))))))))))) -> 0 | Y7: =((IF(($D7=38800),24.3,((IF(($D7=38773),25.2,((IF(($D7=38046),29.2,((IF(($D7=38075),29.3,((IF(($D7="32.2"),32.2,((IF(($D7="33.2"),33.2,((IF(($D7="34.2"),34.2,((IF(($D7="35.2"),35.2,0)))))))))))))))))))))))) -> 0 | Z7: =((IF(($D7=38767),19.2,((IF(($D7="21.2"),21.2,((IF(($D7="22.2"),22.2,((IF(($D7="22.3"),22.3,((IF(($D7="26.2"),26.2,((IF(($D7="42.2"),42.2,((IF(($D7="44.2"),44.2,((IF(($D7="46.2"),46.2,0)))))))))))))))))))))))) -> 0 | AA7: =((IF(($D7="47.2"),47.2,((IF(($D7="50.2"),50.2,((IF(($D7="8.3"),8.3,((IF(($D7="23.2"),23.2,((IF(($D7="43.2"),43.2,((IF(($D7="45.2"),45.2,((IF(($D7="48.2"),48.2,((IF(($D7="51.2"),51.2,0)))))))))))))))))))))))) -> 0 | AB7: =((IF(($D7="13.3"),13.3,((IF(($D7=38758),10.2,((IF(($D7=38762),14.2,((IF(($D7=38760),12.2,((IF(($D7=38764),16.2,((IF(($D7=38766),18.2,((IF(($D7=38776),28.2,((IF(($D7="30.2"),30.2,0)))))))))))))))))))))))) -> 0 | AC7: =((IF(($D7="34.1"),34.1,((IF(($D7="35.1"),35.1,((IF(($D7=38733),16.1,((IF(($D7=38768),20.2,((IF(($D7=38774),26.2,0))))))))))))))) -> 0 | AE7: =(IF((SUM(X7:AD7)<>0),(SUM(X7:AD7)),$D7)) -> 10 | AF7: =((IF(($E7=38785),9.3,((IF(($E7=38761),13.2,((IF(($E7="31.2"),31.2,((IF(($E7=38787),11.3,((IF(($E7=38759),11.2,((IF(($E7=38763),15.2,((IF(($E7=38765),17.2,((IF(($E7=38772),24.2,0)))))))))))))))))))))))) -> 0 | AG7: =((IF(($E7=38800),24.3,((IF(($E7=38773),25.2,((IF(($E7=38046),29.2,((IF(($E7=38075),29.3,((IF(($E7="32.2"),32.2,((IF(($E7="33.2"),33.2,((IF(($E7="34.2"),34.2,((IF(($E7="35.2"),35.2,0)))))))))))))))))))))))) -> 0 | AH7: =((IF(($E7=38767),19.2,((IF(($E7="21.2"),21.2,((IF(($E7="22.2"),22.2,((IF(($E7="22.3"),22.3,((IF(($E7="26.2"),26.2,((IF(($E7="42.2"),42.2,((IF(($E7="44.2"),44.2,((IF(($E7="46.2"),46.2,0)))))))))))))))))))))))) -> 0 | AI7: =((IF(($E7="47.2"),47.2,((IF(($E7="50.2"),50.2,((IF(($E7="8.3"),8.3,((IF(($E7="23.2"),23.2,((IF(($E7="43.2"),43.2,((IF(($E7="45.2"),45.2,((IF(($E7="48.2"),48.2,((IF(($E7="51.2"),51.2,0)))))))))))))))))))))))) -> 0 | AJ7: =((IF(($E7="13.3"),13.3,((IF(($E7=38758),10.2,((IF(($E7=38762),14.2,((IF(($E7=38760),12.2,((IF(($E7=38764),16.2,((IF(($E7=38766),18.2,((IF(($E7=38776),28.2,((IF(($E7="30.2"),30.2,0)))))))))))))))))))))))) -> 0 | AK7: =((IF(($E7="34.1"),34.1,((IF(($E7="35.1"),35.1,((IF(($E7=38733),16.1,((IF(($E7=38768),20.2,((IF(($E7=38774),26.2,((IF(($E7=38771),23.2,0)))))))))))))))))) -> 0 | AM7: =(IF((SUM(AF7:AL7)<>0),(SUM(AF7:AL7)),$E7)) -> 11 | AN7: =((IF(($F7=38785),9.3,((IF(($F7=38761),13.2,((IF(($F7="31.2"),31.2,((IF(($F7=38787),11.3,((IF(($F7=38759),11.2,((IF(($F7=38763),15.2,((IF(($F7=38765),17.2,((IF(($F7=38772),24.2,0)))))))))))))))))))))))) -> 0 | AO7: =((IF(($F7=38800),24.3,((IF(($F7=38773),25.2,((IF(($F7=38046),29.2,((IF(($F7=38075),29.3,((IF(($F7="32.2"),32.2,((IF(($F7="33.2"),33.2,((IF(($F7="34.2"),34.2,((IF(($F7="35.2"),35.2,0)))))))))))))))))))))))) -> 0 | AP7: =((IF(($F7=38767),19.2,((IF(($F7="21.2"),21.2,((IF(($F7="22.2"),22.2,((IF(($F7="22.3"),22.3,((IF(($F7="26.2"),26.2,((IF(($F7="42.2"),42.2,((IF(($F7="44.2"),44.2,((IF(($F7="46.2"),46.2,0)))))))))))))))))))))))) -> 0 | AQ7: =((IF(($F7="47.2"),47.2,((IF(($F7="50.2"),50.2,((IF(($F7="8.3"),8.3,((IF(($F7="23.2"),23.2,((IF(($F7="43.2"),43.2,((IF(($F7="45.2"),45.2,((IF(($F7="48.2"),48.2,((IF(($F7="51.2"),51.2,0)))))))))))))))))))))))) -> 0 | AR7: =((IF(($F7="13.3"),13.3,((IF(($F7=38758),10.2,((IF(($F7=38762),14.2,((IF(($F7=38760),12.2,((IF(($F7=38764),16.2,((IF(($F7=38766),18.2,((IF(($F7=38776),28.2,((IF(($F7="30.2"),30.2,0)))))))))))))))))))))))) -> 0 | AS7: =((IF(($F7="34.1"),34.1,((IF(($F7="35.1"),35.1,((IF(($F7=38733),16.1,((IF(($F7=38768),20.2,((IF(($F7=38774),26.2,0))))))))))))))) -> 0 | AU7: =(IF((SUM(AN7:AT7)<>0),(SUM(AN7:AT7)),$F7)) -> 10 | AV7: =((IF(($G7=38785),9.3,((IF(($G7=38761),13.2,((IF(($G7="31.2"),31.2,((IF(($G7=38787),11.3,((IF(($G7=38759),11.2,((IF(($G7=38763),15.2,((IF(($G7=38765),17.2,((IF(($G7=38772),24.2,0)))))))))))))))))))))))) -> 0 | AW7: =((IF(($G7=38800),24.3,((IF(($G7=38773),25.2,((IF(($G7=38046),29.2,((IF(($G7=38075),29.3,((IF(($G7="32.2"),32.2,((IF(($G7="33.2"),33.2,((IF(($G7="34.2"),34.2,((IF(($G7="35.2"),35.2,0)))))))))))))))))))))))) -> 0 | AX7: =((IF(($G7=38767),19.2,((IF(($G7="21.2"),21.2,((IF(($G7="22.2"),22.2,((IF(($G7="22.3"),22.3,((IF(($G7="26.2"),26.2,((IF(($G7="42.2"),42.2,((IF(($G7="44.2"),44.2,((IF(($G7="46.2"),46.2,0)))))))))))))))))))))))) -> 0 | AY7: =((IF(($G7="47.2"),47.2,((IF(($G7="50.2"),50.2,((IF(($G7="8.3"),8.3,((IF(($G7="23.2"),23.2,((IF(($G7="43.2"),43.2,((IF(($G7="45.2"),45.2,((IF(($G7="48.2"),48.2,((IF(($G7="51.2"),51.2,0)))))))))))))))))))))))) -> 0 | AZ7: =((IF(($G7="13.3"),13.3,((IF(($G7=38758),10.2,((IF(($G7=38762),14.2,((IF(($G7=38760),12.2,((IF(($G7=38764),16.2,((IF(($G7=38766),18.2,((IF(($G7=38776),28.2,((IF(($G7="30.2"),30.2,0)))))))))))))))))))))))) -> 0 | BA7: =((IF(($G7="34.1"),34.1,((IF(($G7="35.1"),35.1,((IF(($G7=38733),16.1,((IF(($G7=38768),20.2,((IF(($G7=38774),26.2,((IF(($G7=38771),23.2,0)))))))))))))))))) -> 0 | BC7: =(IF((SUM(AV7:BB7)<>0),(SUM(AV7:BB7)),$G7)) -> 11
A8: =FREQUENCIAS!E$1 -> D10S1248 | B8: ND | C8: ND | D8: 14 | E8: 15 | F8: 13 | G8: 14 | H8: =((IF(($B8=38785),9.3,((IF(($B8=38761),13.2,((IF(($B8="31.2"),31.2,((IF(($B8=38787),11.3,((IF(($B8=38759),11.2,((IF(($B8=38763),15.2,((IF(($B8=38765),17.2,((IF(($B8=38772),24.2,0)))))))))))))))))))))))) -> 0 | I8: =((IF(($B8=38800),24.3,((IF(($B8=38773),25.2,((IF(($B8=38046),29.2,((IF(($B8=38075),29.3,((IF(($B8="32.2"),32.2,((IF(($B8="33.2"),33.2,((IF(($B8="34.2"),34.2,((IF(($B8="35.2"),35.2,0)))))))))))))))))))))))) -> 0 | J8: =((IF(($B8=38767),19.2,((IF(($B8="21.2"),21.2,((IF(($B8="22.2"),22.2,((IF(($B8="22.3"),22.3,((IF(($B8="26.2"),26.2,((IF(($B8="42.2"),42.2,((IF(($B8="44.2"),44.2,((IF(($B8="46.2"),46.2,0)))))))))))))))))))))))) -> 0 | K8: =((IF(($B8="47.2"),47.2,((IF(($B8="50.2"),50.2,((IF(($B8="8.3"),8.3,((IF(($B8="23.2"),23.2,((IF(($B8="43.2"),43.2,((IF(($B8="45.2"),45.2,((IF(($B8="48.2"),48.2,((IF(($B8="51.2"),51.2,0)))))))))))))))))))))))) -> 0 | L8: =((IF(($B8="13.3"),13.3,((IF(($B8=38758),10.2,((IF(($B8=38762),14.2,((IF(($B8=38760),12.2,((IF(($B8=38764),16.2,((IF(($B8=38766),18.2,((IF(($B8=38776),28.2,((IF(($B8="30.2"),30.2,0)))))))))))))))))))))))) -> 0 | M8: =((IF(($B8="34.1"),34.1,((IF(($B8="35.1"),35.1,((IF(($B8=38733),16.1,((IF(($B8=38768),20.2,((IF(($B8=38774),26.2,0))))))))))))))) -> 0 | O8: =(IF((SUM(H8:N8)<>0),(SUM(H8:N8)),$B8)) -> ND | P8: =((IF(($C8=38785),9.3,((IF(($C8=38761),13.2,((IF(($C8="31.2"),31.2,((IF(($C8=38787),11.3,((IF(($C8=38759),11.2,((IF(($C8=38763),15.2,((IF(($C8=38765),17.2,((IF(($C8=38772),24.2,0)))))))))))))))))))))))) -> 0 | Q8: =((IF(($C8=38800),24.3,((IF(($C8=38773),25.2,((IF(($C8=38046),29.2,((IF(($C8=38075),29.3,((IF(($C8="32.2"),32.2,((IF(($C8="33.2"),33.2,((IF(($C8="34.2"),34.2,((IF(($C8="35.2"),35.2,0)))))))))))))))))))))))) -> 0 | R8: =((IF(($C8=38767),19.2,((IF(($C8="21.2"),21.2,((IF(($C8="22.2"),22.2,((IF(($C8="22.3"),22.3,((IF(($C8="26.2"),26.2,((IF(($C8="42.2"),42.2,((IF(($C8="44.2"),44.2,((IF(($C8="46.2"),46.2,0)))))))))))))))))))))))) -> 0 | S8: =((IF(($C8="47.2"),47.2,((IF(($C8="50.2"),50.2,((IF(($C8="8.3"),8.3,((IF(($C8="23.2"),23.2,((IF(($C8="43.2"),43.2,((IF(($C8="45.2"),45.2,((IF(($C8="48.2"),48.2,((IF(($C8="51.2"),51.2,0)))))))))))))))))))))))) -> 0 | T8: =((IF(($C8="13.3"),13.3,((IF(($C8=38758),10.2,((IF(($C8=38762),14.2,((IF(($C8=38760),12.2,((IF(($C8=38764),16.2,((IF(($C8=38766),18.2,((IF(($C8=38776),28.2,((IF(($C8="30.2"),30.2,0)))))))))))))))))))))))) -> 0 | U8: =((IF(($C8="34.1"),34.1,((IF(($C8="35.1"),35.1,((IF(($C8=38733),16.1,((IF(($C8=38768),20.2,((IF(($C8=38774),26.2,((IF(($C8=38771),23.2,0)))))))))))))))))) -> 0 | W8: =(IF((SUM(P8:V8)<>0),(SUM(P8:V8)),$C8)) -> ND | X8: =((IF(($D8=38785),9.3,((IF(($D8=38761),13.2,((IF(($D8="31.2"),31.2,((IF(($D8=38787),11.3,((IF(($D8=38759),11.2,((IF(($D8=38763),15.2,((IF(($D8=38765),17.2,((IF(($D8=38772),24.2,0)))))))))))))))))))))))) -> 0 | Y8: =((IF(($D8=38800),24.3,((IF(($D8=38773),25.2,((IF(($D8=38046),29.2,((IF(($D8=38075),29.3,((IF(($D8="32.2"),32.2,((IF(($D8="33.2"),33.2,((IF(($D8="34.2"),34.2,((IF(($D8="35.2"),35.2,0)))))))))))))))))))))))) -> 0 | Z8: =((IF(($D8=38767),19.2,((IF(($D8="21.2"),21.2,((IF(($D8="22.2"),22.2,((IF(($D8="22.3"),22.3,((IF(($D8="26.2"),26.2,((IF(($D8="42.2"),42.2,((IF(($D8="44.2"),44.2,((IF(($D8="46.2"),46.2,0)))))))))))))))))))))))) -> 0 | AA8: =((IF(($D8="47.2"),47.2,((IF(($D8="50.2"),50.2,((IF(($D8="8.3"),8.3,((IF(($D8="23.2"),23.2,((IF(($D8="43.2"),43.2,((IF(($D8="45.2"),45.2,((IF(($D8="48.2"),48.2,((IF(($D8="51.2"),51.2,0)))))))))))))))))))))))) -> 0 | AB8: =((IF(($D8="13.3"),13.3,((IF(($D8=38758),10.2,((IF(($D8=38762),14.2,((IF(($D8=38760),12.2,((IF(($D8=38764),16.2,((IF(($D8=38766),18.2,((IF(($D8=38776),28.2,((IF(($D8="30.2"),30.2,0)))))))))))))))))))))))) -> 0 | AC8: =((IF(($D8="34.1"),34.1,((IF(($D8="35.1"),35.1,((IF(($D8=38733),16.1,((IF(($D8=38768),20.2,((IF(($D8=38774),26.2,0))))))))))))))) -> 0 | AE8: =(IF((SUM(X8:AD8)<>0),(SUM(X8:AD8)),$D8)) -> 14 | AF8: =((IF(($E8=38785),9.3,((IF(($E8=38761),13.2,((IF(($E8="31.2"),31.2,((IF(($E8=38787),11.3,((IF(($E8=38759),11.2,((IF(($E8=38763),15.2,((IF(($E8=38765),17.2,((IF(($E8=38772),24.2,0)))))))))))))))))))))))) -> 0 | AG8: =((IF(($E8=38800),24.3,((IF(($E8=38773),25.2,((IF(($E8=38046),29.2,((IF(($E8=38075),29.3,((IF(($E8="32.2"),32.2,((IF(($E8="33.2"),33.2,((IF(($E8="34.2"),34.2,((IF(($E8="35.2"),35.2,0)))))))))))))))))))))))) -> 0 | AH8: =((IF(($E8=38767),19.2,((IF(($E8="21.2"),21.2,((IF(($E8="22.2"),22.2,((IF(($E8="22.3"),22.3,((IF(($E8="26.2"),26.2,((IF(($E8="42.2"),42.2,((IF(($E8="44.2"),44.2,((IF(($E8="46.2"),46.2,0)))))))))))))))))))))))) -> 0 | AI8: =((IF(($E8="47.2"),47.2,((IF(($E8="50.2"),50.2,((IF(($E8="8.3"),8.3,((IF(($E8="23.2"),23.2,((IF(($E8="43.2"),43.2,((IF(($E8="45.2"),45.2,((IF(($E8="48.2"),48.2,((IF(($E8="51.2"),51.2,0)))))))))))))))))))))))) -> 0 | AJ8: =((IF(($E8="13.3"),13.3,((IF(($E8=38758),10.2,((IF(($E8=38762),14.2,((IF(($E8=38760),12.2,((IF(($E8=38764),16.2,((IF(($E8=38766),18.2,((IF(($E8=38776),28.2,((IF(($E8="30.2"),30.2,0)))))))))))))))))))))))) -> 0 | AK8: =((IF(($E8="34.1"),34.1,((IF(($E8="35.1"),35.1,((IF(($E8=38733),16.1,((IF(($E8=38768),20.2,((IF(($E8=38774),26.2,((IF(($E8=38771),23.2,0)))))))))))))))))) -> 0 | AM8: =(IF((SUM(AF8:AL8)<>0),(SUM(AF8:AL8)),$E8)) -> 15 | AN8: =((IF(($F8=38785),9.3,((IF(($F8=38761),13.2,((IF(($F8="31.2"),31.2,((IF(($F8=38787),11.3,((IF(($F8=38759),11.2,((IF(($F8=38763),15.2,((IF(($F8=38765),17.2,((IF(($F8=38772),24.2,0)))))))))))))))))))))))) -> 0 | AO8: =((IF(($F8=38800),24.3,((IF(($F8=38773),25.2,((IF(($F8=38046),29.2,((IF(($F8=38075),29.3,((IF(($F8="32.2"),32.2,((IF(($F8="33.2"),33.2,((IF(($F8="34.2"),34.2,((IF(($F8="35.2"),35.2,0)))))))))))))))))))))))) -> 0 | AP8: =((IF(($F8=38767),19.2,((IF(($F8="21.2"),21.2,((IF(($F8="22.2"),22.2,((IF(($F8="22.3"),22.3,((IF(($F8="26.2"),26.2,((IF(($F8="42.2"),42.2,((IF(($F8="44.2"),44.2,((IF(($F8="46.2"),46.2,0)))))))))))))))))))))))) -> 0 | AQ8: =((IF(($F8="47.2"),47.2,((IF(($F8="50.2"),50.2,((IF(($F8="8.3"),8.3,((IF(($F8="23.2"),23.2,((IF(($F8="43.2"),43.2,((IF(($F8="45.2"),45.2,((IF(($F8="48.2"),48.2,((IF(($F8="51.2"),51.2,0)))))))))))))))))))))))) -> 0 | AR8: =((IF(($F8="13.3"),13.3,((IF(($F8=38758),10.2,((IF(($F8=38762),14.2,((IF(($F8=38760),12.2,((IF(($F8=38764),16.2,((IF(($F8=38766),18.2,((IF(($F8=38776),28.2,((IF(($F8="30.2"),30.2,0)))))))))))))))))))))))) -> 0 | AS8: =((IF(($F8="34.1"),34.1,((IF(($F8="35.1"),35.1,((IF(($F8=38733),16.1,((IF(($F8=38768),20.2,((IF(($F8=38774),26.2,0))))))))))))))) -> 0 | AU8: =(IF((SUM(AN8:AT8)<>0),(SUM(AN8:AT8)),$F8)) -> 13 | AV8: =((IF(($G8=38785),9.3,((IF(($G8=38761),13.2,((IF(($G8="31.2"),31.2,((IF(($G8=38787),11.3,((IF(($G8=38759),11.2,((IF(($G8=38763),15.2,((IF(($G8=38765),17.2,((IF(($G8=38772),24.2,0)))))))))))))))))))))))) -> 0 | AW8: =((IF(($G8=38800),24.3,((IF(($G8=38773),25.2,((IF(($G8=38046),29.2,((IF(($G8=38075),29.3,((IF(($G8="32.2"),32.2,((IF(($G8="33.2"),33.2,((IF(($G8="34.2"),34.2,((IF(($G8="35.2"),35.2,0)))))))))))))))))))))))) -> 0 | AX8: =((IF(($G8=38767),19.2,((IF(($G8="21.2"),21.2,((IF(($G8="22.2"),22.2,((IF(($G8="22.3"),22.3,((IF(($G8="26.2"),26.2,((IF(($G8="42.2"),42.2,((IF(($G8="44.2"),44.2,((IF(($G8="46.2"),46.2,0)))))))))))))))))))))))) -> 0 | AY8: =((IF(($G8="47.2"),47.2,((IF(($G8="50.2"),50.2,((IF(($G8="8.3"),8.3,((IF(($G8="23.2"),23.2,((IF(($G8="43.2"),43.2,((IF(($G8="45.2"),45.2,((IF(($G8="48.2"),48.2,((IF(($G8="51.2"),51.2,0)))))))))))))))))))))))) -> 0 | AZ8: =((IF(($G8="13.3"),13.3,((IF(($G8=38758),10.2,((IF(($G8=38762),14.2,((IF(($G8=38760),12.2,((IF(($G8=38764),16.2,((IF(($G8=38766),18.2,((IF(($G8=38776),28.2,((IF(($G8="30.2"),30.2,0)))))))))))))))))))))))) -> 0 | BA8: =((IF(($G8="34.1"),34.1,((IF(($G8="35.1"),35.1,((IF(($G8=38733),16.1,((IF(($G8=38768),20.2,((IF(($G8=38774),26.2,((IF(($G8=38771),23.2,0)))))))))))))))))) -> 0 | BC8: =(IF((SUM(AV8:BB8)<>0),(SUM(AV8:BB8)),$G8)) -> 14
A9: =FREQUENCIAS!F$1 -> D13S317 | B9: ND | C9: ND | D9: 12 | E9: 14 | F9: 13 | G9: 14 | H9: =((IF(($B9=38785),9.3,((IF(($B9=38761),13.2,((IF(($B9="31.2"),31.2,((IF(($B9=38787),11.3,((IF(($B9=38759),11.2,((IF(($B9=38763),15.2,((IF(($B9=38765),17.2,((IF(($B9=38772),24.2,0)))))))))))))))))))))))) -> 0 | I9: =((IF(($B9=38800),24.3,((IF(($B9=38773),25.2,((IF(($B9=38046),29.2,((IF(($B9=38075),29.3,((IF(($B9="32.2"),32.2,((IF(($B9="33.2"),33.2,((IF(($B9="34.2"),34.2,((IF(($B9="35.2"),35.2,0)))))))))))))))))))))))) -> 0 | J9: =((IF(($B9=38767),19.2,((IF(($B9="21.2"),21.2,((IF(($B9="22.2"),22.2,((IF(($B9="22.3"),22.3,((IF(($B9="26.2"),26.2,((IF(($B9="42.2"),42.2,((IF(($B9="44.2"),44.2,((IF(($B9="46.2"),46.2,0)))))))))))))))))))))))) -> 0 | K9: =((IF(($B9="47.2"),47.2,((IF(($B9="50.2"),50.2,((IF(($B9="8.3"),8.3,((IF(($B9="23.2"),23.2,((IF(($B9="43.2"),43.2,((IF(($B9="45.2"),45.2,((IF(($B9="48.2"),48.2,((IF(($B9="51.2"),51.2,0)))))))))))))))))))))))) -> 0 | L9: =((IF(($B9="13.3"),13.3,((IF(($B9=38758),10.2,((IF(($B9=38762),14.2,((IF(($B9=38760),12.2,((IF(($B9=38764),16.2,((IF(($B9=38766),18.2,((IF(($B9=38776),28.2,((IF(($B9="30.2"),30.2,0)))))))))))))))))))))))) -> 0 | M9: =((IF(($B9="34.1"),34.1,((IF(($B9="35.1"),35.1,((IF(($B9=38733),16.1,((IF(($B9=38768),20.2,((IF(($B9=38774),26.2,((IF(($B9=38784),8.3,((IF(($B9=38789),13.3,0))))))))))))))))))))) -> 0 | O9: =(IF((SUM(H9:N9)<>0),(SUM(H9:N9)),$B9)) -> ND | P9: =((IF(($C9=38785),9.3,((IF(($C9=38761),13.2,((IF(($C9="31.2"),31.2,((IF(($C9=38787),11.3,((IF(($C9=38759),11.2,((IF(($C9=38763),15.2,((IF(($C9=38765),17.2,((IF(($C9=38772),24.2,0)))))))))))))))))))))))) -> 0 | Q9: =((IF(($C9=38800),24.3,((IF(($C9=38773),25.2,((IF(($C9=38046),29.2,((IF(($C9=38075),29.3,((IF(($C9="32.2"),32.2,((IF(($C9="33.2"),33.2,((IF(($C9="34.2"),34.2,((IF(($C9="35.2"),35.2,0)))))))))))))))))))))))) -> 0 | R9: =((IF(($C9=38767),19.2,((IF(($C9="21.2"),21.2,((IF(($C9="22.2"),22.2,((IF(($C9="22.3"),22.3,((IF(($C9="26.2"),26.2,((IF(($C9="42.2"),42.2,((IF(($C9="44.2"),44.2,((IF(($C9="46.2"),46.2,0)))))))))))))))))))))))) -> 0 | S9: =((IF(($C9="47.2"),47.2,((IF(($C9="50.2"),50.2,((IF(($C9="8.3"),8.3,((IF(($C9="23.2"),23.2,((IF(($C9="43.2"),43.2,((IF(($C9="45.2"),45.2,((IF(($C9="48.2"),48.2,((IF(($C9="51.2"),51.2,0)))))))))))))))))))))))) -> 0 | T9: =((IF(($C9="13.3"),13.3,((IF(($C9=38758),10.2,((IF(($C9=38762),14.2,((IF(($C9=38760),12.2,((IF(($C9=38764),16.2,((IF(($C9=38766),18.2,((IF(($C9=38776),28.2,((IF(($C9="30.2"),30.2,0)))))))))))))))))))))))) -> 0 | U9: =((IF(($C9="34.1"),34.1,((IF(($C9="35.1"),35.1,((IF(($C9=38733),16.1,((IF(($C9=38768),20.2,((IF(($C9=38774),26.2,((IF(($C9=38771),23.2,((IF(($C9=38784),8.3,((IF(($C9=38789),13.3,0)))))))))))))))))))))))) -> 0 | W9: =(IF((SUM(P9:V9)<>0),(SUM(P9:V9)),$C9)) -> ND | X9: =((IF(($D9=38785),9.3,((IF(($D9=38761),13.2,((IF(($D9="31.2"),31.2,((IF(($D9=38787),11.3,((IF(($D9=38759),11.2,((IF(($D9=38763),15.2,((IF(($D9=38765),17.2,((IF(($D9=38772),24.2,0)))))))))))))))))))))))) -> 0 | Y9: =((IF(($D9=38800),24.3,((IF(($D9=38773),25.2,((IF(($D9=38046),29.2,((IF(($D9=38075),29.3,((IF(($D9="32.2"),32.2,((IF(($D9="33.2"),33.2,((IF(($D9="34.2"),34.2,((IF(($D9="35.2"),35.2,0)))))))))))))))))))))))) -> 0 | Z9: =((IF(($D9=38767),19.2,((IF(($D9="21.2"),21.2,((IF(($D9="22.2"),22.2,((IF(($D9="22.3"),22.3,((IF(($D9="26.2"),26.2,((IF(($D9="42.2"),42.2,((IF(($D9="44.2"),44.2,((IF(($D9="46.2"),46.2,0)))))))))))))))))))))))) -> 0 | AA9: =((IF(($D9="47.2"),47.2,((IF(($D9="50.2"),50.2,((IF(($D9="8.3"),8.3,((IF(($D9="23.2"),23.2,((IF(($D9="43.2"),43.2,((IF(($D9="45.2"),45.2,((IF(($D9="48.2"),48.2,((IF(($D9="51.2"),51.2,0)))))))))))))))))))))))) -> 0 | AB9: =((IF(($D9="13.3"),13.3,((IF(($D9=38758),10.2,((IF(($D9=38762),14.2,((IF(($D9=38760),12.2,((IF(($D9=38764),16.2,((IF(($D9=38766),18.2,((IF(($D9=38776),28.2,((IF(($D9="30.2"),30.2,0)))))))))))))))))))))))) -> 0 | AC9: =((IF(($D9="34.1"),34.1,((IF(($D9="35.1"),35.1,((IF(($D9=38733),16.1,((IF(($D9=38768),20.2,((IF(($D9=38774),26.2,((IF(($D9=38784),8.3,((IF(($D9=38789),13.3,0))))))))))))))))))))) -> 0 | AE9: =(IF((SUM(X9:AD9)<>0),(SUM(X9:AD9)),$D9)) -> 12 | AF9: =((IF(($E9=38785),9.3,((IF(($E9=38761),13.2,((IF(($E9="31.2"),31.2,((IF(($E9=38787),11.3,((IF(($E9=38759),11.2,((IF(($E9=38763),15.2,((IF(($E9=38765),17.2,((IF(($E9=38772),24.2,0)))))))))))))))))))))))) -> 0 | AG9: =((IF(($E9=38800),24.3,((IF(($E9=38773),25.2,((IF(($E9=38046),29.2,((IF(($E9=38075),29.3,((IF(($E9="32.2"),32.2,((IF(($E9="33.2"),33.2,((IF(($E9="34.2"),34.2,((IF(($E9="35.2"),35.2,0)))))))))))))))))))))))) -> 0 | AH9: =((IF(($E9=38767),19.2,((IF(($E9="21.2"),21.2,((IF(($E9="22.2"),22.2,((IF(($E9="22.3"),22.3,((IF(($E9="26.2"),26.2,((IF(($E9="42.2"),42.2,((IF(($E9="44.2"),44.2,((IF(($E9="46.2"),46.2,0)))))))))))))))))))))))) -> 0 | AI9: =((IF(($E9="47.2"),47.2,((IF(($E9="50.2"),50.2,((IF(($E9="8.3"),8.3,((IF(($E9="23.2"),23.2,((IF(($E9="43.2"),43.2,((IF(($E9="45.2"),45.2,((IF(($E9="48.2"),48.2,((IF(($E9="51.2"),51.2,0)))))))))))))))))))))))) -> 0 | AJ9: =((IF(($E9="13.3"),13.3,((IF(($E9=38758),10.2,((IF(($E9=38762),14.2,((IF(($E9=38760),12.2,((IF(($E9=38764),16.2,((IF(($E9=38766),18.2,((IF(($E9=38776),28.2,((IF(($E9="30.2"),30.2,0)))))))))))))))))))))))) -> 0 | AK9: =((IF(($E9="34.1"),34.1,((IF(($E9="35.1"),35.1,((IF(($E9=38733),16.1,((IF(($E9=38768),20.2,((IF(($E9=38774),26.2,((IF(($E9=38771),23.2,((IF(($E9=38784),8.3,((IF(($E9=38789),13.3,0)))))))))))))))))))))))) -> 0 | AM9: =(IF((SUM(AF9:AL9)<>0),(SUM(AF9:AL9)),$E9)) -> 14 | AN9: =((IF(($F9=38785),9.3,((IF(($F9=38761),13.2,((IF(($F9="31.2"),31.2,((IF(($F9=38787),11.3,((IF(($F9=38759),11.2,((IF(($F9=38763),15.2,((IF(($F9=38765),17.2,((IF(($F9=38772),24.2,0)))))))))))))))))))))))) -> 0 | AO9: =((IF(($F9=38800),24.3,((IF(($F9=38773),25.2,((IF(($F9=38046),29.2,((IF(($F9=38075),29.3,((IF(($F9="32.2"),32.2,((IF(($F9="33.2"),33.2,((IF(($F9="34.2"),34.2,((IF(($F9="35.2"),35.2,0)))))))))))))))))))))))) -> 0 | AP9: =((IF(($F9=38767),19.2,((IF(($F9="21.2"),21.2,((IF(($F9="22.2"),22.2,((IF(($F9="22.3"),22.3,((IF(($F9="26.2"),26.2,((IF(($F9="42.2"),42.2,((IF(($F9="44.2"),44.2,((IF(($F9="46.2"),46.2,0)))))))))))))))))))))))) -> 0 | AQ9: =((IF(($F9="47.2"),47.2,((IF(($F9="50.2"),50.2,((IF(($F9="8.3"),8.3,((IF(($F9="23.2"),23.2,((IF(($F9="43.2"),43.2,((IF(($F9="45.2"),45.2,((IF(($F9="48.2"),48.2,((IF(($F9="51.2"),51.2,0)))))))))))))))))))))))) -> 0 | AR9: =((IF(($F9="13.3"),13.3,((IF(($F9=38758),10.2,((IF(($F9=38762),14.2,((IF(($F9=38760),12.2,((IF(($F9=38764),16.2,((IF(($F9=38766),18.2,((IF(($F9=38776),28.2,((IF(($F9="30.2"),30.2,0)))))))))))))))))))))))) -> 0 | AS9: =((IF(($F9="34.1"),34.1,((IF(($F9="35.1"),35.1,((IF(($F9=38733),16.1,((IF(($F9=38768),20.2,((IF(($F9=38774),26.2,((IF(($F9=38784),8.3,((IF(($F9=38789),13.3,0))))))))))))))))))))) -> 0 | AU9: =(IF((SUM(AN9:AT9)<>0),(SUM(AN9:AT9)),$F9)) -> 13 | AV9: =((IF(($G9=38785),9.3,((IF(($G9=38761),13.2,((IF(($G9="31.2"),31.2,((IF(($G9=38787),11.3,((IF(($G9=38759),11.2,((IF(($G9=38763),15.2,((IF(($G9=38765),17.2,((IF(($G9=38772),24.2,0)))))))))))))))))))))))) -> 0 | AW9: =((IF(($G9=38800),24.3,((IF(($G9=38773),25.2,((IF(($G9=38046),29.2,((IF(($G9=38075),29.3,((IF(($G9="32.2"),32.2,((IF(($G9="33.2"),33.2,((IF(($G9="34.2"),34.2,((IF(($G9="35.2"),35.2,0)))))))))))))))))))))))) -> 0 | AX9: =((IF(($G9=38767),19.2,((IF(($G9="21.2"),21.2,((IF(($G9="22.2"),22.2,((IF(($G9="22.3"),22.3,((IF(($G9="26.2"),26.2,((IF(($G9="42.2"),42.2,((IF(($G9="44.2"),44.2,((IF(($G9="46.2"),46.2,0)))))))))))))))))))))))) -> 0 | AY9: =((IF(($G9="47.2"),47.2,((IF(($G9="50.2"),50.2,((IF(($G9="8.3"),8.3,((IF(($G9="23.2"),23.2,((IF(($G9="43.2"),43.2,((IF(($G9="45.2"),45.2,((IF(($G9="48.2"),48.2,((IF(($G9="51.2"),51.2,0)))))))))))))))))))))))) -> 0 | AZ9: =((IF(($G9="13.3"),13.3,((IF(($G9=38758),10.2,((IF(($G9=38762),14.2,((IF(($G9=38760),12.2,((IF(($G9=38764),16.2,((IF(($G9=38766),18.2,((IF(($G9=38776),28.2,((IF(($G9="30.2"),30.2,0)))))))))))))))))))))))) -> 0 | BA9: =((IF(($G9="34.1"),34.1,((IF(($G9="35.1"),35.1,((IF(($G9=38733),16.1,((IF(($G9=38768),20.2,((IF(($G9=38774),26.2,((IF(($G9=38771),23.2,((IF(($G9=38784),8.3,((IF(($G9=38789),13.3,0)))))))))))))))))))))))) -> 0 | BC9: =(IF((SUM(AV9:BB9)<>0),(SUM(AV9:BB9)),$G9)) -> 14
A10: =FREQUENCIAS!G$1 -> Penta_E | B10: ND | C10: ND | D10: 12 | E10: 13 | F10: 12 | G10: 13 | H10: =((IF(($B10=38785),9.3,((IF(($B10=38761),13.2,((IF(($B10="31.2"),31.2,((IF(($B10=38787),11.3,((IF(($B10=38759),11.2,((IF(($B10=38763),15.2,((IF(($B10=38765),17.2,((IF(($B10=38772),24.2,0)))))))))))))))))))))))) -> 0 | I10: =((IF(($B10=38800),24.3,((IF(($B10=38773),25.2,((IF(($B10=38046),29.2,((IF(($B10=38075),29.3,((IF(($B10="32.2"),32.2,((IF(($B10="33.2"),33.2,((IF(($B10="34.2"),34.2,((IF(($B10="35.2"),35.2,0)))))))))))))))))))))))) -> 0 | J10: =((IF(($B10=38767),19.2,((IF(($B10="21.2"),21.2,((IF(($B10="22.2"),22.2,((IF(($B10="22.3"),22.3,((IF(($B10="26.2"),26.2,((IF(($B10="42.2"),42.2,((IF(($B10="44.2"),44.2,((IF(($B10="46.2"),46.2,0)))))))))))))))))))))))) -> 0 | K10: =((IF(($B10="47.2"),47.2,((IF(($B10="50.2"),50.2,((IF(($B10="8.3"),8.3,((IF(($B10="23.2"),23.2,((IF(($B10="43.2"),43.2,((IF(($B10="45.2"),45.2,((IF(($B10="48.2"),48.2,((IF(($B10="51.2"),51.2,0)))))))))))))))))))))))) -> 0 | L10: =((IF(($B10="13.3"),13.3,((IF(($B10=38758),10.2,((IF(($B10=38762),14.2,((IF(($B10=38760),12.2,((IF(($B10=38764),16.2,((IF(($B10=38766),18.2,((IF(($B10=38776),28.2,((IF(($B10="30.2"),30.2,0)))))))))))))))))))))))) -> 0 | M10: =((IF(($B10="34.1"),34.1,((IF(($B10="35.1"),35.1,((IF(($B10=38733),16.1,((IF(($B10=38768),20.2,((IF(($B10=38774),26.2,0))))))))))))))) -> 0 | O10: =(IF((SUM(H10:N10)<>0),(SUM(H10:N10)),$B10)) -> ND | P10: =((IF(($C10=38785),9.3,((IF(($C10=38761),13.2,((IF(($C10="31.2"),31.2,((IF(($C10=38787),11.3,((IF(($C10=38759),11.2,((IF(($C10=38763),15.2,((IF(($C10=38765),17.2,((IF(($C10=38772),24.2,0)))))))))))))))))))))))) -> 0 | Q10: =((IF(($C10=38800),24.3,((IF(($C10=38773),25.2,((IF(($C10=38046),29.2,((IF(($C10=38075),29.3,((IF(($C10="32.2"),32.2,((IF(($C10="33.2"),33.2,((IF(($C10="34.2"),34.2,((IF(($C10="35.2"),35.2,0)))))))))))))))))))))))) -> 0 | R10: =((IF(($C10=38767),19.2,((IF(($C10="21.2"),21.2,((IF(($C10="22.2"),22.2,((IF(($C10="22.3"),22.3,((IF(($C10="26.2"),26.2,((IF(($C10="42.2"),42.2,((IF(($C10="44.2"),44.2,((IF(($C10="46.2"),46.2,0)))))))))))))))))))))))) -> 0 | S10: =((IF(($C10="47.2"),47.2,((IF(($C10="50.2"),50.2,((IF(($C10="8.3"),8.3,((IF(($C10="23.2"),23.2,((IF(($C10="43.2"),43.2,((IF(($C10="45.2"),45.2,((IF(($C10="48.2"),48.2,((IF(($C10="51.2"),51.2,0)))))))))))))))))))))))) -> 0 | T10: =((IF(($C10="13.3"),13.3,((IF(($C10=38758),10.2,((IF(($C10=38762),14.2,((IF(($C10=38760),12.2,((IF(($C10=38764),16.2,((IF(($C10=38766),18.2,((IF(($C10=38776),28.2,((IF(($C10="30.2"),30.2,0)))))))))))))))))))))))) -> 0 | U10: =((IF(($C10="34.1"),34.1,((IF(($C10="35.1"),35.1,((IF(($C10=38733),16.1,((IF(($C10=38768),20.2,((IF(($C10=38774),26.2,((IF(($C10=38771),23.2,0)))))))))))))))))) -> 0 | W10: =(IF((SUM(P10:V10)<>0),(SUM(P10:V10)),$C10)) -> ND | X10: =((IF(($D10=38785),9.3,((IF(($D10=38761),13.2,((IF(($D10="31.2"),31.2,((IF(($D10=38787),11.3,((IF(($D10=38759),11.2,((IF(($D10=38763),15.2,((IF(($D10=38765),17.2,((IF(($D10=38772),24.2,0)))))))))))))))))))))))) -> 0 | Y10: =((IF(($D10=38800),24.3,((IF(($D10=38773),25.2,((IF(($D10=38046),29.2,((IF(($D10=38075),29.3,((IF(($D10="32.2"),32.2,((IF(($D10="33.2"),33.2,((IF(($D10="34.2"),34.2,((IF(($D10="35.2"),35.2,0)))))))))))))))))))))))) -> 0 | Z10: =((IF(($D10=38767),19.2,((IF(($D10="21.2"),21.2,((IF(($D10="22.2"),22.2,((IF(($D10="22.3"),22.3,((IF(($D10="26.2"),26.2,((IF(($D10="42.2"),42.2,((IF(($D10="44.2"),44.2,((IF(($D10="46.2"),46.2,0)))))))))))))))))))))))) -> 0 | AA10: =((IF(($D10="47.2"),47.2,((IF(($D10="50.2"),50.2,((IF(($D10="8.3"),8.3,((IF(($D10="23.2"),23.2,((IF(($D10="43.2"),43.2,((IF(($D10="45.2"),45.2,((IF(($D10="48.2"),48.2,((IF(($D10="51.2"),51.2,0)))))))))))))))))))))))) -> 0 | AB10: =((IF(($D10="13.3"),13.3,((IF(($D10=38758),10.2,((IF(($D10=38762),14.2,((IF(($D10=38760),12.2,((IF(($D10=38764),16.2,((IF(($D10=38766),18.2,((IF(($D10=38776),28.2,((IF(($D10="30.2"),30.2,0)))))))))))))))))))))))) -> 0 | AC10: =((IF(($D10="34.1"),34.1,((IF(($D10="35.1"),35.1,((IF(($D10=38733),16.1,((IF(($D10=38768),20.2,((IF(($D10=38774),26.2,0))))))))))))))) -> 0 | AE10: =(IF((SUM(X10:AD10)<>0),(SUM(X10:AD10)),$D10)) -> 12 | AF10: =((IF(($E10=38785),9.3,((IF(($E10=38761),13.2,((IF(($E10="31.2"),31.2,((IF(($E10=38787),11.3,((IF(($E10=38759),11.2,((IF(($E10=38763),15.2,((IF(($E10=38765),17.2,((IF(($E10=38772),24.2,0)))))))))))))))))))))))) -> 0 | AG10: =((IF(($E10=38800),24.3,((IF(($E10=38773),25.2,((IF(($E10=38046),29.2,((IF(($E10=38075),29.3,((IF(($E10="32.2"),32.2,((IF(($E10="33.2"),33.2,((IF(($E10="34.2"),34.2,((IF(($E10="35.2"),35.2,0)))))))))))))))))))))))) -> 0 | AH10: =((IF(($E10=38767),19.2,((IF(($E10="21.2"),21.2,((IF(($E10="22.2"),22.2,((IF(($E10="22.3"),22.3,((IF(($E10="26.2"),26.2,((IF(($E10="42.2"),42.2,((IF(($E10="44.2"),44.2,((IF(($E10="46.2"),46.2,0)))))))))))))))))))))))) -> 0 | AI10: =((IF(($E10="47.2"),47.2,((IF(($E10="50.2"),50.2,((IF(($E10="8.3"),8.3,((IF(($E10="23.2"),23.2,((IF(($E10="43.2"),43.2,((IF(($E10="45.2"),45.2,((IF(($E10="48.2"),48.2,((IF(($E10="51.2"),51.2,0)))))))))))))))))))))))) -> 0 | AJ10: =((IF(($E10="13.3"),13.3,((IF(($E10=38758),10.2,((IF(($E10=38762),14.2,((IF(($E10=38760),12.2,((IF(($E10=38764),16.2,((IF(($E10=38766),18.2,((IF(($E10=38776),28.2,((IF(($E10="30.2"),30.2,0)))))))))))))))))))))))) -> 0 | AK10: =((IF(($E10="34.1"),34.1,((IF(($E10="35.1"),35.1,((IF(($E10=38733),16.1,((IF(($E10=38768),20.2,((IF(($E10=38774),26.2,((IF(($E10=38771),23.2,0)))))))))))))))))) -> 0 | AM10: =(IF((SUM(AF10:AL10)<>0),(SUM(AF10:AL10)),$E10)) -> 13 | AN10: =((IF(($F10=38785),9.3,((IF(($F10=38761),13.2,((IF(($F10="31.2"),31.2,((IF(($F10=38787),11.3,((IF(($F10=38759),11.2,((IF(($F10=38763),15.2,((IF(($F10=38765),17.2,((IF(($F10=38772),24.2,0)))))))))))))))))))))))) -> 0 | AO10: =((IF(($F10=38800),24.3,((IF(($F10=38773),25.2,((IF(($F10=38046),29.2,((IF(($F10=38075),29.3,((IF(($F10="32.2"),32.2,((IF(($F10="33.2"),33.2,((IF(($F10="34.2"),34.2,((IF(($F10="35.2"),35.2,0)))))))))))))))))))))))) -> 0 | AP10: =((IF(($F10=38767),19.2,((IF(($F10="21.2"),21.2,((IF(($F10="22.2"),22.2,((IF(($F10="22.3"),22.3,((IF(($F10="26.2"),26.2,((IF(($F10="42.2"),42.2,((IF(($F10="44.2"),44.2,((IF(($F10="46.2"),46.2,0)))))))))))))))))))))))) -> 0 | AQ10: =((IF(($F10="47.2"),47.2,((IF(($F10="50.2"),50.2,((IF(($F10="8.3"),8.3,((IF(($F10="23.2"),23.2,((IF(($F10="43.2"),43.2,((IF(($F10="45.2"),45.2,((IF(($F10="48.2"),48.2,((IF(($F10="51.2"),51.2,0)))))))))))))))))))))))) -> 0 | AR10: =((IF(($F10="13.3"),13.3,((IF(($F10=38758),10.2,((IF(($F10=38762),14.2,((IF(($F10=38760),12.2,((IF(($F10=38764),16.2,((IF(($F10=38766),18.2,((IF(($F10=38776),28.2,((IF(($F10="30.2"),30.2,0)))))))))))))))))))))))) -> 0 | AS10: =((IF(($F10="34.1"),34.1,((IF(($F10="35.1"),35.1,((IF(($F10=38733),16.1,((IF(($F10=38768),20.2,((IF(($F10=38774),26.2,0))))))))))))))) -> 0 | AU10: =(IF((SUM(AN10:AT10)<>0),(SUM(AN10:AT10)),$F10)) -> 12 | AV10: =((IF(($G10=38785),9.3,((IF(($G10=38761),13.2,((IF(($G10="31.2"),31.2,((IF(($G10=38787),11.3,((IF(($G10=38759),11.2,((IF(($G10=38763),15.2,((IF(($G10=38765),17.2,((IF(($G10=38772),24.2,0)))))))))))))))))))))))) -> 0 | AW10: =((IF(($G10=38800),24.3,((IF(($G10=38773),25.2,((IF(($G10=38046),29.2,((IF(($G10=38075),29.3,((IF(($G10="32.2"),32.2,((IF(($G10="33.2"),33.2,((IF(($G10="34.2"),34.2,((IF(($G10="35.2"),35.2,0)))))))))))))))))))))))) -> 0 | AX10: =((IF(($G10=38767),19.2,((IF(($G10="21.2"),21.2,((IF(($G10="22.2"),22.2,((IF(($G10="22.3"),22.3,((IF(($G10="26.2"),26.2,((IF(($G10="42.2"),42.2,((IF(($G10="44.2"),44.2,((IF(($G10="46.2"),46.2,0)))))))))))))))))))))))) -> 0 | AY10: =((IF(($G10="47.2"),47.2,((IF(($G10="50.2"),50.2,((IF(($G10="8.3"),8.3,((IF(($G10="23.2"),23.2,((IF(($G10="43.2"),43.2,((IF(($G10="45.2"),45.2,((IF(($G10="48.2"),48.2,((IF(($G10="51.2"),51.2,0)))))))))))))))))))))))) -> 0 | AZ10: =((IF(($G10="13.3"),13.3,((IF(($G10=38758),10.2,((IF(($G10=38762),14.2,((IF(($G10=38760),12.2,((IF(($G10=38764),16.2,((IF(($G10=38766),18.2,((IF(($G10=38776),28.2,((IF(($G10="30.2"),30.2,0)))))))))))))))))))))))) -> 0 | BA10: =((IF(($G10="34.1"),34.1,((IF(($G10="35.1"),35.1,((IF(($G10=38733),16.1,((IF(($G10=38768),20.2,((IF(($G10=38774),26.2,((IF(($G10=38771),23.2,0)))))))))))))))))) -> 0 | BC10: =(IF((SUM(AV10:BB10)<>0),(SUM(AV10:BB10)),$G10)) -> 13
