Workbook
Name Print_Area: 'DADOS FINAIS'!$A$1:$AN$54
Name Print_Area: 'SUPERVISÃO 3'!$1:$1048576
Name Print_Titles: FREQUENCIAS!$A:$A,FREQUENCIAS!$1:$1

Sheet SUPERVISÃO 4
A1: INST. DE PERÍCIAS CIENTÍFICAS - DIV. BIOLOGIA MOLECULAR | AH1: INCLUSÃO
AG2: Sistema automatizado de cálculo de Genética das Populações desenvolvido pelo Engº e Biólogo Helder Pereira de Figueiredo | AH2: VERIFICAR
A3: COD: | B3: ='DADOS FINAIS'!B3 -> 0 | AB3: PLANILHA NÃO DESTINADA | AH3: OK
A4: MÃE: | B4: ='DADOS FINAIS'!B4 -> 0 | AB4: A IMPRESSÃO - SIMPLES
A5: CRIANÇA: | B5: ='DADOS FINAIS'!B5 -> 0 | AB5: SUPERVISÃO DE SEGURANÇA
A6: SUP PAI: | B6: ='DADOS FINAIS'!B6 -> 0 | AD6: EXCLUI
A7: VERIFICAÇÃO - HIPÓTESE: REPETIÇÃO ALÉLICA | AB7: FREQ. MÍNIMA: | AC7: ='DADOS FINAIS'!$AI$7 -> 0.05 | AD7: NÃO DEF
A8: REGIÃO | B8: MÃE | D8: CRIANÇA | F8: SUP. PAI | H8: M CALC | J8: C CALC | L8: SP CALC | N8: AM1 | O8: AM2 | P8: AM3 | Q8: AL. MAT | R8: AL. PAT. | T8: COMP. | V8: Fr 1A | W8: Fr 2A | X8: Fr 1B | Y8: Fr 2B | Z8: Fr Sp | AA8: M x C | AB8: M x SP | AC8: C x SP | AD8: SIM | AG8: ANÁLISE
A9: D3S1358 | B9: ='DADOS FINAIS'!B9 -> 16 | C9: ='DADOS FINAIS'!C9 -> 18 | D9: ='DADOS FINAIS'!D9 -> 15 | E9: ='DADOS FINAIS'!E9 -> 18 | F9: ='DADOS FINAIS'!F9 -> 14 | G9: ='DADOS FINAIS'!G9 -> 15 | H9: =IF((B9>C9),C9,B9) -> 16 | I9: =IF((C9>B9),C9,B9) -> 18 | J9: =IF((D9>E9),E9,D9) -> 15 | K9: =IF((E9>D9),E9,D9) -> 18 | L9: =IF((F9>G9),G9,F9) -> 14 | M9: =IF((G9>F9),G9,F9) -> 15 | N9: =IF((J9=H9),J9,(IF((J9=I9),J9,0))) -> 0 | O9: =IF((K9=H9),K9,(IF((K9=I9),K9,0))) -> 18 | P9: =(IF(((N9+O9)=(J9+K9)),0,1)) -> 1 | Q9: =IF(OR((N9=O9),(O9=0)),N9,(IF(AND((N9=0),(O9<>0)),O9,$AD$7))) -> 18 | R9: =(IF((Q9<>$AD$7),(J9+K9-Q9),D9)) -> 15 | S9: =(IF((Q9<>$AD$7),0,K9)) -> 0 | T9: =(IF(OR((R9=L9),(R9=M9)),R9,0)) -> 15 | U9: =(IF(AND((P9=0),(OR((M9=N9),(M9=O9)))),S9,(IF((S9<>0),(IF(OR((S9=L9),(S9=M9)),S9,0)),0)))) -> 0 | V9: =IF(R9=0,0,VLOOKUP(R9,FREQUENCIAS!$1:$1048576,(IF(($A9=FREQUENCIAS!$B$1),2,"ERRO")),FREQUENCIAS!$1:$1048576)) -> 0.290991 | W9: =IF(S9=0,0,VLOOKUP(S9,FREQUENCIAS!$1:$1048576,(IF(($A9=FREQUENCIAS!$B$1),2,"ERRO")),FREQUENCIAS!$1:$1048576)) -> 0 | AA9: =((IF((AND(($H9=$J9),($I9=$K9))),2,( IF((OR(($H9=$J9),($I9=$K9),($H9=$K9),($I9=$J9))),1,0))))) -> 1 | AB9: =((IF((AND(($H9=$L9),($I9=$M9))),2,( IF((OR(($H9=$L9),($I9=$M9),($H9=$M9),($I9=$L9))),1,0))))) -> 0 | AC9: =((IF((AND(($J9=$L9),($K9=$M9))),2,( IF((OR(($J9=$L9),($K9=$M9),($J9=$M9),($K9=$L9))),1,0))))) -> 1 | AE9: =(1-AA9)^2 -> 0 | AG9: =IF((AND((AA9>=1),(AC9>=1))),"INCLUSÃO","VERIFICAR") -> INCLUSÃO
A10: D1S1656 | B10: ='DADOS FINAIS'!B10 -> 15 | C10: ='DADOS FINAIS'!C10 -> 16.3 | D10: ='DADOS FINAIS'!D10 -> 16.3 | E10: ='DADOS FINAIS'!E10 -> 19.3 | F10: ='DADOS FINAIS'!F10 -> 13 | G10: ='DADOS FINAIS'!G10 -> 19.3 | H10: =IF((B10>C10),C10,B10) -> 15 | I10: =IF((C10>B10),C10,B10) -> 16.3 | J10: =IF((D10>E10),E10,D10) -> 16.3 | K10: =IF((E10>D10),E10,D10) -> 19.3 | L10: =IF((F10>G10),G10,F10) -> 13 | M10: =IF((G10>F10),G10,F10) -> 19.3 | N10: =IF((J10=H10),J10,(IF((J10=I10),J10,0))) -> 16.3 | O10: =IF((K10=H10),K10,(IF((K10=I10),K10,0))) -> 0 | P10: =(IF(((N10+O10)=(J10+K10)),0,1)) -> 1 | Q10: =IF(OR((N10=O10),(O10=0)),N10,(IF(AND((N10=0),(O10<>0)),O10,$AD$7))) -> 16.3 | R10: =(IF((Q10<>$AD$7),(J10+K10-Q10),D10)) -> 19.3 | S10: =(IF((Q10<>$AD$7),0,K10)) -> 0 | T10: =(IF(OR((R10=L10),(R10=M10)),R10,0)) -> 19.3 | U10: =(IF(AND((P10=0),(OR((M10=N10),(M10=O10)))),S10,(IF((S10<>0),(IF(OR((S10=L10),(S10=M10)),S10,0)),0)))) -> 0 | V10: =IF(R10=0,0,VLOOKUP(R10,FREQUENCIAS!$1:$1048576,(IF(($A10=FREQUENCIAS!$C$1),3,"ERRO")),FREQUENCIAS!$1:$1048576)) -> 0.0036 | W10: =IF(S10=0,0,VLOOKUP(S10,FREQUENCIAS!$1:$1048576,(IF(($A10=FREQUENCIAS!$C$1),3,"ERRO")),FREQUENCIAS!$1:$1048576)) -> 0 | AA10: =((IF((AND(($H10=$J10),($I10=$K10))),2,( IF((OR(($H10=$J10),($I10=$K10),($H10=$K10),($I10=$J10))),1,0))))) -> 1 | AB10: =((IF((AND(($H10=$L10),($I10=$M10))),2,( IF((OR(($H10=$L10),($I10=$M10),($H10=$M10),($I10=$L10))),1,0))))) -> 0 | AC10: =((IF((AND(($J10=$L10),($K10=$M10))),2,( IF((OR(($J10=$L10),($K10=$M10),($J10=$M10),($K10=$L10))),1,0))))) -> 1 | AE10: =(1-AA10)^2 -> 0 | AG10: =IF((AND((AA10>=1),(AC10>=1))),"INCLUSÃO","VERIFICAR") -> INCLUSÃO
A11: D2S441 | B11: ='DADOS FINAIS'!B11 -> 10 | C11: ='DADOS FINAIS'!C11 -> 12 | D11: ='DADOS FINAIS'!D11 -> 10 | E11: ='DADOS FINAIS'!E11 -> 12 | F11: ='DADOS FINAIS'!F11 -> 10 | G11: ='DADOS FINAIS'!G11 -> 11 | H11: =IF((B11>C11),C11,B11) -> 10 | I11: =IF((C11>B11),C11,B11) -> 12 | J11: =IF((D11>E11),E11,D11) -> 10 | K11: =IF((E11>D11),E11,D11) -> 12 | L11: =IF((F11>G11),G11,F11) -> 10 | M11: =IF((G11>F11),G11,F11) -> 11 | N11: =IF((J11=H11),J11,(IF((J11=I11),J11,0))) -> 10 | O11: =IF((K11=H11),K11,(IF((K11=I11),K11,0))) -> 12 | P11: =(IF(((N11+O11)=(J11+K11)),0,1)) -> 0 | Q11: =IF(OR((N11=O11),(O11=0)),N11,(IF(AND((N11=0),(O11<>0)),O11,$AD$7))) -> NÃO DEF | R11: =(IF((Q11<>$AD$7),(J11+K11-Q11),D11)) -> 10 | S11: =(IF((Q11<>$AD$7),0,K11)) -> 12 | T11: =(IF(OR((R11=L11),(R11=M11)),R11,0)) -> 10 | U11: =(IF(AND((P11=0),(OR((M11=N11),(M11=O11)))),S11,(IF((S11<>0),(IF(OR((S11=L11),(S11=M11)),S11,0)),0)))) -> 0 | V11: =IF(R11=0,0,VLOOKUP(R11,FREQUENCIAS!$1:$1048576,(IF(($A11=FREQUENCIAS!$D$1),4,"ERRO")),FREQUENCIAS!$1:$1048576)) -> 0.2611 | W11: =IF(S11=0,0,VLOOKUP(S11,FREQUENCIAS!$1:$1048576,(IF(($A11=FREQUENCIAS!$D$1),4,"ERRO")),FREQUENCIAS!$1:$1048576)) -> 0.0731 | AA11: =((IF((AND(($H11=$J11),($I11=$K11))),2,( IF((OR(($H11=$J11),($I11=$K11),($H11=$K11),($I11=$J11))),1,0))))) -> 2 | AB11: =((IF((AND(($H11=$L11),($I11=$M11))),2,( IF((OR(($H11=$L11),($I11=$M11),($H11=$M11),($I11=$L11))),1,0))))) -> 1 | AC11: =((IF((AND(($J11=$L11),($K11=$M11))),2,( IF((OR(($J11=$L11),($K11=$M11),($J11=$M11),($K11=$L11))),1,0))))) -> 1 | AE11: =(1-AA11)^2 -> 1 | AG11: =IF((AND((AA11>=1),(AC11>=1))),"INCLUSÃO","VERIFICAR") -> INCLUSÃO
A12: D10S1248 | B12: ='DADOS FINAIS'!B12 -> <8 | C12: ='DADOS FINAIS'!C12 -> 13 | D12: ='DADOS FINAIS'!D12 -> <8 | E12: ='DADOS FINAIS'!E12 -> 14 | F12: ='DADOS FINAIS'!F12 -> 13 | G12: ='DADOS FINAIS'!G12 -> 14 | H12: =IF((B12>C12),C12,B12) -> 13 | I12: =IF((C12>B12),C12,B12) -> <8 | J12: =IF((D12>E12),E12,D12) -> 14 | K12: =IF((E12>D12),E12,D12) -> <8 | L12: =IF((F12>G12),G12,F12) -> 13 | M12: =IF((G12>F12),G12,F12) -> 14 | N12: =IF((J12=H12),J12,(IF((J12=I12),J12,0))) -> 0 | O12: =IF((K12=H12),K12,(IF((K12=I12),K12,0))) -> <8 | P12: =(IF(((N12+O12)=(J12+K12)),0,1)) -> #VALUE! | Q12: =IF(OR((N12=O12),(O12=0)),N12,(IF(AND((N12=0),(O12<>0)),O12,$AD$7))) -> <8 | R12: =(IF((Q12<>$AD$7),(J12+K12-Q12),D12)) -> #VALUE! | S12: =(IF((Q12<>$AD$7),0,K12)) -> 0 | T12: =(IF(OR((R12=L12),(R12=M12)),R12,0)) -> #VALUE! | U12: =(IF(AND((P12=0),(OR((M12=N12),(M12=O12)))),S12,(IF((S12<>0),(IF(OR((S12=L12),(S12=M12)),S12,0)),0)))) -> #VALUE! | V12: =IF(R12=0,0,VLOOKUP(R12,FREQUENCIAS!$1:$1048576,(IF(($A12=FREQUENCIAS!$E$1),5,"ERRO")),FREQUENCIAS!$1:$1048576)) -> #VALUE! | W12: =IF(S12=0,0,VLOOKUP(S12,FREQUENCIAS!$1:$1048576,(IF(($A12=FREQUENCIAS!$E$1),5,"ERRO")),FREQUENCIAS!$1:$1048576)) -> 0 | AA12: =((IF((AND(($H12=$J12),($I12=$K12))),2,( IF((OR(($H12=$J12),($I12=$K12),($H12=$K12),($I12=$J12))),1,0))))) -> 1 | AB12: =((IF((AND(($H12=$L12),($I12=$M12))),2,( IF((OR(($H12=$L12),($I12=$M12),($H12=$M12),($I12=$L12))),1,0))))) -> 1 | AC12: =((IF((AND(($J12=$L12),($K12=$M12))),2,( IF((OR(($J12=$L12),($K12=$M12),($J12=$M12),($K12=$L12))),1,0))))) -> 1 | AD12: NÃO | AE12: =(1-AA12)^2 -> 0 | AG12: =IF((AND((AA12>=1),(AC12>=1))),"INCLUSÃO","VERIFICAR") -> INCLUSÃO
A13: D13S317 | B13: ='DADOS FINAIS'!B13 -> 8 | C13: ='DADOS FINAIS'!C13 -> 10 | D13: ='DADOS FINAIS'!D13 -> 10 | E13: ='DADOS FINAIS'!E13 -> 12 | F13: ='DADOS FINAIS'!F13 -> 12 | G13: ='DADOS FINAIS'!G13 -> 12 | H13: =IF((B13>C13),C13,B13) -> 8 | I13: =IF((C13>B13),C13,B13) -> 10 | J13: =IF((D13>E13),E13,D13) -> 10 | K13: =IF((E13>D13),E13,D13) -> 12 | L13: =IF((F13>G13),G13,F13) -> 12 | M13: =IF((G13>F13),G13,F13) -> 12 | N13: =IF((J13=H13),J13,(IF((J13=I13),J13,0))) -> 10 | O13: =IF((K13=H13),K13,(IF((K13=I13),K13,0))) -> 0 | P13: =(IF(((N13+O13)=(J13+K13)),0,1)) -> 1 | Q13: =IF(OR((N13=O13),(O13=0)),N13,(IF(AND((N13=0),(O13<>0)),O13,$AD$7))) -> 10 | R13: =(IF((Q13<>$AD$7),(J13+K13-Q13),D13)) -> 12 | S13: =(IF((Q13<>$AD$7),0,K13)) -> 0 | T13: =(IF(OR((R13=L13),(R13=M13)),R13,0)) -> 12 | U13: =(IF(AND((P13=0),(OR((M13=N13),(M13=O13)))),S13,(IF((S13<>0),(IF(OR((S13=L13),(S13=M13)),S13,0)),0)))) -> 0 | V13: =IF(R13=0,0,VLOOKUP(R13,FREQUENCIAS!$1:$1048576,(IF(($A13=FREQUENCIAS!$F$1),6,"ERRO")),FREQUENCIAS!$1:$1048576)) -> 0.29338 | W13: =IF(S13=0,0,VLOOKUP(S13,FREQUENCIAS!$1:$1048576,(IF(($A13=FREQUENCIAS!$F$1),6,"ERRO")),FREQUENCIAS!$1:$1048576)) -> 0 | AA13: =((IF((AND(($H13=$J13),($I13=$K13))),2,( IF((OR(($H13=$J13),($I13=$K13),($H13=$K13),($I13=$J13))),1,0))))) -> 1 | AB13: =((IF((AND(($H13=$L13),($I13=$M13))),2,( IF((OR(($H13=$L13),($I13=$M13),($H13=$M13),($I13=$L13))),1,0))))) -> 0 | AC13: =((IF((AND(($J13=$L13),($K13=$M13))),2,( IF((OR(($J13=$L13),($K13=$M13),($J13=$M13),($K13=$L13))),1,0))))) -> 1 | AD13: TROCA POSSÍVEL | AE13: =(1-AA13)^2 -> 0 | AG13: =IF((AND((AA13>=1),(AC13>=1))),"INCLUSÃO","VERIFICAR") -> INCLUSÃO | AI13: 1 / F
A14: Penta E | B14: ='DADOS FINAIS'!B14 -> 11 | C14: ='DADOS FINAIS'!C14 -> 11 | D14: ='DADOS FINAIS'!D14 -> 7 | E14: ='DADOS FINAIS'!E14 -> 11 | F14: ='DADOS FINAIS'!F14 -> 7 | G14: ='DADOS FINAIS'!G14 -> 12 | H14: =IF((B14>C14),C14,B14) -> 11 | I14: =IF((C14>B14),C14,B14) -> 11 | J14: =IF((D14>E14),E14,D14) -> 7 | K14: =IF((E14>D14),E14,D14) -> 11 | L14: =IF((F14>G14),G14,F14) -> 7 | M14: =IF((G14>F14),G14,F14) -> 12 | N14: =IF((J14=H14),J14,(IF((J14=I14),J14,0))) -> 0 | O14: =IF((K14=H14),K14,(IF((K14=I14),K14,0))) -> 11 | P14: =(IF(((N14+O14)=(J14+K14)),0,1)) -> 1 | Q14: =IF(OR((N14=O14),(O14=0)),N14,(IF(AND((N14=0),(O14<>0)),O14,$AD$7))) -> 11 | R14: =(IF((Q14<>$AD$7),(J14+K14-Q14),D14)) -> 7 | S14: =(IF((Q14<>$AD$7),0,K14)) -> 0 | T14: =(IF(OR((R14=L14),(R14=M14)),R14,0)) -> 7 | U14: =(IF(AND((P14=0),(OR((M14=N14),(M14=O14)))),S14,(IF((S14<>0),(IF(OR((S14=L14),(S14=M14)),S14,0)),0)))) -> 0 | V14: =IF(R14=0,0,VLOOKUP(R14,FREQUENCIAS!$1:$1048576,(IF(($A14=FREQUENCIAS!$G$1),7,"ERRO")),FREQUENCIAS!$1:$1048576)) -> 0.109383 | W14: =IF(S14=0,0,VLOOKUP(S14,FREQUENCIAS!$1:$1048576,(IF(($A14=FREQUENCIAS!$G$1),7,"ERRO")),FREQUENCIAS!$1:$1048576)) -> 0 | AA14: =((IF((AND(($H14=$J14),($I14=$K14))),2,( IF((OR(($H14=$J14),($I14=$K14),($H14=$K14),($I14=$J14))),1,0))))) -> 1 | AB14: =((IF((AND(($H14=$L14),($I14=$M14))),2,( IF((OR(($H14=$L14),($I14=$M14),($H14=$M14),($I14=$L14))),1,0))))) -> 0 | AC14: =((IF((AND(($J14=$L14),($K14=$M14))),2,( IF((OR(($J14=$L14),($K14=$M14),($J14=$M14),($K14=$L14))),1,0))))) -> 1 | AE14: =(1-AA14)^2 -> 0 | AG14: =IF((AND((AA14>=1),(AC14>=1))),"INCLUSÃO","VERIFICAR") -> INCLUSÃO
A15: D16S539 | B15: ='DADOS FINAIS'!B15 -> 8 | C15: ='DADOS FINAIS'!C15 -> 12 | D15: ='DADOS FINAIS'!D15 -> 11 | E15: ='DADOS FINAIS'!E15 -> 12 | F15: ='DADOS FINAIS'!F15 -> 11 | G15: ='DADOS FINAIS'!G15 -> 12 | H15: =IF((B15>C15),C15,B15) -> 8 | I15: =IF((C15>B15),C15,B15) -> 12 | J15: =IF((D15>E15),E15,D15) -> 11 | K15: =IF((E15>D15),E15,D15) -> 12 | L15: =IF((F15>G15),G15,F15) -> 11 | M15: =IF((G15>F15),G15,F15) -> 12 | N15: =IF((J15=H15),J15,(IF((J15=I15),J15,0))) -> 0 | O15: =IF((K15=H15),K15,(IF((K15=I15),K15,0))) -> 12 | P15: =(IF(((N15+O15)=(J15+K15)),0,1)) -> 1 | Q15: =IF(OR((N15=O15),(O15=0)),N15,(IF(AND((N15=0),(O15<>0)),O15,$AD$7))) -> 12 | R15: =(IF((Q15<>$AD$7),(J15+K15-Q15),D15)) -> 11 | S15: =(IF((Q15<>$AD$7),0,K15)) -> 0 | T15: =(IF(OR((R15=L15),(R15=M15)),R15,0)) -> 11 | U15: =(IF(AND((P15=0),(OR((M15=N15),(M15=O15)))),S15,(IF((S15<>0),(IF(OR((S15=L15),(S15=M15)),S15,0)),0)))) -> 0 | V15: =IF(R15=0,0,VLOOKUP(R15,FREQUENCIAS!$1:$1048576,(IF(($A15=FREQUENCIAS!$H$1),8,"ERRO")),FREQUENCIAS!$1:$1048576)) -> 0.288681 | W15: =IF(S15=0,0,VLOOKUP(S15,FREQUENCIAS!$1:$1048576,(IF(($A15=FREQUENCIAS!$H$1),8,"ERRO")),FREQUENCIAS!$1:$1048576)) -> 0 | AA15: =((IF((AND(($H15=$J15),($I15=$K15))),2,( IF((OR(($H15=$J15),($I15=$K15),($H15=$K15),($I15=$J15))),1,0))))) -> 1 | AB15: =((IF((AND(($H15=$L15),($I15=$M15))),2,( IF((OR(($H15=$L15),($I15=$M15),($H15=$M15),($I15=$L15))),1,0))))) -> 1 | AC15: =((IF((AND(($J15=$L15),($K15=$M15))),2,( IF((OR(($J15=$L15),($K15=$M15),($J15=$M15),($K15=$L15))),1,0))))) -> 2 | AE15: =(1-AA15)^2 -> 0 | AG15: =IF((AND((AA15>=1),(AC15>=1))),"INCLUSÃO","VERIFICAR") -> INCLUSÃO
A16: D18S51 | B16: ='DADOS FINAIS'!B16 -> 15 | C16: ='DADOS FINAIS'!C16 -> 20 | D16: ='DADOS FINAIS'!D16 -> 15 | E16: ='DADOS FINAIS'!E16 -> 18 | F16: ='DADOS FINAIS'!F16 -> 14 | G16: ='DADOS FINAIS'!G16 -> 18 | H16: =IF((B16>C16),C16,B16) -> 15 | I16: =IF((C16>B16),C16,B16) -> 20 | J16: =IF((D16>E16),E16,D16) -> 15 | K16: =IF((E16>D16),E16,D16) -> 18 | L16: =IF((F16>G16),G16,F16) -> 14 | M16: =IF((G16>F16),G16,F16) -> 18 | N16: =IF((J16=H16),J16,(IF((J16=I16),J16,0))) -> 15 | O16: =IF((K16=H16),K16,(IF((K16=I16),K16,0))) -> 0 | P16: =(IF(((N16+O16)=(J16+K16)),0,1)) -> 1 | Q16: =IF(OR((N16=O16),(O16=0)),N16,(IF(AND((N16=0),(O16<>0)),O16,$AD$7))) -> 15 | R16: =(IF((Q16<>$AD$7),(J16+K16-Q16),D16)) -> 18 | S16: =(IF((Q16<>$AD$7),0,K16)) -> 0 | T16: =(IF(OR((R16=L16),(R16=M16)),R16,0)) -> 18 | U16: =(IF(AND((P16=0),(OR((M16=N16),(M16=O16)))),S16,(IF((S16<>0),(IF(OR((S16=L16),(S16=M16)),S16,0)),0)))) -> 0 | V16: =IF(R16=0,0,VLOOKUP(R16,FREQUENCIAS!$1:$1048576,(IF(($A16=FREQUENCIAS!$I$1),9,"ERRO")),FREQUENCIAS!$1:$1048576)) -> 0.07756 | W16: =IF(S16=0,0,VLOOKUP(S16,FREQUENCIAS!$1:$1048576,(IF(($A16=FREQUENCIAS!$I$1),9,"ERRO")),FREQUENCIAS!$1:$1048576)) -> 0 | AA16: =((IF((AND(($H16=$J16),($I16=$K16))),2,( IF((OR(($H16=$J16),($I16=$K16),($H16=$K16),($I16=$J16))),1,0))))) -> 1 | AB16: =((IF((AND(($H16=$L16),($I16=$M16))),2,( IF((OR(($H16=$L16),($I16=$M16),($H16=$M16),($I16=$L16))),1,0))))) -> 0 | AC16: =((IF((AND(($J16=$L16),($K16=$M16))),2,( IF((OR(($J16=$L16),($K16=$M16),($J16=$M16),($K16=$L16))),1,0))))) -> 1 | AE16: =(1-AA16)^2 -> 0 | AG16: =IF((AND((AA16>=1),(AC16>=1))),"INCLUSÃO","VERIFICAR") -> INCLUSÃO
A17: D2S1338 | B17: ='DADOS FINAIS'!B17 -> 20 | C17: ='DADOS FINAIS'!C17 -> 22 | D17: ='DADOS FINAIS'!D17 -> 17 | E17: ='DADOS FINAIS'!E17 -> 20 | F17: ='DADOS FINAIS'!F17 -> 17 | G17: ='DADOS FINAIS'!G17 -> 17 | H17: =IF((B17>C17),C17,B17) -> 20 | I17: =IF((C17>B17),C17,B17) -> 22 | J17: =IF((D17>E17),E17,D17) -> 17 | K17: =IF((E17>D17),E17,D17) -> 20 | L17: =IF((F17>G17),G17,F17) -> 17 | M17: =IF((G17>F17),G17,F17) -> 17 | N17: =IF((J17=H17),J17,(IF((J17=I17),J17,0))) -> 0 | O17: =IF((K17=H17),K17,(IF((K17=I17),K17,0))) -> 20 | P17: =(IF(((N17+O17)=(J17+K17)),0,1)) -> 1 | Q17: =IF(OR((N17=O17),(O17=0)),N17,(IF(AND((N17=0),(O17<>0)),O17,$AD$7))) -> 20 | R17: =(IF((Q17<>$AD$7),(J17+K17-Q17),D17)) -> 17 | S17: =(IF((Q17<>$AD$7),0,K17)) -> 0 | T17: =(IF(OR((R17=L17),(R17=M17)),R17,0)) -> 17 | U17: =(IF(AND((P17=0),(OR((M17=N17),(M17=O17)))),S17,(IF((S17<>0),(IF(OR((S17=L17),(S17=M17)),S17,0)),0)))) -> 0 | V17: =IF(R17=0,0,VLOOKUP(R17,FREQUENCIAS!$1:$1048576,(IF(($A17=FREQUENCIAS!$J$1),10,"ERRO")),FREQUENCIAS!$1:$1048576)) -> 0.2077 | W17: =IF(S17=0,0,VLOOKUP(S17,FREQUENCIAS!$1:$1048576,(IF(($A17=FREQUENCIAS!$J$1),10,"ERRO")),FREQUENCIAS!$1:$1048576)) -> 0 | AA17: =((IF((AND(($H17=$J17),($I17=$K17))),2,( IF((OR(($H17=$J17),($I17=$K17),($H17=$K17),($I17=$J17))),1,0))))) -> 1 | AB17: =((IF((AND(($H17=$L17),($I17=$M17))),2,( IF((OR(($H17=$L17),($I17=$M17),($H17=$M17),($I17=$L17))),1,0))))) -> 0 | AC17: =((IF((AND(($J17=$L17),($K17=$M17))),2,( IF((OR(($J17=$L17),($K17=$M17),($J17=$M17),($K17=$L17))),1,0))))) -> 1 | AD17: NIHIL | AE17: =(1-AA17)^2 -> 0 | AG17: =IF((AND((AA17>=1),(AC17>=1))),"INCLUSÃO","VERIFICAR") -> INCLUSÃO
A18: CSF1PO | B18: ='DADOS FINAIS'!B18 -> 10 | C18: ='DADOS FINAIS'!C18 -> 11 | D18: ='DADOS FINAIS'!D18 -> 10 | E18: ='DADOS FINAIS'!E18 -> 10 | F18: ='DADOS FINAIS'!F18 -> 10 | G18: ='DADOS FINAIS'!G18 -> 10 | H18: =IF((B18>C18),C18,B18) -> 10 | I18: =IF((C18>B18),C18,B18) -> 11 | J18: =IF((D18>E18),E18,D18) -> 10 | K18: =IF((E18>D18),E18,D18) -> 10 | L18: =IF((F18>G18),G18,F18) -> 10 | M18: =IF((G18>F18),G18,F18) -> 10 | N18: =IF((J18=H18),J18,(IF((J18=I18),J18,0))) -> 10 | O18: =IF((K18=H18),K18,(IF((K18=I18),K18,0))) -> 10 | P18: =(IF(((N18+O18)=(J18+K18)),0,1)) -> 0 | Q18: =IF(OR((N18=O18),(O18=0)),N18,(IF(AND((N18=0),(O18<>0)),O18,$AD$7))) -> 10 | R18: =(IF((Q18<>$AD$7),(J18+K18-Q18),D18)) -> 10 | S18: =(IF((Q18<>$AD$7),0,K18)) -> 0 | T18: =(IF(OR((R18=L18),(R18=M18)),R18,0)) -> 10 | U18: =(IF(AND((P18=0),(OR((M18=N18),(M18=O18)))),S18,(IF((S18<>0),(IF(OR((S18=L18),(S18=M18)),S18,0)),0)))) -> 0 | V18: =IF(R18=0,0,VLOOKUP(R18,FREQUENCIAS!$1:$1048576,(IF(($A18=FREQUENCIAS!$K$1),11,"ERRO")),FREQUENCIAS!$1:$1048576)) -> 0.262376 | W18: =IF(S18=0,0,VLOOKUP(S18,FREQUENCIAS!$1:$1048576,(IF(($A18=FREQUENCIAS!$K$1),11,"ERRO")),FREQUENCIAS!$1:$1048576)) -> 0 | AA18: =((IF((AND(($H18=$J18),($I18=$K18))),2,( IF((OR(($H18=$J18),($I18=$K18),($H18=$K18),($I18=$J18))),1,0))))) -> 1 | AB18: =((IF((AND(($H18=$L18),($I18=$M18))),2,( IF((OR(($H18=$L18),($I18=$M18),($H18=$M18),($I18=$L18))),1,0))))) -> 1 | AC18: =((IF((AND(($J18=$L18),($K18=$M18))),2,( IF((OR(($J18=$L18),($K18=$M18),($J18=$M18),($K18=$L18))),1,0))))) -> 2 | AE18: =(1-AA18)^2 -> 0 | AG18: =IF((AND((AA18>=1),(AC18>=1))),"INCLUSÃO","VERIFICAR") -> INCLUSÃO
A19: Penta D | B19: ='DADOS FINAIS'!B19 -> 8 | C19: ='DADOS FINAIS'!C19 -> 11 | D19: ='DADOS FINAIS'!D19 -> 11 | E19: ='DADOS FINAIS'!E19 -> 11 | F19: ='DADOS FINAIS'!F19 -> 11 | G19: ='DADOS FINAIS'!G19 -> 12 | H19: =IF((B19>C19),C19,B19) -> 8 | I19: =IF((C19>B19),C19,B19) -> 11 | J19: =IF((D19>E19),E19,D19) -> 11 | K19: =IF((E19>D19),E19,D19) -> 11 | L19: =IF((F19>G19),G19,F19) -> 11 | M19: =IF((G19>F19),G19,F19) -> 12 | N19: =IF((J19=H19),J19,(IF((J19=I19),J19,0))) -> 11 | O19: =IF((K19=H19),K19,(IF((K19=I19),K19,0))) -> 11 | P19: =(IF(((N19+O19)=(J19+K19)),0,1)) -> 0 | Q19: =IF(OR((N19=O19),(O19=0)),N19,(IF(AND((N19=0),(O19<>0)),O19,$AD$7))) -> 11 | R19: =(IF((Q19<>$AD$7),(J19+K19-Q19),D19)) -> 11 | S19: =(IF((Q19<>$AD$7),0,K19)) -> 0 | T19: =(IF(OR((R19=L19),(R19=M19)),R19,0)) -> 11 | U19: =(IF(AND((P19=0),(OR((M19=N19),(M19=O19)))),S19,(IF((S19<>0),(IF(OR((S19=L19),(S19=M19)),S19,0)),0)))) -> 0 | V19: =IF(R19=0,0,VLOOKUP(R19,FREQUENCIAS!$1:$1048576,(IF(($A19=FREQUENCIAS!$L$1),12,"ERRO")),FREQUENCIAS!$1:$1048576)) -> 0.156798 | W19: =IF(S19=0,0,VLOOKUP(S19,FREQUENCIAS!$1:$1048576,(IF(($A19=FREQUENCIAS!$L$1),12,"ERRO")),FREQUENCIAS!$1:$1048576)) -> 0 | AA19: =((IF((AND(($H19=$J19),($I19=$K19))),2,( IF((OR(($H19=$J19),($I19=$K19),($H19=$K19),($I19=$J19))),1,0))))) -> 1 | AB19: =((IF((AND(($H19=$L19),($I19=$M19))),2,( IF((OR(($H19=$L19),($I19=$M19),($H19=$M19),($I19=$L19))),1,0))))) -> 1 | AC19: =((IF((AND(($J19=$L19),($K19=$M19))),2,( IF((OR(($J19=$L19),($K19=$M19),($J19=$M19),($K19=$L19))),1,0))))) -> 1 | AD19: NÃO HOUVE TROCA | AE19: =(1-AA19)^2 -> 0 | AG19: =IF((AND((AA19>=1),(AC19>=1))),"INCLUSÃO","VERIFICAR") -> INCLUSÃO | AI19: 1 / 2F
A20: TH01 | B20: ='DADOS FINAIS'!B20 -> 6 | C20: ='DADOS FINAIS'!C20 -> 7 | D20: ='DADOS FINAIS'!D20 -> 6 | E20: ='DADOS FINAIS'!E20 -> 6 | F20: ='DADOS FINAIS'!F20 -> 6 | G20: ='DADOS FINAIS'!G20 -> 6 | H20: =IF((B20>C20),C20,B20) -> 6 | I20: =IF((C20>B20),C20,B20) -> 7 | J20: =IF((D20>E20),E20,D20) -> 6 | K20: =IF((E20>D20),E20,D20) -> 6 | L20: =IF((F20>G20),G20,F20) -> 6 | M20: =IF((G20>F20),G20,F20) -> 6 | N20: =IF((J20=H20),J20,(IF((J20=I20),J20,0))) -> 6 | O20: =IF((K20=H20),K20,(IF((K20=I20),K20,0))) -> 6 | P20: =(IF(((N20+O20)=(J20+K20)),0,1)) -> 0 | Q20: =IF(OR((N20=O20),(O20=0)),N20,(IF(AND((N20=0),(O20<>0)),O20,$AD$7))) -> 6 | R20: =(IF((Q20<>$AD$7),(J20+K20-Q20),D20)) -> 6 | S20: =(IF((Q20<>$AD$7),0,K20)) -> 0 | T20: =(IF(OR((R20=L20),(R20=M20)),R20,0)) -> 6 | U20: =(IF(AND((P20=0),(OR((M20=N20),(M20=O20)))),S20,(IF((S20<>0),(IF(OR((S20=L20),(S20=M20)),S20,0)),0)))) -> 0 | V20: =IF(R20=0,0,VLOOKUP(R20,FREQUENCIAS!$1:$1048576,(IF(($A20=FREQUENCIAS!$M$1),13,"ERRO")),FREQUENCIAS!$1:$1048576)) -> 0.211238 | W20: =IF(S20=0,0,VLOOKUP(S20,FREQUENCIAS!$1:$1048576,(IF(($A20=FREQUENCIAS!$M$1),13,"ERRO")),FREQUENCIAS!$1:$1048576)) -> 0 | AA20: =((IF((AND(($H20=$J20),($I20=$K20))),2,( IF((OR(($H20=$J20),($I20=$K20),($H20=$K20),($I20=$J20))),1,0))))) -> 1 | AB20: =((IF((AND(($H20=$L20),($I20=$M20))),2,( IF((OR(($H20=$L20),($I20=$M20),($H20=$M20),($I20=$L20))),1,0))))) -> 1 | AC20: =((IF((AND(($J20=$L20),($K20=$M20))),2,( IF((OR(($J20=$L20),($K20=$M20),($J20=$M20),($K20=$L20))),1,0))))) -> 2 | AE20: =(1-AA20)^2 -> 0 | AG20: =IF((AND((AA20>=1),(AC20>=1))),"INCLUSÃO","VERIFICAR") -> INCLUSÃO
A21: vWA | B21: ='DADOS FINAIS'!B21 -> 15 | C21: ='DADOS FINAIS'!C21 -> 17 | D21: ='DADOS FINAIS'!D21 -> 15 | E21: ='DADOS FINAIS'!E21 -> 17 | F21: ='DADOS FINAIS'!F21 -> 17 | G21: ='DADOS FINAIS'!G21 -> 17 | H21: =IF((B21>C21),C21,B21) -> 15 | I21: =IF((C21>B21),C21,B21) -> 17 | J21: =IF((D21>E21),E21,D21) -> 15 | K21: =IF((E21>D21),E21,D21) -> 17 | L21: =IF((F21>G21),G21,F21) -> 17 | M21: =IF((G21>F21),G21,F21) -> 17 | N21: =IF((J21=H21),J21,(IF((J21=I21),J21,0))) -> 15 | O21: =IF((K21=H21),K21,(IF((K21=I21),K21,0))) -> 17 | P21: =(IF(((N21+O21)=(J21+K21)),0,1)) -> 0 | Q21: =IF(OR((N21=O21),(O21=0)),N21,(IF(AND((N21=0),(O21<>0)),O21,$AD$7))) -> NÃO DEF | R21: =(IF((Q21<>$AD$7),(J21+K21-Q21),D21)) -> 15 | S21: =(IF((Q21<>$AD$7),0,K21)) -> 17 | T21: =(IF(OR((R21=L21),(R21=M21)),R21,0)) -> 0 | U21: =(IF(AND((P21=0),(OR((M21=N21),(M21=O21)))),S21,(IF((S21<>0),(IF(OR((S21=L21),(S21=M21)),S21,0)),0)))) -> 17 | V21: =IF(R21=0,0,VLOOKUP(R21,FREQUENCIAS!$1:$1048576,(IF(($A21=FREQUENCIAS!$N$1),14,"ERRO")),FREQUENCIAS!$1:$1048576)) -> 0.137994 | W21: =IF(S21=0,0,VLOOKUP(S21,FREQUENCIAS!$1:$1048576,(IF(($A21=FREQUENCIAS!$N$1),14,"ERRO")),FREQUENCIAS!$1:$1048576)) -> 0.254844 | AA21: =((IF((AND(($H21=$J21),($I21=$K21))),2,( IF((OR(($H21=$J21),($I21=$K21),($H21=$K21),($I21=$J21))),1,0))))) -> 2 | AB21: =((IF((AND(($H21=$L21),($I21=$M21))),2,( IF((OR(($H21=$L21),($I21=$M21),($H21=$M21),($I21=$L21))),1,0))))) -> 1 | AC21: =((IF((AND(($J21=$L21),($K21=$M21))),2,( IF((OR(($J21=$L21),($K21=$M21),($J21=$M21),($K21=$L21))),1,0))))) -> 1 | AE21: =(1-AA21)^2 -> 1 | AG21: =IF((AND((AA21>=1),(AC21>=1))),"INCLUSÃO","VERIFICAR") -> INCLUSÃO
A22: D21S11 | B22: ='DADOS FINAIS'!B22 -> 31.2 | C22: ='DADOS FINAIS'!C22 -> 33.2 | D22: ='DADOS FINAIS'!D22 -> 28 | E22: ='DADOS FINAIS'!E22 -> 31.2 | F22: ='DADOS FINAIS'!F22 -> 28 | G22: ='DADOS FINAIS'!G22 -> 30 | H22: =IF((B22>C22),C22,B22) -> 31.2 | I22: =IF((C22>B22),C22,B22) -> 33.2 | J22: =IF((D22>E22),E22,D22) -> 28 | K22: =IF((E22>D22),E22,D22) -> 31.2 | L22: =IF((F22>G22),G22,F22) -> 28 | M22: =IF((G22>F22),G22,F22) -> 30 | N22: =IF((J22=H22),J22,(IF((J22=I22),J22,0))) -> 0 | O22: =IF((K22=H22),K22,(IF((K22=I22),K22,0))) -> 31.2 | P22: =(IF(((N22+O22)=(J22+K22)),0,1)) -> 1 | Q22: =IF(OR((N22=O22),(O22=0)),N22,(IF(AND((N22=0),(O22<>0)),O22,$AD$7))) -> 31.2 | R22: =(IF((Q22<>$AD$7),(J22+K22-Q22),D22)) -> 28 | S22: =(IF((Q22<>$AD$7),0,K22)) -> 0 | T22: =(IF(OR((R22=L22),(R22=M22)),R22,0)) -> 28 | U22: =(IF(AND((P22=0),(OR((M22=N22),(M22=O22)))),S22,(IF((S22<>0),(IF(OR((S22=L22),(S22=M22)),S22,0)),0)))) -> 0 | V22: =IF(R22=0,0,VLOOKUP(R22,FREQUENCIAS!$1:$1048576,(IF(($A22=FREQUENCIAS!$O$1),15,"ERRO")),FREQUENCIAS!$1:$1048576)) -> #N/A | W22: =IF(S22=0,0,VLOOKUP(S22,FREQUENCIAS!$1:$1048576,(IF(($A22=FREQUENCIAS!$O$1),15,"ERRO")),FREQUENCIAS!$1:$1048576)) -> 0 | AA22: =((IF((AND(($H22=$J22),($I22=$K22))),2,( IF((OR(($H22=$J22),($I22=$K22),($H22=$K22),($I22=$J22))),1,0))))) -> 1 | AB22: =((IF((AND(($H22=$L22),($I22=$M22))),2,( IF((OR(($H22=$L22),($I22=$M22),($H22=$M22),($I22=$L22))),1,0))))) -> 0 | AC22: =((IF((AND(($J22=$L22),($K22=$M22))),2,( IF((OR(($J22=$L22),($K22=$M22),($J22=$M22),($K22=$L22))),1,0))))) -> 1 | AE22: =(1-AA22)^2 -> 0 | AG22: =IF((AND((AA22>=1),(AC22>=1))),"INCLUSÃO","VERIFICAR") -> INCLUSÃO
A23: D7S820 | B23: ='DADOS FINAIS'!B23 -> 8 | C23: ='DADOS FINAIS'!C23 -> 10 | D23: ='DADOS FINAIS'!D23 -> 10 | E23: ='DADOS FINAIS'!E23 -> 10 | F23: ='DADOS FINAIS'!F23 -> 10 | G23: ='DADOS FINAIS'!G23 -> 10 | H23: =IF((B23>C23),C23,B23) -> 8 | I23: =IF((C23>B23),C23,B23) -> 10 | J23: =IF((D23>E23),E23,D23) -> 10 | K23: =IF((E23>D23),E23,D23) -> 10 | L23: =IF((F23>G23),G23,F23) -> 10 | M23: =IF((G23>F23),G23,F23) -> 10 | N23: =IF((J23=H23),J23,(IF((J23=I23),J23,0))) -> 10 | O23: =IF((K23=H23),K23,(IF((K23=I23),K23,0))) -> 10 | P23: =(IF(((N23+O23)=(J23+K23)),0,1)) -> 0 | Q23: =IF(OR((N23=O23),(O23=0)),N23,(IF(AND((N23=0),(O23<>0)),O23,$AD$7))) -> 10 | R23: =(IF((Q23<>$AD$7),(J23+K23-Q23),D23)) -> 10 | S23: =(IF((Q23<>$AD$7),0,K23)) -> 0 | T23: =(IF(OR((R23=L23),(R23=M23)),R23,0)) -> 10 | U23: =(IF(AND((P23=0),(OR((M23=N23),(M23=O23)))),S23,(IF((S23<>0),(IF(OR((S23=L23),(S23=M23)),S23,0)),0)))) -> 0 | V23: =IF(R23=0,0,VLOOKUP(R23,FREQUENCIAS!$1:$1048576,(IF(($A23=FREQUENCIAS!$P$1),16,"ERRO")),FREQUENCIAS!$1:$1048576)) -> 0.275034 | W23: =IF(S23=0,0,VLOOKUP(S23,FREQUENCIAS!$1:$1048576,(IF(($A23=FREQUENCIAS!$P$1),16,"ERRO")),FREQUENCIAS!$1:$1048576)) -> 0 | AA23: =((IF((AND(($H23=$J23),($I23=$K23))),2,( IF((OR(($H23=$J23),($I23=$K23),($H23=$K23),($I23=$J23))),1,0))))) -> 1 | AB23: =((IF((AND(($H23=$L23),($I23=$M23))),2,( IF((OR(($H23=$L23),($I23=$M23),($H23=$M23),($I23=$L23))),1,0))))) -> 1 | AC23: =((IF((AND(($J23=$L23),($K23=$M23))),2,( IF((OR(($J23=$L23),($K23=$M23),($J23=$M23),($K23=$L23))),1,0))))) -> 2 | AD23: NIHIL | AE23: =(1-AA23)^2 -> 0 | AG23: =IF((AND((AA23>=1),(AC23>=1))),"INCLUSÃO","VERIFICAR") -> INCLUSÃO
A24: D5S818 | B24: ='DADOS FINAIS'!B24 -> 9 | C24: ='DADOS FINAIS'!C24 -> 13 | D24: ='DADOS FINAIS'!D24 -> 9 | E24: ='DADOS FINAIS'!E24 -> 11 | F24: ='DADOS FINAIS'!F24 -> 11 | G24: ='DADOS FINAIS'!G24 -> 11 | H24: =IF((B24>C24),C24,B24) -> 9 | I24: =IF((C24>B24),C24,B24) -> 13 | J24: =IF((D24>E24),E24,D24) -> 9 | K24: =IF((E24>D24),E24,D24) -> 11 | L24: =IF((F24>G24),G24,F24) -> 11 | M24: =IF((G24>F24),G24,F24) -> 11 | N24: =IF((J24=H24),J24,(IF((J24=I24),J24,0))) -> 9 | O24: =IF((K24=H24),K24,(IF((K24=I24),K24,0))) -> 0 | P24: =(IF(((N24+O24)=(J24+K24)),0,1)) -> 1 | Q24: =IF(OR((N24=O24),(O24=0)),N24,(IF(AND((N24=0),(O24<>0)),O24,$AD$7))) -> 9 | R24: =(IF((Q24<>$AD$7),(J24+K24-Q24),D24)) -> 11 | S24: =(IF((Q24<>$AD$7),0,K24)) -> 0 | T24: =(IF(OR((R24=L24),(R24=M24)),R24,0)) -> 11 | U24: =(IF(AND((P24=0),(OR((M24=N24),(M24=O24)))),S24,(IF((S24<>0),(IF(OR((S24=L24),(S24=M24)),S24,0)),0)))) -> 0 | V24: =IF(R24=0,0,VLOOKUP(R24,FREQUENCIAS!$1:$1048576,(IF(($A24=FREQUENCIAS!$Q$1),17,"ERRO")),FREQUENCIAS!$1:$1048576)) -> 0.329063 | W24: =IF(S24=0,0,VLOOKUP(S24,FREQUENCIAS!$1:$1048576,(IF(($A24=FREQUENCIAS!$Q$1),17,"ERRO")),FREQUENCIAS!$1:$1048576)) -> 0 | AA24: =((IF((AND(($H24=$J24),($I24=$K24))),2,( IF((OR(($H24=$J24),($I24=$K24),($H24=$K24),($I24=$J24))),1,0))))) -> 1 | AB24: =((IF((AND(($H24=$L24),($I24=$M24))),2,( IF((OR(($H24=$L24),($I24=$M24),($H24=$M24),($I24=$L24))),1,0))))) -> 0 | AC24: =((IF((AND(($J24=$L24),($K24=$M24))),2,( IF((OR(($J24=$L24),($K24=$M24),($J24=$M24),($K24=$L24))),1,0))))) -> 1 | AD24: NIHIL | AE24: =(1-AA24)^2 -> 0 | AG24: =IF((AND((AA24>=1),(AC24>=1))),"INCLUSÃO","VERIFICAR") -> INCLUSÃO
A25: TPOX | B25: ='DADOS FINAIS'!B25 -> 11 | C25: ='DADOS FINAIS'!C25 -> 11 | D25: ='DADOS FINAIS'!D25 -> 8 | E25: ='DADOS FINAIS'!E25 -> 11 | F25: ='DADOS FINAIS'!F25 -> 7 | G25: ='DADOS FINAIS'!G25 -> 8 | H25: =IF((B25>C25),C25,B25) -> 11 | I25: =IF((C25>B25),C25,B25) -> 11 | J25: =IF((D25>E25),E25,D25) -> 8 | K25: =IF((E25>D25),E25,D25) -> 11 | L25: =IF((F25>G25),G25,F25) -> 7 | M25: =IF((G25>F25),G25,F25) -> 8 | N25: =IF((J25=H25),J25,(IF((J25=I25),J25,0))) -> 0 | O25: =IF((K25=H25),K25,(IF((K25=I25),K25,0))) -> 11 | P25: =(IF(((N25+O25)=(J25+K25)),0,1)) -> 1 | Q25: =IF(OR((N25=O25),(O25=0)),N25,(IF(AND((N25=0),(O25<>0)),O25,$AD$7))) -> 11 | R25: =(IF((Q25<>$AD$7),(J25+K25-Q25),D25)) -> 8 | S25: =(IF((Q25<>$AD$7),0,K25)) -> 0 | T25: =(IF(OR((R25=L25),(R25=M25)),R25,0)) -> 8 | U25: =(IF(AND((P25=0),(OR((M25=N25),(M25=O25)))),S25,(IF((S25<>0),(IF(OR((S25=L25),(S25=M25)),S25,0)),0)))) -> 0 | V25: =IF(R25=0,0,VLOOKUP(R25,FREQUENCIAS!$1:$1048576,(IF(($A25=FREQUENCIAS!$R$1),18,"ERRO")),FREQUENCIAS!$1:$1048576)) -> 0.455862 | W25: =IF(S25=0,0,VLOOKUP(S25,FREQUENCIAS!$1:$1048576,(IF(($A25=FREQUENCIAS!$R$1),18,"ERRO")),FREQUENCIAS!$1:$1048576)) -> 0 | AA25: =((IF((AND(($H25=$J25),($I25=$K25))),2,( IF((OR(($H25=$J25),($I25=$K25),($H25=$K25),($I25=$J25))),1,0))))) -> 1 | AB25: =((IF((AND(($H25=$L25),($I25=$M25))),2,( IF((OR(($H25=$L25),($I25=$M25),($H25=$M25),($I25=$L25))),1,0))))) -> 0 | AC25: =((IF((AND(($J25=$L25),($K25=$M25))),2,( IF((OR(($J25=$L25),($K25=$M25),($J25=$M25),($K25=$L25))),1,0))))) -> 1 | AD25: NIHIL | AE25: =(1-AA25)^2 -> 0 | AG25: =IF((AND((AA25>=1),(AC25>=1))),"INCLUSÃO","VERIFICAR") -> INCLUSÃO
A26: D8S1179 | B26: ='DADOS FINAIS'!B26 -> 10 | C26: ='DADOS FINAIS'!C26 -> 14 | D26: ='DADOS FINAIS'!D26 -> 10 | E26: ='DADOS FINAIS'!E26 -> 14 | F26: ='DADOS FINAIS'!F26 -> 14 | G26: ='DADOS FINAIS'!G26 -> 15 | H26: =IF((B26>C26),C26,B26) -> 10 | I26: =IF((C26>B26),C26,B26) -> 14 | J26: =IF((D26>E26),E26,D26) -> 10 | K26: =IF((E26>D26),E26,D26) -> 14 | L26: =IF((F26>G26),G26,F26) -> 14 | M26: =IF((G26>F26),G26,F26) -> 15 | N26: =IF((J26=H26),J26,(IF((J26=I26),J26,0))) -> 10 | O26: =IF((K26=H26),K26,(IF((K26=I26),K26,0))) -> 14 | P26: =(IF(((N26+O26)=(J26+K26)),0,1)) -> 0 | Q26: =IF(OR((N26=O26),(O26=0)),N26,(IF(AND((N26=0),(O26<>0)),O26,$AD$7))) -> NÃO DEF | R26: =(IF((Q26<>$AD$7),(J26+K26-Q26),D26)) -> 10 | S26: =(IF((Q26<>$AD$7),0,K26)) -> 14 | T26: =(IF(OR((R26=L26),(R26=M26)),R26,0)) -> 0 | U26: =(IF(AND((P26=0),(OR((M26=N26),(M26=O26)))),S26,(IF((S26<>0),(IF(OR((S26=L26),(S26=M26)),S26,0)),0)))) -> 14 | V26: =IF(R26=0,0,VLOOKUP(R26,FREQUENCIAS!$1:$1048576,(IF(($A26=FREQUENCIAS!$S$1),19,"ERRO")),FREQUENCIAS!$1:$1048576)) -> 0.068213 | W26: =IF(S26=0,0,VLOOKUP(S26,FREQUENCIAS!$1:$1048576,(IF(($A26=FREQUENCIAS!$S$1),19,"ERRO")),FREQUENCIAS!$1:$1048576)) -> 0.25087 | AA26: =((IF((AND(($H26=$J26),($I26=$K26))),2,( IF((OR(($H26=$J26),($I26=$K26),($H26=$K26),($I26=$J26))),1,0))))) -> 2 | AB26: =((IF((AND(($H26=$L26),($I26=$M26))),2,( IF((OR(($H26=$L26),($I26=$M26),($H26=$M26),($I26=$L26))),1,0))))) -> 1 | AC26: =((IF((AND(($J26=$L26),($K26=$M26))),2,( IF((OR(($J26=$L26),($K26=$M26),($J26=$M26),($K26=$L26))),1,0))))) -> 1 | AD26: NIHIL | AE26: =(1-AA26)^2 -> 1 | AG26: =IF((AND((AA26>=1),(AC26>=1))),"INCLUSÃO","VERIFICAR") -> INCLUSÃO
A27: D12S391 | B27: ='DADOS FINAIS'!B27 -> 17 | C27: ='DADOS FINAIS'!C27 -> 19 | D27: ='DADOS FINAIS'!D27 -> 18.3 | E27: ='DADOS FINAIS'!E27 -> 19 | F27: ='DADOS FINAIS'!F27 -> 18.3 | G27: ='DADOS FINAIS'!G27 -> 22 | H27: =IF((B27>C27),C27,B27) -> 17 | I27: =IF((C27>B27),C27,B27) -> 19 | J27: =IF((D27>E27),E27,D27) -> 18.3 | K27: =IF((E27>D27),E27,D27) -> 19 | L27: =IF((F27>G27),G27,F27) -> 18.3 | M27: =IF((G27>F27),G27,F27) -> 22 | N27: =IF((J27=H27),J27,(IF((J27=I27),J27,0))) -> 0 | O27: =IF((K27=H27),K27,(IF((K27=I27),K27,0))) -> 19 | P27: =(IF(((N27+O27)=(J27+K27)),0,1)) -> 1 | Q27: =IF(OR((N27=O27),(O27=0)),N27,(IF(AND((N27=0),(O27<>0)),O27,$AD$7))) -> 19 | R27: =(IF((Q27<>$AD$7),(J27+K27-Q27),D27)) -> 18.3 | S27: =(IF((Q27<>$AD$7),0,K27)) -> 0 | T27: =(IF(OR((R27=L27),(R27=M27)),R27,0)) -> 18.3 | U27: =(IF(AND((P27=0),(OR((M27=N27),(M27=O27)))),S27,(IF((S27<>0),(IF(OR((S27=L27),(S27=M27)),S27,0)),0)))) -> 0 | V27: =IF(R27=0,0,VLOOKUP(R27,FREQUENCIAS!$1:$1048576,(IF(($A27=FREQUENCIAS!$T$1),20,"ERRO")),FREQUENCIAS!$1:$1048576)) -> #N/A | W27: =IF(S27=0,0,VLOOKUP(S27,FREQUENCIAS!$1:$1048576,(IF(($A27=FREQUENCIAS!$T$1),20,"ERRO")),FREQUENCIAS!$1:$1048576)) -> 0 | AA27: =((IF((AND(($H27=$J27),($I27=$K27))),2,( IF((OR(($H27=$J27),($I27=$K27),($H27=$K27),($I27=$J27))),1,0))))) -> 1 | AB27: =((IF((AND(($H27=$L27),($I27=$M27))),2,( IF((OR(($H27=$L27),($I27=$M27),($H27=$M27),($I27=$L27))),1,0))))) -> 0 | AC27: =((IF((AND(($J27=$L27),($K27=$M27))),2,( IF((OR(($J27=$L27),($K27=$M27),($J27=$M27),($K27=$L27))),1,0))))) -> 1 | AD27: NIHIL | AE27: =(1-AA27)^2 -> 0 | AG27: =IF((AND((AA27>=1),(AC27>=1))),"INCLUSÃO","VERIFICAR") -> INCLUSÃO
A28: D19S433 | B28: ='DADOS FINAIS'!B28 -> 12 | C28: ='DADOS FINAIS'!C28 -> 14 | D28: ='DADOS FINAIS'!D28 -> 14 | E28: ='DADOS FINAIS'!E28 -> 14 | F28: ='DADOS FINAIS'!F28 -> 14 | G28: ='DADOS FINAIS'!G28 -> 14 | H28: =IF((B28>C28),C28,B28) -> 12 | I28: =IF((C28>B28),C28,B28) -> 14 | J28: =IF((D28>E28),E28,D28) -> 14 | K28: =IF((E28>D28),E28,D28) -> 14 | L28: =IF((F28>G28),G28,F28) -> 14 | M28: =IF((G28>F28),G28,F28) -> 14 | N28: =IF((J28=H28),J28,(IF((J28=I28),J28,0))) -> 14 | O28: =IF((K28=H28),K28,(IF((K28=I28),K28,0))) -> 14 | P28: =(IF(((N28+O28)=(J28+K28)),0,1)) -> 0 | Q28: =IF(OR((N28=O28),(O28=0)),N28,(IF(AND((N28=0),(O28<>0)),O28,$AD$7))) -> 14 | R28: =(IF((Q28<>$AD$7),(J28+K28-Q28),D28)) -> 14 | S28: =(IF((Q28<>$AD$7),0,K28)) -> 0 | T28: =(IF(OR((R28=L28),(R28=M28)),R28,0)) -> 14 | U28: =(IF(AND((P28=0),(OR((M28=N28),(M28=O28)))),S28,(IF((S28<>0),(IF(OR((S28=L28),(S28=M28)),S28,0)),0)))) -> 0 | V28: =IF(R28=0,0,VLOOKUP(R28,FREQUENCIAS!$1:$1048576,(IF(($A28=FREQUENCIAS!$U$1),21,"ERRO")),FREQUENCIAS!$1:$1048576)) -> 0.2941 | W28: =IF(S28=0,0,VLOOKUP(S28,FREQUENCIAS!$1:$1048576,(IF(($A28=FREQUENCIAS!$U$1),21,"ERRO")),FREQUENCIAS!$1:$1048576)) -> 0 | AA28: =((IF((AND(($H28=$J28),($I28=$K28))),2,( IF((OR(($H28=$J28),($I28=$K28),($H28=$K28),($I28=$J28))),1,0))))) -> 1 | AB28: =((IF((AND(($H28=$L28),($I28=$M28))),2,( IF((OR(($H28=$L28),($I28=$M28),($H28=$M28),($I28=$L28))),1,0))))) -> 1 | AC28: =((IF((AND(($J28=$L28),($K28=$M28))),2,( IF((OR(($J28=$L28),($K28=$M28),($J28=$M28),($K28=$L28))),1,0))))) -> 2 | AD28: NIHIL | AE28: =(1-AA28)^2 -> 0 | AG28: =IF((AND((AA28>=1),(AC28>=1))),"INCLUSÃO","VERIFICAR") -> INCLUSÃO
A29: FGA | B29: ='DADOS FINAIS'!B29 -> 21 | C29: ='DADOS FINAIS'!C29 -> 23 | D29: ='DADOS FINAIS'!D29 -> 19 | E29: ='DADOS FINAIS'!E29 -> 21 | F29: ='DADOS FINAIS'!F29 -> 19 | G29: ='DADOS FINAIS'!G29 -> 26 | H29: =IF((B29>C29),C29,B29) -> 21 | I29: =IF((C29>B29),C29,B29) -> 23 | J29: =IF((D29>E29),E29,D29) -> 19 | K29: =IF((E29>D29),E29,D29) -> 21 | L29: =IF((F29>G29),G29,F29) -> 19 | M29: =IF((G29>F29),G29,F29) -> 26 | N29: =IF((J29=H29),J29,(IF((J29=I29),J29,0))) -> 0 | O29: =IF((K29=H29),K29,(IF((K29=I29),K29,0))) -> 21 | P29: =(IF(((N29+O29)=(J29+K29)),0,1)) -> 1 | Q29: =IF(OR((N29=O29),(O29=0)),N29,(IF(AND((N29=0),(O29<>0)),O29,$AD$7))) -> 21 | R29: =(IF((Q29<>$AD$7),(J29+K29-Q29),D29)) -> 19 | S29: =(IF((Q29<>$AD$7),0,K29)) -> 0 | T29: =(IF(OR((R29=L29),(R29=M29)),R29,0)) -> 19 | U29: =(IF(AND((P29=0),(OR((M29=N29),(M29=O29)))),S29,(IF((S29<>0),(IF(OR((S29=L29),(S29=M29)),S29,0)),0)))) -> 0 | V29: =IF(R29=0,0,VLOOKUP(R29,FREQUENCIAS!$1:$1048576,(IF(($A29=FREQUENCIAS!$V$1),22,"ERRO")),FREQUENCIAS!$1:$1048576)) -> 0.075358 | W29: =IF(S29=0,0,VLOOKUP(S29,FREQUENCIAS!$1:$1048576,(IF(($A29=FREQUENCIAS!$V$1),22,"ERRO")),FREQUENCIAS!$1:$1048576)) -> 0 | AA29: =((IF((AND(($H29=$J29),($I29=$K29))),2,( IF((OR(($H29=$J29),($I29=$K29),($H29=$K29),($I29=$J29))),1,0))))) -> 1 | AB29: =((IF((AND(($H29=$L29),($I29=$M29))),2,( IF((OR(($H29=$L29),($I29=$M29),($H29=$M29),($I29=$L29))),1,0))))) -> 0 | AC29: =((IF((AND(($J29=$L29),($K29=$M29))),2,( IF((OR(($J29=$L29),($K29=$M29),($J29=$M29),($K29=$L29))),1,0))))) -> 1 | AD29: NIHIL | AE29: =(1-AA29)^2 -> 0 | AG29: =IF((AND((AA29>=1),(AC29>=1))),"INCLUSÃO","VERIFICAR") -> INCLUSÃO
A30: D22S1045 | B30: ='DADOS FINAIS'!B30 -> 11 | C30: ='DADOS FINAIS'!C30 -> 16 | D30: ='DADOS FINAIS'!D30 -> 16 | E30: ='DADOS FINAIS'!E30 -> 16 | F30: ='DADOS FINAIS'!F30 -> 16 | G30: ='DADOS FINAIS'!G30 -> 17 | H30: =IF((B30>C30),C30,B30) -> 11 | I30: =IF((C30>B30),C30,B30) -> 16 | J30: =IF((D30>E30),E30,D30) -> 16 | K30: =IF((E30>D30),E30,D30) -> 16 | L30: =IF((F30>G30),G30,F30) -> 16 | M30: =IF((G30>F30),G30,F30) -> 17 | N30: =IF((J30=H30),J30,(IF((J30=I30),J30,0))) -> 16 | O30: =IF((K30=H30),K30,(IF((K30=I30),K30,0))) -> 16 | P30: =(IF(((N30+O30)=(J30+K30)),0,1)) -> 0 | Q30: =IF(OR((N30=O30),(O30=0)),N30,(IF(AND((N30=0),(O30<>0)),O30,$AD$7))) -> 16 | R30: =(IF((Q30<>$AD$7),(J30+K30-Q30),D30)) -> 16 | S30: =(IF((Q30<>$AD$7),0,K30)) -> 0 | T30: =(IF(OR((R30=L30),(R30=M30)),R30,0)) -> 16 | U30: =(IF(AND((P30=0),(OR((M30=N30),(M30=O30)))),S30,(IF((S30<>0),(IF(OR((S30=L30),(S30=M30)),S30,0)),0)))) -> 0 | V30: =IF(R30=0,0,VLOOKUP(R30,FREQUENCIAS!$1:$1048576,(IF(($A30=FREQUENCIAS!$W$1),23,"ERRO")),FREQUENCIAS!$1:$1048576)) -> 0.3287 | W30: =IF(S30=0,0,VLOOKUP(S30,FREQUENCIAS!$1:$1048576,(IF(($A30=FREQUENCIAS!$W$1),23,"ERRO")),FREQUENCIAS!$1:$1048576)) -> 0 | AA30: =((IF((AND(($H30=$J30),($I30=$K30))),2,( IF((OR(($H30=$J30),($I30=$K30),($H30=$K30),($I30=$J30))),1,0))))) -> 1 | AB30: =((IF((AND(($H30=$L30),($I30=$M30))),2,( IF((OR(($H30=$L30),($I30=$M30),($H30=$M30),($I30=$L30))),1,0))))) -> 1 | AC30: =((IF((AND(($J30=$L30),($K30=$M30))),2,( IF((OR(($J30=$L30),($K30=$M30),($J30=$M30),($K30=$L30))),1,0))))) -> 1 | AD30: NIHIL | AE30: =(1-AA30)^2 -> 0 | AG30: =IF((AND((AA30>=1),(AC30>=1))),"INCLUSÃO","VERIFICAR") -> INCLUSÃO
AA31: ÍNDICE DE PATERNIDADE ACUMULADO: | AB31: =(IF(((PRODUCT(AC9:AC30))<>0),PRODUCT(AB9:AB30),$AD$23)) -> 0 | AE31: =(IF(((PRODUCT(AC9:AC30))<>0),((1-AE9)*(1-AE10)*(1-AE11)*(1-AE12)*(1-AE13)*(1-AE14)*(1-AE15)*(1-AE16)*(1-AE17)*(1-AE18)*(1-AE19)*(1-AE20)*(1-AE21)*(1-AE22)*(1-AE23)*(1-AE24)*(1-AE25)*(1-AE26)*(1-AE27)*(1-AE28)*(1-AE29)*(1-AE30)),$AD$23)) -> 0
AA32: PROBABILIDADE DE PATERNIDADE: | AB32: =(IF(((PRODUCT(AC9:AC30))<>0),(ROUNDDOWN((AB31/(AB31+1)),11)),$AD$23)) -> 0
AA33: HIPÓTESE TROCA ALELOS M e SP: | AB33: =(IF(((PRODUCT(AC9:AC30))<>0),(ROUNDDOWN((1-$AE31),11)),$AD$13)) -> 1
G34: COMPARTILHAMENTOS: | M34: SOMATÓRIOS: | AA34: =SUM(AA9:AA30) -> 25 | AB34: =SUM(AB9:AB30) -> 11 | AC34: =SUM(AC9:AC30) -> 27 | AG34: =IF((AND((AA34<=40),(AB34<=40),(AC34<=40))),"OK","VERIFICAR") -> OK | AH34: =SUM(AH9:AH23) -> 0
B36: PROTOCOLO DA SUPERVISÃO 4
C37: A PRESENTE SUPERVISÃO DESTINA-SE A VERIFICAR SE HOUVE REPETI-
B38: ÇÃO NOS ALELOS DE DUAS DAS PESSOAS ANALISADAS. O NÚMERO DE COM-
B39: PARTILHAMENTO IGUAL A 30 CONFIRMA A HIPÓTESE. 28 ou 29 COMPARTILHA-
B40: MENTOS INDICA A NECESSIDADE DE VERIFICAÇÃO. OCORRENDO 28, 29 ou 30:
C41: a) não expedir o Laudo;
...

Sheet SUPERVISÃO 3
A1: IPC MS EXAMES DE DNA - DIVISÃO DE GENÉTICA MOLECULAR
AN2: Sistema automatizado de cálculo de Genética de Populações desenvolvido pelo Engº e Biólogo Helder Pereira de Figueiredo
A3: CÓDIGO: | AH3: AMELOGENINA | AM3: SUPERV
A4: MÃE: | AI4: =(IF(('IMPORTAÇÃO GENOTIPER'!W4="X"),"XX",(IF(('IMPORTAÇÃO GENOTIPER'!W4<>"X"),"ERRO")))) -> XX | AM4: =IF(('SUPERVISÃO 1'!$AB$34="EVIDÊNCIA DE TROCA"),"VERIFICAR","OK") -> OK
A5: INVTE: | AI5: =(IF(('IMPORTAÇÃO GENOTIPER'!AM4="Y"),"XY",(IF(('IMPORTAÇÃO GENOTIPER'!AM4="X"),"XX","ERRO")))) -> XY | AM5: =IF(('SUPERVISÃO 2'!$AB$34="EVIDÊNCIA DE TROCA"),"VERIFICAR","OK") -> OK
A6: SP. PAI: | AI6: =(IF(('IMPORTAÇÃO GENOTIPER'!BC4="Y"),"XY",(IF(('IMPORTAÇÃO GENOTIPER'!BC4<>"Y"),"ERRO")))) -> XY | AJ6: EXCLUI | AM6: =IF(('SUPERVISÃO 3'!$AB$34="TROCA POSSÍVEL"),"VERIFICAR","OK") -> OK | AZ6: TAXA FIXA: | BB6: 0.001
A7: =IF(($BD$31=1)," DETECTADA 1 MUTAÇÃO MATERNA",IF(($BD$31=2)," DETECTADAS 2 MUTAÇÕES MATERNAS",IF(($BD$31>=3)," DETECTADA EXCLUSÃO DE MÃE"," MATERNIDADE CONFIRMADA"))) -> MATERNIDADE CONFIRMADA | AB7: aqui colocar coluna = num. Corresp. | AH7: FREQ. MÍN.: | AI7: 0.02 | AJ7: NÃO DEF | AM7: =IF(('SUPERVISÃO 4'!$AG$34="VERIFICAR"),"VERIFICAR","OK") -> OK | AQ7: AQUI NÃO USOU POIS NÃO TEM O LIMITE DOS MARCADORES | AZ7: MUTAÇÃO VARIÁVEL | BI7: AL. MAT. ORIGINÁRIOS | BL7: AL. 1 SP. ORIGINÁRIOS | BO7: AL. 2 SP. ORIGINÁRIOS
A8: REGIÃO | B8: MÃE - HIP | D8: CRIANÇA | F8: SP - HIP | H8: MÃE 'A' | J8: CRIA 'A' | L8: SP 'A' | N8: M CALC | P8: C CALC | R8: SP CALC | T8: AM1 | U8: AM2 | V8: AM3 | W8: AL. MAT | X8: AL. PAT. | Z8: COMP. | AB8: Fr 1A | AC8: Fr 2A | AD8: Fr 1B | AE8: Fr 2B | AF8: Fr Sp | AG8: =((IF((OR(($A9="ERRO-FT"),($A10="ERRO-FT"),($A11="ERRO-FT"),($A12="ERRO-FT"),($A13="ERRO-FT"),($A14="ERRO-FT"),($A15="ERRO-FT"),($A16="ERRO-FT"),($A17="ERRO-FT"),($A18="ERRO-FT"),($A19="ERRO-FT"),($A20="ERRO-FT"),($A21="ERRO-FT"),($A22="ERRO-FT"),($A23="ERRO-FT"))),"AL.INF.","FREQ."))) -> FREQ. | AH8: =((IF((OR(($A9="ERRO-FT"),($A10="ERRO-FT"),($A11="ERRO-FT"),($A12="ERRO-FT"),($A13="ERRO-FT"),($A14="ERRO-FT"),($A15="ERRO-FT"),($A16="ERRO-FT"),($A17="ERRO-FT"),($A18="ERRO-FT"),($A19="ERRO-FT"),($A20="ERRO-FT"),($A21="ERRO-FT"),($A22="ERRO-FT"),($A23="ERRO-FT"))),"AL.SUP.","PI"))) -> PI | AI8: PR. PAT | AJ8: SIM | AM8: FÓRM | AN8: AM | AX8: MT | AY8: TX. MUTAÇÃO | AZ8: LOCUS | BA8: PE | BB8: MUT | BC8: OMISSÃO | BD8: EXCL. MÃE | BF8: L. INF | BG8: L. SUP | BI8: < / > | BJ8: AL.MAT. | BK8: MT.ORIG | BL8: < / > | BM8: AL.PT.1 | BN8: AL1-OR | BO8: < / > | BP8: AL.PT.2 | BQ8: AL2-OR
A9: D3S1358 | B9: ='DADOS FINAIS'!F9 -> 14 | C9: ='DADOS FINAIS'!G9 -> 15 | D9: ='DADOS FINAIS'!D9 -> 15 | E9: ='DADOS FINAIS'!E9 -> 18 | F9: ='DADOS FINAIS'!B9 -> 16 | G9: ='DADOS FINAIS'!C9 -> 18 | H9: =(IF(CODE(B9)=(60),($BF9-1),(IF(CODE(B9)=(62),($BG9+1),B9)))) -> 14 | I9: =(IF(CODE(C9)=(60),($BF9-1),(IF(CODE(C9)=(62),($BG9+1),C9)))) -> 15 | J9: =(IF(CODE(D9)=(60),($BF9-1),(IF(CODE(D9)=(62),($BG9+1),D9)))) -> 15 | K9: =(IF(CODE(E9)=(60),($BF9-1),(IF(CODE(E9)=(62),($BG9+1),E9)))) -> 18 | L9: =(IF(CODE(F9)=(60),($BF9-1),(IF(CODE(F9)=(62),($BG9+1),F9)))) -> 16 | M9: =(IF(CODE(G9)=(60),($BF9-1),(IF(CODE(G9)=(62),($BG9+1),G9)))) -> 18 | N9: =IF((H9>I9),I9,H9) -> 14 | O9: =IF((I9>H9),I9,H9) -> 15 | P9: =IF((J9>K9),K9,J9) -> 15 | Q9: =IF((K9>J9),K9,J9) -> 18 | R9: =IF((L9>M9),M9,L9) -> 16 | S9: =IF((M9>L9),M9,L9) -> 18 | T9: =IF((P9=N9),P9,(IF((P9=O9),P9,0))) -> 15 | U9: =IF((Q9=N9),Q9,(IF((Q9=O9),Q9,0))) -> 0 | V9: =(IF((OR((P9=">18"),(Q9=">18"))),2,(IF(((T9+U9)=(P9+Q9)),0,1)))) -> 1 | W9: =IF(OR(($T9=$U9),($U9=0)),$T9,(IF(AND(($T9=0),($U9<>0)),$U9,$AJ$7))) -> 15 | X9: =(ROUND( (IF((AND((T9=0),(U9=0))),D9,(IF((V9=2),S9,(IF((W9<>$AJ$7),(P9+Q9-W9),P9)))))),1)) -> 18 | Y9: =(IF((AND(($T9=0),($U9=0))),$E9,(IF(($W9<>$AJ$7),0,$Q9)))) -> 0 | Z9: =(IF(OR((X9=R9),(X9=S9)),X9,0)) -> 18 | AA9: =(IF(AND((V9=0),(Z9=0),(OR((S9=T9),(S9=U9)))),Y9,(IF((Y9<>0),(IF(OR((Y9=R9),(Y9=S9)),Y9,0)),0)))) -> 0 | AB9: =IF(X9=0,0,VLOOKUP(X9,FREQUENCIAS!$1:$1048576,(IF(($A9=FREQUENCIAS!$B$1),2,"ERRO")),FREQUENCIAS!$1:$1048576)) -> 0.123926 | AC9: =IF(Y9=0,0,VLOOKUP(Y9,FREQUENCIAS!$1:$1048576,(IF(($A9=FREQUENCIAS!$B$1),2,"ERRO")),FREQUENCIAS!$1:$1048576)) -> 0 | AG9: =(IF((A9="ERRO-FT"),"8",((IF((AND(($Z9=0),($AA9=0),($AX$32="N"))),0,(IF((AND(($Z9=0),($AA9=0),(AX$32="S"))),1,(IF((AB9+AC9+AD9+AE9+AF9)<=$AI$7,$AI$7,(AB9+AC9+AD9+AE9+AF9)))))))))) -> 0.123926 | AH9: =(IF((A9="ERRO-FT"),"19",(IF((AND(($Z9=0),($AA9=0),($AX$32="N"))),0,(IF((AND(($Z9=0),($AA9=0),(AX$32="S"))),$AY9,(IF(OR((AND(($B9=$C9),($C9=$D9),($D9=$E9),($E9=$F9),($F9=$G9))), ((AND(($N9=$P9),($P9=$R9),($O9=$Q9),($Q9=$S9),($N9<>$O9)))),(AND(($D9=$E9),($B9<>$C9),($E9=$F9),($F9=$G9))),((AND(($X9=$Z9),($F9=$G9))))),(1/$AG9),(1/(2*$AG9)))))))))) -> 4.0346658 | AI9: =(IF((AH9=0),0,(AH9/(AH9+1)))) -> 0.80137709 | AK9: =(1-AG9)^2 -> 0.76750565 | AM9: =IF((AND(($Z9=0),($AA9=0),($AX$32="N"))),"EXCLUI",(IF((AND(($Z9=0),($AA9=0),(AX$32="S"))),"MUTAÇÃO",(IF(OR((AND((B9=C9),(C9=D9),(D9=E9),(E9=F9),(F9=G9))),((AND((N9=P9),(P9=R9),(O9=Q9),(Q9=S9),(N9<>O9)))),(AND((D9=E9),(B9<>C9),(E9=F9),(F9=G9))),((AND((X9=Z9),(F9=G9))))),("1 / F"),("1 / 2F")))))) -> 1 / 2F | AN9: =(IF((AND(($BD$31<=2),(BD9=1))),"MT",(IF((AND(($BD$31>2),(BD9=1))),"EM","OK")))) -> OK | AQ9: =(IF(OR((B9="<8"),(B9=">19"),(B9=19),(B9=#REF!),(B9=#REF!),(B9=#REF!),(B9=#REF!),(B9=#REF!),(B9=#REF!),(B9=#REF!),(B9=#REF!),(B9=#REF!),(B9=#REF!),(B9=#REF!)),1,0)) -> #REF! | AR9: =(IF(OR((C9="<8"),(C9=">19"),(C9=19),(C9=#REF!),(C9=#REF!),(C9=#REF!),(C9=#REF!),(C9=#REF!),(C9=#REF!),(C9=#REF!),(C9=#REF!),(C9=#REF!),(C9=#REF!),(C9=#REF!)),1,0)) -> #REF! | AS9: =(IF(OR((D9="<8"),(D9=">19"),(D9=19),(D9=#REF!),(D9=#REF!),(D9=#REF!),(D9=#REF!),(D9=#REF!),(D9=#REF!),(D9=#REF!),(D9=#REF!),(D9=#REF!),(D9=#REF!),(D9=#REF!)),1,0)) -> #REF! | AT9: =(IF(OR((E9="<8"),(E9=">19"),(E9=19),(E9=#REF!),(E9=#REF!),(E9=#REF!),(E9=#REF!),(E9=#REF!),(E9=#REF!),(E9=#REF!),(E9=#REF!),(E9=#REF!),(E9=#REF!),(E9=#REF!)),1,0)) -> #REF! | AU9: =(IF(OR((F9="<8"),(F9=">19"),(F9=19),(F9=#REF!),(F9=#REF!),(F9=#REF!),(F9=#REF!),(F9=#REF!),(F9=#REF!),(F9=#REF!),(F9=#REF!),(F9=#REF!),(F9=#REF!),(F9=#REF!)),1,0)) -> #REF! | AV9: =(IF(OR((G9="<8"),(G9=">19"),(G9=19),(G9=#REF!),(G9=#REF!),(G9=#REF!),(G9=#REF!),(G9=#REF!),(G9=#REF!),(G9=#REF!),(G9=#REF!),(G9=#REF!),(G9=#REF!),(G9=#REF!)),1,0)) -> #REF! | AX9: =IF(($AG9=0),1,0) -> 0 | AY9: =(IF((AND(($AX$32="S"),($AX$33="F"))),$BB$6,(IF((AND(($AX$32="S"),($AX$33="V"))),(BB9/(BA9)),0)))) -> 0 | BA9: =IF($A9=FREQUENCIAS!$B$1,FREQUENCIAS!$B$2,"ERRO NO PE") -> 0.549 | BB9: =IF($A9=FREQUENCIAS!$B$1,FREQUENCIAS!$B$3,"ERRO NA MUT") -> 0.0012 | BC9: =(IF((AND(($AX$32="N"),($AX$34="O"),($AX9=1))),1,$AH9)) -> 4.0346658 | BD9: =IF((W9=0),1,0) -> 0 | BF9: 8 | BG9: 19 | BH9: =(IF((AND((B9>=$BF9),(B9<=$BG9),(C9>=$BF9),(C9<=$BG9),(D9>=$BF9),(D9<=$BG9),(E9>=$BF9),(E9<=$BG9),(F9>=$BF9),(F9<=$BG9),(G9>=$BF9),(G9<=$BG9))),"CORRETO",(IF((OR((B9="<8"),(C9="<8"),(D9="<8"),(E9="<8"),(F9="<8"),(G9="<8"),(B9=">19"),(C9=">19"),(D9=">19"),(E9=">19"),(F9=">19"),(G9=">19"))),"CORRETO","ALELO ERRADO")))) -> CORRETO | BI9: =IF(($W9=($BF9-1)),"<",IF(($W9=($BG9+1)),">","")) | BJ9: =IF(($W9=($BF9-1)),$BF9,IF(($W9=($BG9-1)),$BG9,$W9)) -> 15 | BK9: =(IF((OR(($W9=($BF9-1)),($W9=($BG9+1)))),(CONCATENATE((BI9),(BJ9))),$W9)) -> 15 | BL9: =IF(($Z9=($BF9-1)),"<",IF(($Z9=($BG9+1)),">","")) | BM9: =IF(($Z9=($BF9-1)),$BF9,IF(($Z9=($BG9+1)),$BG9,$Z9)) -> 18 | BN9: =(IF((OR(($Z9=($BF9-1)),($Z9=($BG9+1)))),(CONCATENATE((BL9),(BM9))),$Z9)) -> 18 | BO9: =IF(($AA9=($BF9-1)),"<",IF(($AA9=($BG9+1)),">","")) | BP9: =IF((AA9=($BF9-1)),BG9,IF((AA9=($BG9+1)),$BG9,AA9)) -> 0 | BQ9: =(IF((OR(($AA9=($BF9-1)),($AA9=($BG9+1)))),(CONCATENATE((BO9),(BP9))),$AA9)) -> 0 | BT9: 9 | BU9: <8
A10: D1S1656 | B10: ='DADOS FINAIS'!F10 -> 13 | C10: ='DADOS FINAIS'!G10 -> 19.3 | D10: ='DADOS FINAIS'!D10 -> 16.3 | E10: ='DADOS FINAIS'!E10 -> 19.3 | F10: ='DADOS FINAIS'!B10 -> 15 | G10: ='DADOS FINAIS'!C10 -> 16.3 | H10: =(IF(CODE(B10)=(60),($BF10-1),(IF(CODE(B10)=(62),($BG10+1),B10)))) -> 13 | I10: =(IF(CODE(C10)=(60),($BF10-1),(IF(CODE(C10)=(62),($BG10+1),C10)))) -> 19.3 | J10: =(IF(CODE(D10)=(60),($BF10-1),(IF(CODE(D10)=(62),($BG10+1),D10)))) -> 16.3 | K10: =(IF(CODE(E10)=(60),($BF10-1),(IF(CODE(E10)=(62),($BG10+1),E10)))) -> 19.3 | L10: =(IF(CODE(F10)=(60),($BF10-1),(IF(CODE(F10)=(62),($BG10+1),F10)))) -> 15 | M10: =(IF(CODE(G10)=(60),($BF10-1),(IF(CODE(G10)=(62),($BG10+1),G10)))) -> 16.3 | N10: =IF((H10>I10),I10,H10) -> 13 | O10: =IF((I10>H10),I10,H10) -> 19.3 | P10: =IF((J10>K10),K10,J10) -> 16.3 | Q10: =IF((K10>J10),K10,J10) -> 19.3 | R10: =IF((L10>M10),M10,L10) -> 15 | S10: =IF((M10>L10),M10,L10) -> 16.3 | T10: =IF((P10=N10),P10,(IF((P10=O10),P10,0))) -> 0 | U10: =IF((Q10=N10),Q10,(IF((Q10=O10),Q10,0))) -> 19.3 | V10: =(IF((OR((P10=">36"),(Q10=">36"))),2,(IF(((T10+U10)=(P10+Q10)),0,1)))) -> 1 | W10: =IF(OR((T10=U10),(U10=0)),T10,(IF(AND((T10=0),(U10<>0)),U10,$AJ$7))) -> 19.3 | X10: =(ROUND( (IF((AND((T10=0),(U10=0))),D10,(IF((V10=2),S10,(IF((W10<>$AJ$7),(P10+Q10-W10),P10)))))),1)) -> 16.3 | Y10: =(IF((AND((T10=0),(U10=0))),E10,(IF((W10<>$AJ$7),0,Q10)))) -> 0 | Z10: =(IF(OR((X10=R10),(X10=S10)),X10,0)) -> 16.3 | AA10: =(IF(AND((V10=0),(Z10=0),(OR((S10=T10),(S10=U10)))),Y10,(IF((Y10<>0),(IF(OR((Y10=R10),(Y10=S10)),Y10,0)),0)))) -> 0 | AB10: =IF(X10=0,0,VLOOKUP(X10,FREQUENCIAS!$1:$1048576,(IF(($A10=FREQUENCIAS!$C$1),3,"ERRO")),FREQUENCIAS!$1:$1048576)) -> 0.0505 | AC10: =IF(Y10=0,0,VLOOKUP(Y10,FREQUENCIAS!$1:$1048576,(IF(($A10=FREQUENCIAS!$C$1),3,"ERRO")),FREQUENCIAS!$1:$1048576)) -> 0 | AG10: =(IF((A10="ERRO-FT"),"24",((IF((AND(($Z10=0),($AA10=0),($AX$32="N"))),0,(IF((AND(($Z10=0),($AA10=0),(AX$32="S"))),1,(IF((AB10+AC10+AD10+AE10+AF10)<=$AI$7,$AI$7,(AB10+AC10+AD10+AE10+AF10)))))))))) -> 0.0505 | AH10: =(IF((A10="ERRO-FT"),"38",(IF((AND(($Z10=0),($AA10=0),($AX$32="N"))),0,(IF((AND(($Z10=0),($AA10=0),(AX$32="S"))),$AY10,(IF(OR((AND(($B10=$C10),($C10=$D10),($D10=$E10),($E10=$F10),($F10=$G10))), ((AND(($N10=$P10),($P10=$R10),($O10=$Q10),($Q10=$S10),($N10<>$O10)))),(AND(($D10=$E10),($B10<>$C10),($E10=$F10),($F10=$G10))),((AND(($X10=$Z10),($F10=$G10))))),(1/$AG10),(1/(2*$AG10)))))))))) -> 9.9009901 | AI10: =(IF((AH10=0),0,(AH10/(AH10+1)))) -> 0.90826521 | AK10: =(1-AG10)^2 -> 0.90155025 | AM10: =IF((AND(($Z10=0),($AA10=0),($AX$32="N"))),"EXCLUI",(IF((AND(($Z10=0),($AA10=0),(AX$32="S"))),"MUTAÇÃO",(IF(OR((AND((B10=C10),(C10=D10),(D10=E10),(E10=F10),(F10=G10))),((AND((N10=P10),(P10=R10),(O10=Q10),(Q10=S10),(N10<>O10)))),(AND((D10=E10),(B10<>C10),(E10=F10),(F10=G10))),((AND((X10=Z10),(F10=G10))))),("1 / F"),("1 / 2F")))))) -> 1 / 2F | AN10: =(IF((AND(($BD$31<=2),(BD10=1))),"MT",(IF((AND(($BD$31>2),(BD10=1))),"EM","OK")))) -> OK | AQ10: =(IF(OR((B10="<24"),(B10=">38"),(B10=24),(B10=24.3),(B10=25.2),(B10=28.2),(B10=29.3),(B10=34.1),(B10=35.1),(B10=37),(B10=38),(B10=#REF!),(B10=#REF!),(B10=#REF!),(B10=#REF!),(B10=#REF!),(B10=#REF!),(B10=#REF!),(B10=#REF!),(B10=#REF!),(B10=#REF!),(B10=#REF!),(B10=#REF!),(B10=#REF!),(B10=#REF!),(B10=#REF!),(B10=#REF!),(B10=#REF!),(B10=#REF!),(B10=#REF!)),1,BW10)) -> #REF! | AR10: =(IF(OR((C10="<24"),(C10=">38"),(C10=24),(C10=24.3),(C10=25.2),(C10=28.2),(C10=29.3),(C10=34.1),(C10=35.1),(C10=37),(C10=38),(C10=#REF!),(C10=#REF!),(C10=#REF!),(C10=#REF!),(C10=#REF!),(C10=#REF!),(C10=#REF!),(C10=#REF!),(C10=#REF!),(C10=#REF!),(C10=#REF!),(C10=#REF!),(C10=#REF!),(C10=#REF!),(C10=#REF!),(C10=#REF!),(C10=#REF!),(C10=#REF!),(C10=#REF!)),1,BX10)) -> #REF! | AS10: =(IF(OR((D10="<24"),(D10=">38"),(D10=24),(D10=24.3),(D10=25.2),(D10=28.2),(D10=29.3),(D10=34.1),(D10=35.1),(D10=37),(D10=38),(D10=#REF!),(D10=#REF!),(D10=#REF!),(D10=#REF!),(D10=#REF!),(D10=#REF!),(D10=#REF!),(D10=#REF!),(D10=#REF!),(D10=#REF!),(D10=#REF!),(D10=#REF!),(D10=#REF!),(D10=#REF!),(D10=#REF!),(D10=#REF!),(D10=#REF!),(D10=#REF!),(D10=#REF!)),1,BY10)) -> #REF! | AT10: =(IF(OR((E10="<24"),(E10=">38"),(E10=24),(E10=24.3),(E10=25.2),(E10=28.2),(E10=29.3),(E10=34.1),(E10=35.1),(E10=37),(E10=38),(E10=#REF!),(E10=#REF!),(E10=#REF!),(E10=#REF!),(E10=#REF!),(E10=#REF!),(E10=#REF!),(E10=#REF!),(E10=#REF!),(E10=#REF!),(E10=#REF!),(E10=#REF!),(E10=#REF!),(E10=#REF!),(E10=#REF!),(E10=#REF!),(E10=#REF!),(E10=#REF!),(E10=#REF!)),1,BZ10)) -> #REF! | AU10: =(IF(OR((F10="<24"),(F10=">38"),(F10=24),(F10=24.3),(F10=25.2),(F10=28.2),(F10=29.3),(F10=34.1),(F10=35.1),(F10=37),(F10=38),(F10=#REF!),(F10=#REF!),(F10=#REF!),(F10=#REF!),(F10=#REF!),(F10=#REF!),(F10=#REF!),(F10=#REF!),(F10=#REF!),(F10=#REF!),(F10=#REF!),(F10=#REF!),(F10=#REF!),(F10=#REF!),(F10=#REF!),(F10=#REF!),(F10=#REF!),(F10=#REF!),(F10=#REF!)),1,CA10)) -> #REF! | AV10: =(IF(OR((G10="<24"),(G10=">38"),(G10=24),(G10=24.3),(G10=25.2),(G10=28.2),(G10=29.3),(G10=34.1),(G10=35.1),(G10=37),(G10=38),(G10=#REF!),(G10=#REF!),(G10=#REF!),(G10=#REF!),(G10=#REF!),(G10=#REF!),(G10=#REF!),(G10=#REF!),(G10=#REF!),(G10=#REF!),(G10=#REF!),(G10=#REF!),(G10=#REF!),(G10=#REF!),(G10=#REF!),(G10=#REF!),(G10=#REF!),(G10=#REF!),(G10=#REF!)),1,CB10)) -> #REF! | AW10: APOIO (BW-CB) | AX10: =IF(($AG10=0),1,0) -> 0 | AY10: =(IF((AND(($AX$32="S"),($AX$33="F"))),$BB$6,(IF((AND(($AX$32="S"),($AX$33="V"))),(BB10/(BA10)),0)))) -> 0 | BA10: =IF($A10=FREQUENCIAS!$C$1,FREQUENCIAS!$C$2,"ERRO NO PE") -> 0.759 | BB10: =IF($A10=FREQUENCIAS!$C$1,FREQUENCIAS!$C$3,"ERRO NA MUT") -> 0 | BC10: =(IF((AND(($AX$32="N"),($AX$34="O"),($AX10=1))),1,$AH10)) -> 9.9009901 | BD10: =IF((W10=0),1,0) -> 0 | BF10: 24 | BG10: 38 | BH10: =(IF((AND((B10>=$BF10),(B10<=$BG10),(C10>=$BF10),(C10<=$BG10),(D10>=$BF10),(D10<=$BG10),(E10>=$BF10),(E10<=$BG10),(F10>=$BF10),(F10<=$BG10),(G10>=$BF10),(G10<=$BG10))),"CORRETO",(IF((OR((B10="<24"),(C10="<24"),(D10="<24"),(E10="<24"),(F10="<24"),(G10="<24"),(B10=">38"),(C10=">38"),(D10=">38"),(E10=">38"),(F10=">38"),(G10=">38"))),"CORRETO","ALELO ERRADO")))) -> ALELO ERRADO | BI10: =IF(($W10=($BF10-1)),"<",IF(($W10=($BG10+1)),">","")) | BJ10: =IF(($W10=($BF10-1)),$BF10,IF(($W10=($BG10-1)),$BG10,$W10)) -> 19.3 | BK10: =(IF((OR(($W10=($BF10-1)),($W10=($BG10+1)))),(CONCATENATE((BI10),(BJ10))),$W10)) -> 19.3 | BL10: =IF(($Z10=($BF10-1)),"<",IF(($Z10=($BG10+1)),">","")) | BM10: =IF(($Z10=($BF10-1)),$BF10,IF(($Z10=($BG10+1)),$BG10,$Z10)) -> 16.3 | BN10: =(IF((OR(($Z10=($BF10-1)),($Z10=($BG10+1)))),(CONCATENATE((BL10),(BM10))),$Z10)) -> 16.3 | BO10: =IF(($AA10=($BF10-1)),"<",IF(($AA10=($BG10+1)),">","")) | BP10: =IF((AA10=($BF10-1)),BG10,IF((AA10=($BG10+1)),$BG10,AA10)) -> 0 | BQ10: =(IF((OR(($AA10=($BF10-1)),($AA10=($BG10+1)))),(CONCATENATE((BO10),(BP10))),$AA10)) -> 0 | BT10: 24 | BU10: 30 | BW10: =(IF((B10=35.2),1,0)) -> 0 | BX10: =(IF((C10=35.2),1,0)) -> 0 | BY10: =(IF((D10=35.2),1,0)) -> 0 | BZ10: =(IF((E10=35.2),1,0)) -> 0 | CA10: =(IF((F10=35.2),1,0)) -> 0 | CB10: =(IF((G10=35.2),1,0)) -> 0
A11: D2S441 | B11: ='DADOS FINAIS'!F11 -> 10 | C11: ='DADOS FINAIS'!G11 -> 11 | D11: ='DADOS FINAIS'!D11 -> 10 | E11: ='DADOS FINAIS'!E11 -> 12 | F11: ='DADOS FINAIS'!B11 -> 10 | G11: ='DADOS FINAIS'!C11 -> 12 | H11: =(IF(CODE(B11)=(60),($BF11-1),(IF(CODE(B11)=(62),($BG11+1),B11)))) -> 10 | I11: =(IF(CODE(C11)=(60),($BF11-1),(IF(CODE(C11)=(62),($BG11+1),C11)))) -> 11 | J11: =(IF(CODE(D11)=(60),($BF11-1),(IF(CODE(D11)=(62),($BG11+1),D11)))) -> 10 | K11: =(IF(CODE(E11)=(60),($BF11-1),(IF(CODE(E11)=(62),($BG11+1),E11)))) -> 12 | L11: =(IF(CODE(F11)=(60),($BF11-1),(IF(CODE(F11)=(62),($BG11+1),F11)))) -> 10 | M11: =(IF(CODE(G11)=(60),($BF11-1),(IF(CODE(G11)=(62),($BG11+1),G11)))) -> 12 | N11: =IF((H11>I11),I11,H11) -> 10 | O11: =IF((I11>H11),I11,H11) -> 11 | P11: =IF((J11>K11),K11,J11) -> 10 | Q11: =IF((K11>J11),K11,J11) -> 12 | R11: =IF((L11>M11),M11,L11) -> 10 | S11: =IF((M11>L11),M11,L11) -> 12 | T11: =IF((P11=N11),P11,(IF((P11=O11),P11,0))) -> 10 | U11: =IF((Q11=N11),Q11,(IF((Q11=O11),Q11,0))) -> 0 | V11: =(IF((OR((P11=">22"),(Q11=">22"))),2,(IF(((T11+U11)=(P11+Q11)),0,1)))) -> 1 | W11: =IF(OR((T11=U11),(U11=0)),T11,(IF(AND((T11=0),(U11<>0)),U11,$AJ$7))) -> 10 | X11: =(ROUND( (IF((AND((T11=0),(U11=0))),D11,(IF((V11=2),S11,(IF((W11<>$AJ$7),(P11+Q11-W11),P11)))))),1)) -> 12 | Y11: =(ROUND( (IF((AND((T11=0),(U11=0))),E11,(IF((W11<>$AJ$7),0,Q11)))),1)) -> 0 | Z11: =(IF(OR((X11=R11),(X11=S11)),X11,0)) -> 12 | AA11: =(IF(AND((V11=0),(Z11=0),(OR((S11=T11),(S11=U11)))),Y11,(IF((Y11<>0),(IF(OR((Y11=R11),(Y11=S11)),Y11,0)),0)))) -> 0 | AB11: =IF(X11=0,0,VLOOKUP(X11,FREQUENCIAS!$1:$1048576,(IF(($A11=FREQUENCIAS!$D$1),4,"ERRO")),FREQUENCIAS!$1:$1048576)) -> 0.0731 | AC11: =IF(Y11=0,0,VLOOKUP(Y11,FREQUENCIAS!$1:$1048576,(IF(($A11=FREQUENCIAS!$D$1),4,"ERRO")),FREQUENCIAS!$1:$1048576)) -> 0 | AG11: =(IF((A11="ERRO-FT"),"6",((IF((AND(($Z11=0),($AA11=0),($AX$32="N"))),0,(IF((AND(($Z11=0),($AA11=0),(AX$32="S"))),1,(IF((AB11+AC11+AD11+AE11+AF11)<=$AI$7,$AI$7,(AB11+AC11+AD11+AE11+AF11)))))))))) -> 0.0731 | AH11: =(IF((A11="ERRO-FT"),"15",(IF((AND(($Z11=0),($AA11=0),($AX$32="N"))),0,(IF((AND(($Z11=0),($AA11=0),(AX$32="S"))),$AY11,(IF(OR((AND(($B11=$C11),($C11=$D11),($D11=$E11),($E11=$F11),($F11=$G11))), ((AND(($N11=$P11),($P11=$R11),($O11=$Q11),($Q11=$S11),($N11<>$O11)))),(AND(($D11=$E11),($B11<>$C11),($E11=$F11),($F11=$G11))),((AND(($X11=$Z11),($F11=$G11))))),(1/$AG11),(1/(2*$AG11)))))))))) -> 6.8399453 | AI11: =(IF((AH11=0),0,(AH11/(AH11+1)))) -> 0.87244809 | AK11: =(1-AG11)^2 -> 0.85914361 | AM11: =IF((AND(($Z11=0),($AA11=0),($AX$32="N"))),"EXCLUI",(IF((AND(($Z11=0),($AA11=0),(AX$32="S"))),"MUTAÇÃO",(IF(OR((AND((B11=C11),(C11=D11),(D11=E11),(E11=F11),(F11=G11))),((AND((N11=P11),(P11=R11),(O11=Q11),(Q11=S11),(N11<>O11)))),(AND((D11=E11),(B11<>C11),(E11=F11),(F11=G11))),((AND((X11=Z11),(F11=G11))))),("1 / F"),("1 / 2F")))))) -> 1 / 2F | AN11: =(IF((AND(($BD$31<=2),(BD11=1))),"MT",(IF((AND(($BD$31>2),(BD11=1))),"EM","OK")))) -> OK | AQ11: =(IF(OR((B11="<6"),(B11=">15"),(B11=6),(B11=15),(B11=#REF!),(B11=#REF!),(B11=#REF!),(B11=#REF!),(B11=#REF!),(B11=#REF!),(B11=#REF!),(B11=#REF!)),1,0)) -> #REF! | AR11: =(IF(OR((C11="<6"),(C11=">15"),(C11=6),(C11=15),(C11=#REF!),(C11=#REF!),(C11=#REF!),(C11=#REF!),(C11=#REF!),(C11=#REF!),(C11=#REF!),(C11=#REF!)),1,0)) -> #REF! | AS11: =(IF(OR((D11="<6"),(D11=">15"),(D11=6),(D11=15),(D11=#REF!),(D11=#REF!),(D11=#REF!),(D11=#REF!),(D11=#REF!),(D11=#REF!),(D11=#REF!),(D11=#REF!)),1,0)) -> #REF! | AT11: =(IF(OR((E11="<6"),(E11=">15"),(E11=6),(E11=15),(E11=#REF!),(E11=#REF!),(E11=#REF!),(E11=#REF!),(E11=#REF!),(E11=#REF!),(E11=#REF!),(E11=#REF!)),1,0)) -> #REF! | AU11: =(IF(OR((F11="<6"),(F11=">15"),(F11=6),(F11=15),(F11=#REF!),(F11=#REF!),(F11=#REF!),(F11=#REF!),(F11=#REF!),(F11=#REF!),(F11=#REF!),(F11=#REF!)),1,0)) -> #REF! | AV11: =(IF(OR((G11="<6"),(G11=">15"),(G11=6),(G11=15),(G11=#REF!),(G11=#REF!),(G11=#REF!),(G11=#REF!),(G11=#REF!),(G11=#REF!),(G11=#REF!),(G11=#REF!)),1,0)) -> #REF! | AX11: =IF(($AG11=0),1,0) -> 0 | AY11: =(IF((AND(($AX$32="S"),($AX$33="F"))),$BB$6,(IF((AND(($AX$32="S"),($AX$33="V"))),(BB11/(BA11)),0)))) -> 0 | BA11: =IF($A11=FREQUENCIAS!$D$1,FREQUENCIAS!$D$2,"ERRO NO PE") -> 0.513 | BB11: =IF($A11=FREQUENCIAS!$D$1,FREQUENCIAS!$D$3,"ERRO NA MUT") -> 0 | BC11: =(IF((AND(($AX$32="N"),($AX$34="O"),($AX11=1))),1,$AH11)) -> 6.8399453 | BD11: =IF((W11=0),1,0) -> 0 | BF11: 6 | BG11: 15 | BH11: =(IF((AND((B11>=$BF11),(B11<=$BG11),(C11>=$BF11),(C11<=$BG11),(D11>=$BF11),(D11<=$BG11),(E11>=$BF11),(E11<=$BG11),(F11>=$BF11),(F11<=$BG11),(G11>=$BF11),(G11<=$BG11))),"CORRETO",(IF((OR((B11="<6"),(C11="<6"),(D11="<6"),(E11="<6"),(F11="<6"),(G11="<6"),(B11=">15"),(C11=">15"),(D11=">15"),(E11=">15"),(F11=">15"),(G11=">15"))),"CORRETO","ALELO ERRADO")))) -> CORRETO | BI11: =IF(($W11=($BF11-1)),"<",IF(($W11=($BG11+1)),">","")) | BJ11: =IF(($W11=($BF11-1)),$BF11,IF(($W11=($BG11-1)),$BG11,$W11)) -> 10 | BK11: =(IF((OR(($W11=($BF11-1)),($W11=($BG11+1)))),(CONCATENATE((BI11),(BJ11))),$W11)) -> 10 | BL11: =IF(($Z11=($BF11-1)),"<",IF(($Z11=($BG11+1)),">","")) | BM11: =IF(($Z11=($BF11-1)),$BF11,IF(($Z11=($BG11+1)),$BG11,$Z11)) -> 12 | BN11: =(IF((OR(($Z11=($BF11-1)),($Z11=($BG11+1)))),(CONCATENATE((BL11),(BM11))),$Z11)) -> 12 | BO11: =IF(($AA11=($BF11-1)),"<",IF(($AA11=($BG11+1)),">","")) | BP11: =IF((AA11=($BF11-1)),BG11,IF((AA11=($BG11+1)),$BG11,AA11)) -> 0 | BQ11: =(IF((OR(($AA11=($BF11-1)),($AA11=($BG11+1)))),(CONCATENATE((BO11),(BP11))),$AA11)) -> 0 | BT11: 10 | BU11: 10
