Workbook

Sheet IPCMS
A1: IPCMS - Instituto de Perícias Científicas | J1: PLACA
C3: Extração Caixa | F3: PCR | J3: Observação
C4: Extração Perito
C5: Extração Data | F5: Reaction Mix: n x 5.25 uL =
F6: Primer: n x 2.75 uL =
C7: PCR Caixa | F7: Taq Gold: n x 0.25 uL =
C8: PCR Perito | F8: Água: n x 4.40 uL =
C9: PCR Data | F9: DNA 0.5-1.25ng
C10: PCR Maquina | F10: Volume Final 12.5 uL por reação
B12: 1 | C12: =B12+1 -> 2 | D12: =C12+1 -> 3 | E12: =D12+1 -> 4 | F12: =E12+1 -> 5 | G12: =F12+1 -> 6 | H12: =G12+1 -> 7 | I12: =H12+1 -> 8 | J12: =I12+1 -> 9 | ... M12: =L12+1 -> 12
A13: A
A14: B
A15: C
A16: D
A17: E
A18: F
A19: G
A20: H
C22: Diluição | F22: Eletroforese LIZ Lote | J22: Observação
A23: ABI 3130 | C23: Corrida Data
C24: Perito Data | F24: Formamida: n+4 x 8.7 uL =
C25: Análise Data | F25: GS500 LIZ: n+4 x 0.3 uL =
C26: Análise Perito | F26: Distribuir 9 uL/poço e adicionar
C27: Conferente | F27: 1 uL do produto de PCR ou ladder

Sheet EXPORTAR
A1: Container Name | B1: Description | C1: ContainerType | D1: AppType | E1: Owner | F1: Operator
A2: =IPCMS!K1 -> 0 | B2: 10_09_20 | C2: 96-Well | D2: Regular | E2: Bruno | F2: Bruno
A3: AppServer | B3: AppInstance
A4: GeneMapper | B4: GeneMapper_Generic_Instance
A5: Well | B5: Sample Name | C5: Comment | D5: Priority | E5: Sample Type | F5: Snp Set | G5: Analysis Method | H5: Panel | I5: User-Defined 3 | J5: Size Standard | K5: User-Defined 2 | L5: User-Defined 1 | M5: Results Group 1 | N5: Instrument Protocol 1
A6: A01 | B6: =IF((IPCMS!$B13)="",0,IPCMS!$B13) -> 0 | D6: =IF($B6="","",100) -> 100 | E6: =IF($B6="FUSION","Allelic Ladder","Sample") -> Sample | G6: =IF($B6="","","Fusion") -> Fusion | H6: =IF($B6="","","PowerPlex_Fusion_Panels_IDX_v2.0") -> PowerPlex_Fusion_Panels_IDX_v2.0 | J6: =IF($B6="","","CC5_ILS_500_IDX") -> CC5_ILS_500_IDX | M6: =IF($B6="","","Paternidade") -> Paternidade | N6: =IF($B6="","","Fusion") -> Fusion
A7: B01 | B7: =IF((IPCMS!$B14)="",0,IPCMS!$B14) -> 0 | D7: =IF($B7="","",100) -> 100 | E7: =IF($B7="FUSION","Allelic Ladder","Sample") -> Sample | G7: =IF($B7="","","Fusion") -> Fusion | H7: =IF($B7="","","PowerPlex_Fusion_Panels_IDX_v2.0") -> PowerPlex_Fusion_Panels_IDX_v2.0 | J7: =IF($B7="","","CC5_ILS_500_IDX") -> CC5_ILS_500_IDX | M7: =IF($B7="","","Paternidade") -> Paternidade | N7: =IF($B7="","","Fusion") -> Fusion
A8: C01 | B8: =IF((IPCMS!$B15)="",0,IPCMS!$B15) -> 0 | D8: =IF($B8="","",100) -> 100 | E8: =IF($B8="FUSION","Allelic Ladder","Sample") -> Sample | G8: =IF($B8="","","Fusion") -> Fusion | H8: =IF($B8="","","PowerPlex_Fusion_Panels_IDX_v2.0") -> PowerPlex_Fusion_Panels_IDX_v2.0 | J8: =IF($B8="","","CC5_ILS_500_IDX") -> CC5_ILS_500_IDX | M8: =IF($B8="","","Paternidade") -> Paternidade | N8: =IF($B8="","","Fusion") -> Fusion
A9: D01 | B9: =IF((IPCMS!$B16)="",0,IPCMS!$B16) -> 0 | D9: =IF($B9="","",100) -> 100 | E9: =IF($B9="FUSION","Allelic Ladder","Sample") -> Sample | G9: =IF($B9="","","Fusion") -> Fusion | H9: =IF($B9="","","PowerPlex_Fusion_Panels_IDX_v2.0") -> PowerPlex_Fusion_Panels_IDX_v2.0 | J9: =IF($B9="","","CC5_ILS_500_IDX") -> CC5_ILS_500_IDX | M9: =IF($B9="","","Paternidade") -> Paternidade | N9: =IF($B9="","","Fusion") -> Fusion
A10: E01 | B10: =IF((IPCMS!$B17)="",0,IPCMS!$B17) -> 0 | D10: =IF($B10="","",100) -> 100 | E10: =IF($B10="FUSION","Allelic Ladder","Sample") -> Sample | G10: =IF($B10="","","Fusion") -> Fusion | H10: =IF($B10="","","PowerPlex_Fusion_Panels_IDX_v2.0") -> PowerPlex_Fusion_Panels_IDX_v2.0 | J10: =IF($B10="","","CC5_ILS_500_IDX") -> CC5_ILS_500_IDX | M10: =IF($B10="","","Paternidade") -> Paternidade | N10: =IF($B10="","","Fusion") -> Fusion
A11: F01 | B11: =IF((IPCMS!$B18)="",0,IPCMS!$B18) -> 0 | D11: =IF($B11="","",100) -> 100 | E11: =IF($B11="FUSION","Allelic Ladder","Sample") -> Sample | G11: =IF($B11="","","Fusion") -> Fusion | H11: =IF($B11="","","PowerPlex_Fusion_Panels_IDX_v2.0") -> PowerPlex_Fusion_Panels_IDX_v2.0 | J11: =IF($B11="","","CC5_ILS_500_IDX") -> CC5_ILS_500_IDX | M11: =IF($B11="","","Paternidade") -> Paternidade | N11: =IF($B11="","","Fusion") -> Fusion
A12: G01 | B12: =IF((IPCMS!$B19)="",0,IPCMS!$B19) -> 0 | D12: =IF($B12="","",100) -> 100 | E12: =IF($B12="FUSION","Allelic Ladder","Sample") -> Sample | G12: =IF($B12="","","Fusion") -> Fusion | H12: =IF($B12="","","PowerPlex_Fusion_Panels_IDX_v2.0") -> PowerPlex_Fusion_Panels_IDX_v2.0 | J12: =IF($B12="","","CC5_ILS_500_IDX") -> CC5_ILS_500_IDX | M12: =IF($B12="","","Paternidade") -> Paternidade | N12: =IF($B12="","","Fusion") -> Fusion
A13: H01 | B13: =IF((IPCMS!$B20)="",0,IPCMS!$B20) -> 0 | D13: =IF($B13="","",100) -> 100 | E13: =IF($B13="FUSION","Allelic Ladder","Sample") -> Sample | G13: =IF($B13="","","Fusion") -> Fusion | H13: =IF($B13="","","PowerPlex_Fusion_Panels_IDX_v2.0") -> PowerPlex_Fusion_Panels_IDX_v2.0 | J13: =IF($B13="","","CC5_ILS_500_IDX") -> CC5_ILS_500_IDX | M13: =IF($B13="","","Paternidade") -> Paternidade | N13: =IF($B13="","","Fusion") -> Fusion
A14: A02 | B14: =IF((IPCMS!$C13)="",0,IPCMS!$C13) -> 0 | D14: =IF($B14="","",100) -> 100 | E14: =IF($B14="FUSION","Allelic Ladder","Sample") -> Sample | G14: =IF($B14="","","Fusion") -> Fusion | H14: =IF($B14="","","PowerPlex_Fusion_Panels_IDX_v2.0") -> PowerPlex_Fusion_Panels_IDX_v2.0 | J14: =IF($B14="","","CC5_ILS_500_IDX") -> CC5_ILS_500_IDX | M14: =IF($B14="","","Paternidade") -> Paternidade | N14: =IF($B14="","","Fusion") -> Fusion
A15: B02 | B15: =IF((IPCMS!$C14)="",0,IPCMS!$C14) -> 0 | D15: =IF($B15="","",100) -> 100 | E15: =IF($B15="FUSION","Allelic Ladder","Sample") -> Sample | G15: =IF($B15="","","Fusion") -> Fusion | H15: =IF($B15="","","PowerPlex_Fusion_Panels_IDX_v2.0") -> PowerPlex_Fusion_Panels_IDX_v2.0 | J15: =IF($B15="","","CC5_ILS_500_IDX") -> CC5_ILS_500_IDX | M15: =IF($B15="","","Paternidade") -> Paternidade | N15: =IF($B15="","","Fusion") -> Fusion
A16: C02 | B16: =IF((IPCMS!$C15)="",0,IPCMS!$C15) -> 0 | D16: =IF($B16="","",100) -> 100 | E16: =IF($B16="FUSION","Allelic Ladder","Sample") -> Sample | G16: =IF($B16="","","Fusion") -> Fusion | H16: =IF($B16="","","PowerPlex_Fusion_Panels_IDX_v2.0") -> PowerPlex_Fusion_Panels_IDX_v2.0 | J16: =IF($B16="","","CC5_ILS_500_IDX") -> CC5_ILS_500_IDX | M16: =IF($B16="","","Paternidade") -> Paternidade | N16: =IF($B16="","","Fusion") -> Fusion
A17: D02 | B17: =IF((IPCMS!$C16)="",0,IPCMS!$C16) -> 0 | D17: =IF($B17="","",100) -> 100 | E17: =IF($B17="FUSION","Allelic Ladder","Sample") -> Sample | G17: =IF($B17="","","Fusion") -> Fusion | H17: =IF($B17="","","PowerPlex_Fusion_Panels_IDX_v2.0") -> PowerPlex_Fusion_Panels_IDX_v2.0 | J17: =IF($B17="","","CC5_ILS_500_IDX") -> CC5_ILS_500_IDX | M17: =IF($B17="","","Paternidade") -> Paternidade | N17: =IF($B17="","","Fusion") -> Fusion
A18: E02 | B18: =IF((IPCMS!$C17)="",0,IPCMS!$C17) -> 0 | D18: =IF($B18="","",100) -> 100 | E18: =IF($B18="FUSION","Allelic Ladder","Sample") -> Sample | G18: =IF($B18="","","Fusion") -> Fusion | H18: =IF($B18="","","PowerPlex_Fusion_Panels_IDX_v2.0") -> PowerPlex_Fusion_Panels_IDX_v2.0 | J18: =IF($B18="","","CC5_ILS_500_IDX") -> CC5_ILS_500_IDX | M18: =IF($B18="","","Paternidade") -> Paternidade | N18: =IF($B18="","","Fusion") -> Fusion
A19: F02 | B19: =IF((IPCMS!$C18)="",0,IPCMS!$C18) -> 0 | D19: =IF($B19="","",100) -> 100 | E19: =IF($B19="FUSION","Allelic Ladder","Sample") -> Sample | G19: =IF($B19="","","Fusion") -> Fusion | H19: =IF($B19="","","PowerPlex_Fusion_Panels_IDX_v2.0") -> PowerPlex_Fusion_Panels_IDX_v2.0 | J19: =IF($B19="","","CC5_ILS_500_IDX") -> CC5_ILS_500_IDX | M19: =IF($B19="","","Paternidade") -> Paternidade | N19: =IF($B19="","","Fusion") -> Fusion
A20: G02 | B20: =IF((IPCMS!$C19)="",0,IPCMS!$C19) -> 0 | D20: =IF($B20="","",100) -> 100 | E20: =IF($B20="FUSION","Allelic Ladder","Sample") -> Sample | G20: =IF($B20="","","Fusion") -> Fusion | H20: =IF($B20="","","PowerPlex_Fusion_Panels_IDX_v2.0") -> PowerPlex_Fusion_Panels_IDX_v2.0 | J20: =IF($B20="","","CC5_ILS_500_IDX") -> CC5_ILS_500_IDX | M20: =IF($B20="","","Paternidade") -> Paternidade | N20: =IF($B20="","","Fusion") -> Fusion
A21: H02 | B21: =IF((IPCMS!$C20)="",0,IPCMS!$C20) -> 0 | D21: =IF($B21="","",100) -> 100 | E21: =IF($B21="FUSION","Allelic Ladder","Sample") -> Sample | G21: =IF($B21="","","Fusion") -> Fusion | H21: =IF($B21="","","PowerPlex_Fusion_Panels_IDX_v2.0") -> PowerPlex_Fusion_Panels_IDX_v2.0 | J21: =IF($B21="","","CC5_ILS_500_IDX") -> CC5_ILS_500_IDX | M21: =IF($B21="","","Paternidade") -> Paternidade | N21: =IF($B21="","","Fusion") -> Fusion
A22: A03 | B22: =IF((IPCMS!$D13)="",0,IPCMS!$D13) -> 0 | D22: =IF($B22="","",100) -> 100 | E22: =IF($B22="FUSION","Allelic Ladder","Sample") -> Sample | G22: =IF($B22="","","Fusion") -> Fusion | H22: =IF($B22="","","PowerPlex_Fusion_Panels_IDX_v2.0") -> PowerPlex_Fusion_Panels_IDX_v2.0 | J22: =IF($B22="","","CC5_ILS_500_IDX") -> CC5_ILS_500_IDX | M22: =IF($B22="","","Paternidade") -> Paternidade | N22: =IF($B22="","","Fusion") -> Fusion
A23: B03 | B23: =IF((IPCMS!$D14)="",0,IPCMS!$D14) -> 0 | D23: =IF($B23="","",100) -> 100 | E23: =IF($B23="FUSION","Allelic Ladder","Sample") -> Sample | G23: =IF($B23="","","Fusion") -> Fusion | H23: =IF($B23="","","PowerPlex_Fusion_Panels_IDX_v2.0") -> PowerPlex_Fusion_Panels_IDX_v2.0 | J23: =IF($B23="","","CC5_ILS_500_IDX") -> CC5_ILS_500_IDX | M23: =IF($B23="","","Paternidade") -> Paternidade | N23: =IF($B23="","","Fusion") -> Fusion
A24: C03 | B24: =IF((IPCMS!$D15)="",0,IPCMS!$D15) -> 0 | D24: =IF($B24="","",100) -> 100 | E24: =IF($B24="FUSION","Allelic Ladder","Sample") -> Sample | G24: =IF($B24="","","Fusion") -> Fusion | H24: =IF($B24="","","PowerPlex_Fusion_Panels_IDX_v2.0") -> PowerPlex_Fusion_Panels_IDX_v2.0 | J24: =IF($B24="","","CC5_ILS_500_IDX") -> CC5_ILS_500_IDX | M24: =IF($B24="","","Paternidade") -> Paternidade | N24: =IF($B24="","","Fusion") -> Fusion
A25: D03 | B25: =IF((IPCMS!$D16)="",0,IPCMS!$D16) -> 0 | D25: =IF($B25="","",100) -> 100 | E25: =IF($B25="FUSION","Allelic Ladder","Sample") -> Sample | G25: =IF($B25="","","Fusion") -> Fusion | H25: =IF($B25="","","PowerPlex_Fusion_Panels_IDX_v2.0") -> PowerPlex_Fusion_Panels_IDX_v2.0 | J25: =IF($B25="","","CC5_ILS_500_IDX") -> CC5_ILS_500_IDX | M25: =IF($B25="","","Paternidade") -> Paternidade | N25: =IF($B25="","","Fusion") -> Fusion
A26: E03 | B26: =IF((IPCMS!$D17)="",0,IPCMS!$D17) -> 0 | D26: =IF($B26="","",100) -> 100 | E26: =IF($B26="FUSION","Allelic Ladder","Sample") -> Sample | G26: =IF($B26="","","Fusion") -> Fusion | H26: =IF($B26="","","PowerPlex_Fusion_Panels_IDX_v2.0") -> PowerPlex_Fusion_Panels_IDX_v2.0 | J26: =IF($B26="","","CC5_ILS_500_IDX") -> CC5_ILS_500_IDX | M26: =IF($B26="","","Paternidade") -> Paternidade | N26: =IF($B26="","","Fusion") -> Fusion
A27: F03 | B27: =IF((IPCMS!$D18)="",0,IPCMS!$D18) -> 0 | D27: =IF($B27="","",100) -> 100 | E27: =IF($B27="FUSION","Allelic Ladder","Sample") -> Sample | G27: =IF($B27="","","Fusion") -> Fusion | H27: =IF($B27="","","PowerPlex_Fusion_Panels_IDX_v2.0") -> PowerPlex_Fusion_Panels_IDX_v2.0 | J27: =IF($B27="","","CC5_ILS_500_IDX") -> CC5_ILS_500_IDX | M27: =IF($B27="","","Paternidade") -> Paternidade | N27: =IF($B27="","","Fusion") -> Fusion
A28: G03 | B28: =IF((IPCMS!$D19)="",0,IPCMS!$D19) -> 0 | D28: =IF($B28="","",100) -> 100 | E28: =IF($B28="FUSION","Allelic Ladder","Sample") -> Sample | G28: =IF($B28="","","Fusion") -> Fusion | H28: =IF($B28="","","PowerPlex_Fusion_Panels_IDX_v2.0") -> PowerPlex_Fusion_Panels_IDX_v2.0 | J28: =IF($B28="","","CC5_ILS_500_IDX") -> CC5_ILS_500_IDX | M28: =IF($B28="","","Paternidade") -> Paternidade | N28: =IF($B28="","","Fusion") -> Fusion
A29: H03 | B29: =IF((IPCMS!$D20)="",0,IPCMS!$D20) -> 0 | D29: =IF($B29="","",100) -> 100 | E29: =IF($B29="FUSION","Allelic Ladder","Sample") -> Sample | G29: =IF($B29="","","Fusion") -> Fusion | H29: =IF($B29="","","PowerPlex_Fusion_Panels_IDX_v2.0") -> PowerPlex_Fusion_Panels_IDX_v2.0 | J29: =IF($B29="","","CC5_ILS_500_IDX") -> CC5_ILS_500_IDX | M29: =IF($B29="","","Paternidade") -> Paternidade | N29: =IF($B29="","","Fusion") -> Fusion
A30: A04 | B30: =IF((IPCMS!$E13)="",0,IPCMS!$E13) -> 0 | D30: =IF($B30="","",100) -> 100 | E30: =IF($B30="FUSION","Allelic Ladder","Sample") -> Sample | G30: =IF($B30="","","Fusion") -> Fusion | H30: =IF($B30="","","PowerPlex_Fusion_Panels_IDX_v2.0") -> PowerPlex_Fusion_Panels_IDX_v2.0 | J30: =IF($B30="","","CC5_ILS_500_IDX") -> CC5_ILS_500_IDX | M30: =IF($B30="","","Paternidade") -> Paternidade | N30: =IF($B30="","","Fusion") -> Fusion
A31: B04 | B31: =IF((IPCMS!$E14)="",0,IPCMS!$E14) -> 0 | D31: =IF($B31="","",100) -> 100 | E31: =IF($B31="FUSION","Allelic Ladder","Sample") -> Sample | G31: =IF($B31="","","Fusion") -> Fusion | H31: =IF($B31="","","PowerPlex_Fusion_Panels_IDX_v2.0") -> PowerPlex_Fusion_Panels_IDX_v2.0 | J31: =IF($B31="","","CC5_ILS_500_IDX") -> CC5_ILS_500_IDX | M31: =IF($B31="","","Paternidade") -> Paternidade | N31: =IF($B31="","","Fusion") -> Fusion
A32: C04 | B32: =IF((IPCMS!$E15)="",0,IPCMS!$E15) -> 0 | D32: =IF($B32="","",100) -> 100 | E32: =IF($B32="FUSION","Allelic Ladder","Sample") -> Sample | G32: =IF($B32="","","Fusion") -> Fusion | H32: =IF($B32="","","PowerPlex_Fusion_Panels_IDX_v2.0") -> PowerPlex_Fusion_Panels_IDX_v2.0 | J32: =IF($B32="","","CC5_ILS_500_IDX") -> CC5_ILS_500_IDX | M32: =IF($B32="","","Paternidade") -> Paternidade | N32: =IF($B32="","","Fusion") -> Fusion
A33: D04 | B33: =IF((IPCMS!$E16)="",0,IPCMS!$E16) -> 0 | D33: =IF($B33="","",100) -> 100 | E33: =IF($B33="FUSION","Allelic Ladder","Sample") -> Sample | G33: =IF($B33="","","Fusion") -> Fusion | H33: =IF($B33="","","PowerPlex_Fusion_Panels_IDX_v2.0") -> PowerPlex_Fusion_Panels_IDX_v2.0 | J33: =IF($B33="","","CC5_ILS_500_IDX") -> CC5_ILS_500_IDX | M33: =IF($B33="","","Paternidade") -> Paternidade | N33: =IF($B33="","","Fusion") -> Fusion
A34: E04 | B34: =IF((IPCMS!$E17)="",0,IPCMS!$E17) -> 0 | D34: =IF($B34="","",100) -> 100 | E34: =IF($B34="FUSION","Allelic Ladder","Sample") -> Sample | G34: =IF($B34="","","Fusion") -> Fusion | H34: =IF($B34="","","PowerPlex_Fusion_Panels_IDX_v2.0") -> PowerPlex_Fusion_Panels_IDX_v2.0 | J34: =IF($B34="","","CC5_ILS_500_IDX") -> CC5_ILS_500_IDX | M34: =IF($B34="","","Paternidade") -> Paternidade | N34: =IF($B34="","","Fusion") -> Fusion
A35: F04 | B35: =IF((IPCMS!$E18)="",0,IPCMS!$E18) -> 0 | D35: =IF($B35="","",100) -> 100 | E35: =IF($B35="FUSION","Allelic Ladder","Sample") -> Sample | G35: =IF($B35="","","Fusion") -> Fusion | H35: =IF($B35="","","PowerPlex_Fusion_Panels_IDX_v2.0") -> PowerPlex_Fusion_Panels_IDX_v2.0 | J35: =IF($B35="","","CC5_ILS_500_IDX") -> CC5_ILS_500_IDX | M35: =IF($B35="","","Paternidade") -> Paternidade | N35: =IF($B35="","","Fusion") -> Fusion
A36: G04 | B36: =IF((IPCMS!$E19)="",0,IPCMS!$E19) -> 0 | D36: =IF($B36="","",100) -> 100 | E36: =IF($B36="FUSION","Allelic Ladder","Sample") -> Sample | G36: =IF($B36="","","Fusion") -> Fusion | H36: =IF($B36="","","PowerPlex_Fusion_Panels_IDX_v2.0") -> PowerPlex_Fusion_Panels_IDX_v2.0 | J36: =IF($B36="","","CC5_ILS_500_IDX") -> CC5_ILS_500_IDX | M36: =IF($B36="","","Paternidade") -> Paternidade | N36: =IF($B36="","","Fusion") -> Fusion
A37: H04 | B37: =IF((IPCMS!$E20)="",0,IPCMS!$E20) -> 0 | D37: =IF($B37="","",100) -> 100 | E37: =IF($B37="FUSION","Allelic Ladder","Sample") -> Sample | G37: =IF($B37="","","Fusion") -> Fusion | H37: =IF($B37="","","PowerPlex_Fusion_Panels_IDX_v2.0") -> PowerPlex_Fusion_Panels_IDX_v2.0 | J37: =IF($B37="","","CC5_ILS_500_IDX") -> CC5_ILS_500_IDX | M37: =IF($B37="","","Paternidade") -> Paternidade | N37: =IF($B37="","","Fusion") -> Fusion
A38: A05 | B38: =IF((IPCMS!$F13)="",0,IPCMS!$F13) -> 0 | D38: =IF($B38="","",100) -> 100 | E38: =IF($B38="FUSION","Allelic Ladder","Sample") -> Sample | G38: =IF($B38="","","Fusion") -> Fusion | H38: =IF($B38="","","PowerPlex_Fusion_Panels_IDX_v2.0") -> PowerPlex_Fusion_Panels_IDX_v2.0 | J38: =IF($B38="","","CC5_ILS_500_IDX") -> CC5_ILS_500_IDX | M38: =IF($B38="","","Paternidade") -> Paternidade | N38: =IF($B38="","","Fusion") -> Fusion
A39: B05 | B39: =IF((IPCMS!$F14)="",0,IPCMS!$F14) -> 0 | D39: =IF($B39="","",100) -> 100 | E39: =IF($B39="FUSION","Allelic Ladder","Sample") -> Sample | G39: =IF($B39="","","Fusion") -> Fusion | H39: =IF($B39="","","PowerPlex_Fusion_Panels_IDX_v2.0") -> PowerPlex_Fusion_Panels_IDX_v2.0 | J39: =IF($B39="","","CC5_ILS_500_IDX") -> CC5_ILS_500_IDX | M39: =IF($B39="","","Paternidade") -> Paternidade | N39: =IF($B39="","","Fusion") -> Fusion
A40: C05 | B40: =IF((IPCMS!$F15)="",0,IPCMS!$F15) -> 0 | D40: =IF($B40="","",100) -> 100 | E40: =IF($B40="FUSION","Allelic Ladder","Sample") -> Sample | G40: =IF($B40="","","Fusion") -> Fusion | H40: =IF($B40="","","PowerPlex_Fusion_Panels_IDX_v2.0") -> PowerPlex_Fusion_Panels_IDX_v2.0 | J40: =IF($B40="","","CC5_ILS_500_IDX") -> CC5_ILS_500_IDX | M40: =IF($B40="","","Paternidade") -> Paternidade | N40: =IF($B40="","","Fusion") -> Fusion
...

Sheet IMPRIMIR
C1: MAPA DE AMPLIFICAÇÃO | H1: DATA: | I1: =EXPORTAR!B2 -> 10_09_20
B4: H | C4: G | D4: F | E4: E | F4: D | G4: C | H4: B | I4: A
A5: 1 | J5: 1
A6: 2 | J6: 2
A7: 3 | J7: 3
A8: 4 | J8: 4
A9: 5 | J9: 5
A10: 6 | J10: 6
A11: 7 | B11: =IPCMS!H20 -> 0 | C11: =IPCMS!H19 -> 0 | D11: =IPCMS!H18 -> 0 | E11: =IPCMS!H17 -> 0 | F11: =IPCMS!H16 -> 0 | G11: =IPCMS!H15 -> 0 | H11: =IPCMS!H14 -> 0 | I11: =IPCMS!H13 -> 0 | J11: 7
A12: 8 | B12: =IPCMS!I20 -> 0 | C12: =IPCMS!I19 -> 0 | D12: =IPCMS!I18 -> 0 | E12: =IPCMS!I17 -> 0 | F12: =IPCMS!I16 -> 0 | G12: =IPCMS!I15 -> 0 | H12: =IPCMS!I14 -> 0 | I12: =IPCMS!I13 -> 0 | J12: 8
A13: 9 | B13: =IPCMS!J20 -> 0 | C13: =IPCMS!J19 -> 0 | D13: =IPCMS!J18 -> 0 | E13: =IPCMS!J17 -> 0 | F13: =IPCMS!J16 -> 0 | G13: =IPCMS!J15 -> 0 | H13: =IPCMS!J14 -> 0 | I13: =IPCMS!J13 -> 0 | J13: 9
A14: 10 | B14: =IPCMS!K20 -> 0 | C14: =IPCMS!K19 -> 0 | D14: =IPCMS!K18 -> 0 | E14: =IPCMS!K17 -> 0 | F14: =IPCMS!K16 -> 0 | G14: =IPCMS!K15 -> 0 | H14: =IPCMS!K14 -> 0 | I14: =IPCMS!K13 -> 0 | J14: 10
A15: 11 | F15: =IPCMS!L16 -> 0 | G15: =IPCMS!L15 -> 0 | H15: =IPCMS!L14 -> 0 | I15: =IPCMS!L13 -> 0 | J15: 11
A16: 12 | J16: 12
A18: Pipetagem e desnaturação: ____/____/20____ Responsáveis: ___________
A19: Corrida: ____/____/20____ Responsáveis: ___________
A20: Micropipetas: 16-2A ( ) 17 -2A ( ) 5 - 1C ( ) outros ( ) __________
A21: Lote: FOR + LIZ: ___________ Ladder: _____________ Outros: ____________
A22: Termociclador: 9600 ( ) 9700 ( )
